Workbook

Sheet PP F.G ROLL
A1: SO# | B1: Party Name | C1: Job Name | D1: MATERIAL | E1: Roll Size | F1: Guage | G1: Seal | H1: Section IN | I1: TR # | J1: DATE | K1: I.BAGS | L1: WEIGHT | M1: CORE | N1: NET WEIGHT | O1: TO Section OUT | P1: PO# | Q1: BILL # | R1: DATE 2 | S1: O.ROLLS | T1: O.KGS
A2: =CONCATENATE(E2,"/",F2) -> 14/5 | B2: STOCK | C2: PP | D2: PP | E2: 14 | F2: 5 | H2: OPENING | J2: 45870 | K2: 42 | L2: =38+44+45+65+25+29+61+57+51+38+41+50+58+60+32+54+52+50+44+50+36+50+26+52+57 -> 1165 | M2: =1.4*25 -> 35 | N2: =+L2-M2 -> 1130
A3: =CONCATENATE(E3,"/",F3) -> 13/5 | B3: STOCK | C3: PP | D3: PP | E3: 13 | F3: 5 | H3: OPENING | J3: 45870 | K3: 21 | L3: =45+40+54+37+36+49+32+44+38+43+25+47+51+51+65+34+28+38+50+15+13 -> 835 | M3: =1.3*21 -> 27.3 | N3: =+L3-M3 -> 807.7
A4: =CONCATENATE(E4,"/",F4) -> 12/5 | B4: STOCK | C4: PP | D4: PP | E4: 12 | F4: 5 | H4: OPENING | J4: 45870 | K4: 32 | L4: =41+51+55+44+43+41+43+38+41+48+48+43+44+41+18+43+44+45+44+23+16+54+45+49+43+41+35+53+46+53+50+42 -> 1365 | M4: =1.2*32 -> 38.4 | N4: =+L4-M4 -> 1326.6
A5: =CONCATENATE(E5,"/",F5) -> 11/5 | B5: STOCK | C5: PP | D5: PP | E5: 11 | F5: 5 | H5: OPENING | J5: 45870 | K5: 30 | L5: =60+43+50+46+22+17+44+39+50+44+47+42+42+43+43+47+46+53+48+47+44+46+51+55+37+32 -> 1138 | M5: =1.1*26 -> 28.6 | N5: =+L5-M5 -> 1109.4
A6: =CONCATENATE(E6,"/",F6) -> 8/5 | B6: STOCK | C6: PP | D6: PP | E6: 8 | F6: 5 | H6: OPENING | J6: 45870 | K6: 38 | L6: =16+34+27+30+41+40+38+45+34+34+31+34+27+27+34+21+39+30+21+28+34+44+39+42+34+27+38+35+35+36+21+25+23+31+31+39+30+40 -> 1235 | M6: =0.8*38 -> 30.4 | N6: =+L6-M6 -> 1204.6
A7: =CONCATENATE(E7,"/",F7) -> 7/5 | B7: STOCK | C7: PP | D7: PP | E7: 7 | F7: 5 | H7: OPENING | J7: 45870 | K7: 14 | L7: 350 | M7: =0.7*11 -> 7.7 | N7: 350
A8: =CONCATENATE(E8,"/",F8) -> 6/5 | B8: STOCK | C8: PP | D8: PP | E8: 6 | F8: 5 | H8: OPENING | J8: 45870 | K8: 33 | L8: =36+33+33+34+25+22+28+28+14+11+32+29+28+30+31+33+31+33+32+33+32+35+34+36+34+34+30+35+36+36+35+38+38 -> 1029 | M8: =0.6*33 -> 19.8 | N8: =+L8-M8 -> 1009.2
A9: =CONCATENATE(E9,"/",F9) -> 14/6.5 | B9: STOCK | C9: PP | D9: PP | E9: 14 | F9: 6.5 | H9: OPENING | J9: 45870 | K9: 12 | L9: =49+36+45+44+41+41+43+48+35+35+35+43 -> 495 | M9: =1.4*12 -> 16.8 | N9: =+L9-M9 -> 478.2
A10: =CONCATENATE(E10,"/",F10) -> 15/6 | B10: STOCK | C10: PP | D10: PP | E10: 15 | F10: 6 | H10: OPENING | J10: 45870 | K10: 7 | L10: =24+32+36+32+31+34+34 -> 223 | M10: =1.5*7 -> 10.5 | N10: =+L10-M10 -> 212.5
A11: =CONCATENATE(E11,"/",F11) -> 18/4 | B11: STOCK | C11: PP | D11: PP | E11: 18 | F11: 4 | H11: OPENING | J11: 45870 | K11: 15 | L11: =46+48+40+33+50+42+43+53+52+52+55+30+53+47+53 -> 697 | M11: =1.8*15 -> 27 | N11: =+L11-M11 -> 670
A12: =CONCATENATE(E12,"/",F12) -> 7/4 | B12: STOCK | C12: PP | D12: PP | E12: 7 | F12: 4 | H12: OPENING | J12: 45870 | K12: 4 | L12: =14+23+24+20 -> 81 | M12: =0.7*4 -> 2.8 | N12: =+L12-M12 -> 78.2
A13: =CONCATENATE(E13,"/",F13) -> 8/4 | B13: STOCK | C13: PP | D13: PP | E13: 8 | F13: 4 | H13: OPENING | J13: 45870 | K13: 8 | L13: =35+37+34+34+33+31+32+20 -> 256 | M13: =0.8*8 -> 6.4 | N13: =+L13-M13 -> 249.6
A14: =CONCATENATE(E14,"/",F14) -> 9/4 | B14: STOCK | C14: PP | D14: PP | E14: 9 | F14: 4 | H14: OPENING | J14: 45870 | K14: 3 | L14: =42+31+31 -> 104 | M14: =0.9*3 -> 2.7 | N14: =+L14-M14 -> 101.3
A15: =CONCATENATE(E15,"/",F15) -> 2/5 | B15: STOCK | C15: PP | D15: PP | E15: 2 | F15: 5 | H15: OPENING | J15: 45870 | K15: 15 | L15: =20+20+21+21+21+22+23+20+21+20+18+18+19+20+20 -> 304 | M15: =0.2*15 -> 3 | N15: =+L15-M15 -> 301
A16: =CONCATENATE(E16,"/",F16) -> 24/5 | B16: STOCK | C16: PP | D16: PP | E16: 24 | F16: 5 | H16: OPENING | J16: 45870 | K16: =20+2+8+9 -> 39 | L16: 1717.8 | M16: =2.4*17 -> 40.8 | N16: 1717.8
A17: =CONCATENATE(E17,"/",F17) -> 20/5 | B17: STOCK | C17: PP | D17: PP | E17: 20 | F17: 5 | H17: OPENING | J17: 45870 | K17: 30 | L17: =35+41+42+66+58+62+51+70+66+44+53+49+64+54+47+58+49+64+54+47+58+49+54+44+49+60+62+51+48+65+52 -> 1666 | M17: =2*30 -> 60 | N17: =+L17-M17 -> 1606
A18: =CONCATENATE(E18,"/",F18) -> 19/5 | B18: STOCK | C18: PP | D18: PP | E18: 19 | F18: 5 | H18: OPENING | J18: 45870 | K18: 10 | L18: =69+57+32+52+64+57+60+60+50+65 -> 566 | M18: =1.9*10 -> 19 | N18: =+L18-M18 -> 547
A19: =CONCATENATE(E19,"/",F19) -> 17/5 | B19: STOCK | C19: PP | D19: PP | E19: 17 | F19: 5 | H19: OPENING | J19: 45870 | K19: 4 | L19: =25+27+34+56 -> 142 | M19: =1.7*4 -> 6.8 | N19: =+L19-M19 -> 135.2
A20: =CONCATENATE(E20,"/",F20) -> 22/6 | B20: STOCK | C20: PP | D20: PP | E20: 22 | F20: 6 | H20: OPENING | J20: 45870 | K20: 10 | L20: 251.3 | M20: =2.2*4 -> 8.8 | N20: 266.9
A21: =CONCATENATE(E21,"/",F21) -> 18/5 | B21: STOCK | C21: PP | D21: PP | E21: 18 | F21: 5 | H21: OPENING | J21: 45870 | K21: 7 | L21: =31+30+40+46+46+56+49 -> 298 | M21: =1.8*7 -> 12.6 | N21: =+L21-M21 -> 285.4
A22: =CONCATENATE(E22,"/",F22) -> 16/5 | B22: STOCK | C22: PP | D22: PP | E22: 16 | F22: 5 | H22: OPENING | J22: 45870 | K22: 7 | L22: =12+20+18+34+33+25+38 -> 180 | M22: =1.6*7 -> 11.2 | N22: =+L22-M22 -> 168.8
A23: =CONCATENATE(E23,"/",F23) -> 15/5 | B23: STOCK | C23: PP | D23: PP | E23: 15 | F23: 5 | H23: OPENING | J23: 45870 | K23: 26 | L23: =18+38+34+54+56+42+29+33+29+25+27+54+51+48+44+52+53+31+21+26+37+24+42+51+38+39 -> 996 | M23: =1.5*26 -> 39 | N23: =+L23-M23 -> 957
A24: =CONCATENATE(E24,"/",F24) -> 2/6.5 | B24: STOCK | C24: PP | D24: PP | E24: 2 | F24: 6.5 | H24: OPENING | J24: 45870 | K24: 4 | L24: =37+52+50+47 -> 186 | M24: =0.2*4 -> 0.8 | N24: =+L24-M24 -> 185.2
A25: =CONCATENATE(E25,"/",F25) -> 19/4 | B25: STOCK | C25: PP | D25: PP | E25: 19 | F25: 4 | H25: OPENING | J25: 45870 | K25: 1 | L25: 22 | M25: 1.9 | N25: =+L25-M25 -> 20.1
A26: =CONCATENATE(E26,"/",F26) -> 24/4 | B26: STOCK | C26: PP | D26: PP | E26: 24 | F26: 4 | H26: OPENING | J26: 45870 | K26: 1 | L26: 42 | M26: 2.4 | N26: =+L26-M26 -> 39.6
A27: =CONCATENATE(E27,"/",F27) -> 11/7 | B27: STOCK | C27: PP | D27: PP | E27: 11 | F27: 7 | H27: OPENING | J27: 45870 | K27: 4 | L27: =41+45+15+28 -> 129 | M27: =1.1*4 -> 4.4 | N27: =+L27-M27 -> 124.6
A28: =CONCATENATE(E28,"/",F28) -> 6/4 | B28: STOCK | C28: PP | D28: PP | E28: 6 | F28: 4 | H28: OPENING | J28: 45870 | K28: 6 | L28: =29+29+35+30+38+34 -> 195 | M28: =0.6*6 -> 3.6 | N28: =+L28-M28 -> 191.4
A29: =CONCATENATE(E29,"/",F29) -> 13/7 | B29: STOCK | C29: PP | D29: PP | E29: 13 | F29: 7 | H29: OPENING | J29: 45870 | K29: 2 | L29: =26+45 -> 71 | M29: =1.3*2 -> 2.6 | N29: =+L29-M29 -> 68.4
A30: =CONCATENATE(E30,"/",F30) -> 12/6.5 | B30: STOCK | C30: PP | D30: PP | E30: 12 | F30: 6.5 | H30: OPENING | J30: 45870 | K30: 7 | L30: =20+26+26+51+17+16+33 -> 189 | M30: =1.2*7 -> 8.4 | N30: =+L30-M30 -> 180.6
A31: =CONCATENATE(E31,"/",F31) -> 17/7 | B31: STOCK | C31: PP | D31: PP | E31: 17 | F31: 7 | H31: OPENING | J31: 45870 | K31: 7 | L31: =20+23+65+60+57+62+58 -> 345 | M31: =1.7*7 -> 11.9 | N31: =+L31-M31 -> 333.1
A32: =CONCATENATE(E32,"/",F32) -> 15/4 | B32: STOCK | C32: PP | D32: PP | E32: 15 | F32: 4 | H32: OPENING | J32: 45870 | K32: 7 | L32: =34+51+53+54+47+66+51+50+39+55 -> 500 | M32: =1.5*7 -> 10.5 | N32: =+L32-M32 -> 489.5
A33: =CONCATENATE(E33,"/",F33) -> 16/8 | B33: STOCK | C33: PP | D33: PP | E33: 16 | F33: 8 | H33: OPENING | J33: 45870 | K33: 10 | L33: =28+30 -> 58 | M33: =1.6*10 -> 16 | N33: =+L33-M33 -> 42
A34: =CONCATENATE(E34,"/",F34) -> 15/7 | B34: STOCK | C34: PP | D34: PP | E34: 15 | F34: 7 | H34: OPENING | J34: 45870 | K34: 2 | L34: =17+18 -> 35 | M34: =1.5*2 -> 3 | N34: =+L34-M34 -> 32
A35: =CONCATENATE(E35,"/",F35) -> 8/6.5 | B35: STOCK | C35: PP | D35: PP | E35: 8 | F35: 6.5 | H35: OPENING | J35: 45870 | K35: 2 | L35: =27+46+40+40+40+40+40 -> 273 | M35: =0.8*2 -> 1.6 | N35: =+L35-M35 -> 271.4
A36: =CONCATENATE(E36,"/",F36) -> 18/7 | B36: STOCK | C36: PP | D36: PP | E36: 18 | F36: 7 | H36: OPENING | J36: 45870 | K36: 7 | L36: 51 | M36: =1.8*7 -> 12.6 | N36: =25+19.6 -> 44.6
A37: =CONCATENATE(E37,"/",F37) -> 8/4 | B37: STOCK | C37: PP | D37: PP | E37: 8 | F37: 4 | H37: OPENING | J37: 45870 | K37: 1 | L37: 24 | M37: 0.8 | N37: =+L37-M37 -> 23.2
A38: =CONCATENATE(E38,"/",F38) -> 8/10 | B38: STOCK | C38: PP | D38: PP | E38: 8 | F38: 10 | H38: OPENING | J38: 45870 | K38: 1 | L38: 27 | M38: 0.8 | N38: =+L38-M38 -> 26.2
A39: =CONCATENATE(E39,"/",F39) -> 9/10 | B39: STOCK | C39: PP | D39: PP | E39: 9 | F39: 10 | H39: OPENING | J39: 45870 | K39: 1 | L39: 31 | M39: 0.9 | N39: =+L39-M39 -> 30.1
A40: =CONCATENATE(E40,"/",F40) -> 16/7 | B40: STOCK | C40: PP | D40: PP | E40: 16 | F40: 7 | H40: OPENING | J40: 45870 | K40: 2 | L40: =47+80+54 -> 181 | M40: =1.6*7 -> 11.2 | N40: =+L40-M40 -> 169.8
...

Sheet PP ROLL STOCK
A1: Row Labels | B1: FORMULA | C1: SO | D1: Order Date | E1: PARTY NAME | F1: SIZE | G1: GAUGE | H1: INN BAGS | I1: INN KGS | J1: OUT BAGS | K1: OUT KGS | L1: STOCK BAGS | M1: STOCK KGS | N1: Group | O1: QUALITY | P1: SAP CODE | R1: SAP SIZE | S1: SAP BALANCE
A2: (blank) | C2: =+A2 -> (blank) | D2: =_xlfn.MAXIFS('PP F.G ROLL'!J:J,'PP F.G ROLL'!A:A,'PP ROLL STOCK'!C2) -> 0 | E2: {=IFERROR(VLOOKUP(C2,'PP F.G ROLL'!A:T,{2,5,6},0),"-")} -> - | H2: =SUMIFS('PP F.G ROLL'!K:K,'PP F.G ROLL'!$A:$A,'PP ROLL STOCK'!$C2) -> 0 | I2: =SUMIFS('PP F.G ROLL'!N:N,'PP F.G ROLL'!$A:$A,'PP ROLL STOCK'!$C2) -> 0 | J2: =SUMIFS('PP F.G ROLL'!S:S,'PP F.G ROLL'!$A:$A,'PP ROLL STOCK'!$C2) -> 0 | K2: =SUMIFS('PP F.G ROLL'!T:T,'PP F.G ROLL'!$A:$A,'PP ROLL STOCK'!$C2) -> 0 | L2: =+H2-J2 -> 0 | M2: =+I2-K2 -> 0 | N2: =IFERROR(VLOOKUP(C2,'[1]MIX SALE ORDER'!$A:$E,4,),"OTHERS") -> OTHERS | O2: =VLOOKUP(C2,'PP F.G ROLL'!A:T,4,0) -> #N/A | P2: {=_xlfn.XLOOKUP(R$2:R$300,'SAP CODE'!F:F,'SAP CODE'!A:A)} -> 179 | Q2: / | R2: =CONCATENATE(F2,Q2,G2,) -> /
A3: 14/5 | C3: =+A3 -> 14/5 | D3: =_xlfn.MAXIFS('PP F.G ROLL'!J:J,'PP F.G ROLL'!A:A,'PP ROLL STOCK'!C3) -> 45917 | E3: {=IFERROR(VLOOKUP(C3,'PP F.G ROLL'!A:T,{2,5,6},0),"-")} -> STOCK | F3: 14 | G3: 5 | H3: =SUMIFS('PP F.G ROLL'!K:K,'PP F.G ROLL'!$A:$A,'PP ROLL STOCK'!$C3) -> 136 | I3: =SUMIFS('PP F.G ROLL'!N:N,'PP F.G ROLL'!$A:$A,'PP ROLL STOCK'!$C3) -> 5456.54 | J3: =SUMIFS('PP F.G ROLL'!S:S,'PP F.G ROLL'!$A:$A,'PP ROLL STOCK'!$C3) -> 150 | K3: =SUMIFS('PP F.G ROLL'!T:T,'PP F.G ROLL'!$A:$A,'PP ROLL STOCK'!$C3) -> 4246.8 | L3: =+H3-J3 -> -14 | M3: =+I3-K3 -> 1209.74 | N3: =IFERROR(VLOOKUP(C3,'[1]MIX SALE ORDER'!$A:$E,4,),"OTHERS") -> OTHERS | O3: =VLOOKUP(C3,'PP F.G ROLL'!A:T,4,0) -> PP | P3: #N/A | Q3: / | R3: =CONCATENATE(F3,Q3,G3,) -> 14/5
A4: 13/5 | C4: =+A4 -> 13/5 | D4: =_xlfn.MAXIFS('PP F.G ROLL'!J:J,'PP F.G ROLL'!A:A,'PP ROLL STOCK'!C4) -> 45904 | E4: {=IFERROR(VLOOKUP(C4,'PP F.G ROLL'!A:T,{2,5,6},0),"-")} -> STOCK | F4: 13 | G4: 5 | H4: =SUMIFS('PP F.G ROLL'!K:K,'PP F.G ROLL'!$A:$A,'PP ROLL STOCK'!$C4) -> 48 | I4: =SUMIFS('PP F.G ROLL'!N:N,'PP F.G ROLL'!$A:$A,'PP ROLL STOCK'!$C4) -> 2157.84 | J4: =SUMIFS('PP F.G ROLL'!S:S,'PP F.G ROLL'!$A:$A,'PP ROLL STOCK'!$C4) -> 73 | K4: =SUMIFS('PP F.G ROLL'!T:T,'PP F.G ROLL'!$A:$A,'PP ROLL STOCK'!$C4) -> 1825 | L4: =+H4-J4 -> -25 | M4: =+I4-K4 -> 332.84 | N4: =IFERROR(VLOOKUP(C4,'[1]MIX SALE ORDER'!$A:$E,4,),"OTHERS") -> OTHERS | O4: =VLOOKUP(C4,'PP F.G ROLL'!A:T,4,0) -> PP | P4: #N/A | Q4: / | R4: =CONCATENATE(F4,Q4,G4,) -> 13/5
A5: 12/5 | C5: =+A5 -> 12/5 | D5: =_xlfn.MAXIFS('PP F.G ROLL'!J:J,'PP F.G ROLL'!A:A,'PP ROLL STOCK'!C5) -> 45929 | E5: {=IFERROR(VLOOKUP(C5,'PP F.G ROLL'!A:T,{2,5,6},0),"-")} -> STOCK | F5: 12 | G5: 5 | H5: =SUMIFS('PP F.G ROLL'!K:K,'PP F.G ROLL'!$A:$A,'PP ROLL STOCK'!$C5) -> 70 | I5: =SUMIFS('PP F.G ROLL'!N:N,'PP F.G ROLL'!$A:$A,'PP ROLL STOCK'!$C5) -> 3101 | J5: =SUMIFS('PP F.G ROLL'!S:S,'PP F.G ROLL'!$A:$A,'PP ROLL STOCK'!$C5) -> 113 | K5: =SUMIFS('PP F.G ROLL'!T:T,'PP F.G ROLL'!$A:$A,'PP ROLL STOCK'!$C5) -> 2974.5 | L5: =+H5-J5 -> -43 | M5: =+I5-K5 -> 126.5 | N5: =IFERROR(VLOOKUP(C5,'[1]MIX SALE ORDER'!$A:$E,4,),"OTHERS") -> OTHERS | O5: =VLOOKUP(C5,'PP F.G ROLL'!A:T,4,0) -> PP | P5: #N/A | Q5: / | R5: =CONCATENATE(F5,Q5,G5,) -> 12/5
A6: 11/5 | C6: =+A6 -> 11/5 | D6: =_xlfn.MAXIFS('PP F.G ROLL'!J:J,'PP F.G ROLL'!A:A,'PP ROLL STOCK'!C6) -> 45930 | E6: {=IFERROR(VLOOKUP(C6,'PP F.G ROLL'!A:T,{2,5,6},0),"-")} -> STOCK | F6: 11 | G6: 5 | H6: =SUMIFS('PP F.G ROLL'!K:K,'PP F.G ROLL'!$A:$A,'PP ROLL STOCK'!$C6) -> 115 | I6: =SUMIFS('PP F.G ROLL'!N:N,'PP F.G ROLL'!$A:$A,'PP ROLL STOCK'!$C6) -> 3325 | J6: =SUMIFS('PP F.G ROLL'!S:S,'PP F.G ROLL'!$A:$A,'PP ROLL STOCK'!$C6) -> 115 | K6: =SUMIFS('PP F.G ROLL'!T:T,'PP F.G ROLL'!$A:$A,'PP ROLL STOCK'!$C6) -> 3325 | L6: =+H6-J6 -> 0 | M6: =+I6-K6 -> 0 | N6: =IFERROR(VLOOKUP(C6,'[1]MIX SALE ORDER'!$A:$E,4,),"OTHERS") -> OTHERS | O6: =VLOOKUP(C6,'PP F.G ROLL'!A:T,4,0) -> PP | P6: FGPTPPR000037 | Q6: / | R6: =CONCATENATE(F6,Q6,G6,) -> 11/5
A7: 8/5 | C7: =+A7 -> 8/5 | D7: =_xlfn.MAXIFS('PP F.G ROLL'!J:J,'PP F.G ROLL'!A:A,'PP ROLL STOCK'!C7) -> 45927 | E7: {=IFERROR(VLOOKUP(C7,'PP F.G ROLL'!A:T,{2,5,6},0),"-")} -> STOCK | F7: 8 | G7: 5 | H7: =SUMIFS('PP F.G ROLL'!K:K,'PP F.G ROLL'!$A:$A,'PP ROLL STOCK'!$C7) -> 145 | I7: =SUMIFS('PP F.G ROLL'!N:N,'PP F.G ROLL'!$A:$A,'PP ROLL STOCK'!$C7) -> 5038.8 | J7: =SUMIFS('PP F.G ROLL'!S:S,'PP F.G ROLL'!$A:$A,'PP ROLL STOCK'!$C7) -> 167 | K7: =SUMIFS('PP F.G ROLL'!T:T,'PP F.G ROLL'!$A:$A,'PP ROLL STOCK'!$C7) -> 4300 | L7: =+H7-J7 -> -22 | M7: =+I7-K7 -> 738.8 | N7: =IFERROR(VLOOKUP(C7,'[1]MIX SALE ORDER'!$A:$E,4,),"OTHERS") -> OTHERS | O7: =VLOOKUP(C7,'PP F.G ROLL'!A:T,4,0) -> PP | P7: #N/A | Q7: / | R7: =CONCATENATE(F7,Q7,G7,) -> 8/5
A8: 7/5 | C8: =+A8 -> 7/5 | D8: =_xlfn.MAXIFS('PP F.G ROLL'!J:J,'PP F.G ROLL'!A:A,'PP ROLL STOCK'!C8) -> 45929 | E8: {=IFERROR(VLOOKUP(C8,'PP F.G ROLL'!A:T,{2,5,6},0),"-")} -> STOCK | F8: 7 | G8: 5 | H8: =SUMIFS('PP F.G ROLL'!K:K,'PP F.G ROLL'!$A:$A,'PP ROLL STOCK'!$C8) -> 115 | I8: =SUMIFS('PP F.G ROLL'!N:N,'PP F.G ROLL'!$A:$A,'PP ROLL STOCK'!$C8) -> 3362.34 | J8: =SUMIFS('PP F.G ROLL'!S:S,'PP F.G ROLL'!$A:$A,'PP ROLL STOCK'!$C8) -> 101 | K8: =SUMIFS('PP F.G ROLL'!T:T,'PP F.G ROLL'!$A:$A,'PP ROLL STOCK'!$C8) -> 2515.12 | L8: =+H8-J8 -> 14 | M8: =+I8-K8 -> 847.22 | N8: =IFERROR(VLOOKUP(C8,'[1]MIX SALE ORDER'!$A:$E,4,),"OTHERS") -> OTHERS | O8: =VLOOKUP(C8,'PP F.G ROLL'!A:T,4,0) -> PP | P8: FGPTPPR000002 | Q8: / | R8: =CONCATENATE(F8,Q8,G8,) -> 7/5
A9: 6/5 | C9: =+A9 -> 6/5 | D9: =_xlfn.MAXIFS('PP F.G ROLL'!J:J,'PP F.G ROLL'!A:A,'PP ROLL STOCK'!C9) -> 45929 | E9: {=IFERROR(VLOOKUP(C9,'PP F.G ROLL'!A:T,{2,5,6},0),"-")} -> STOCK | F9: 6 | G9: 5 | H9: =SUMIFS('PP F.G ROLL'!K:K,'PP F.G ROLL'!$A:$A,'PP ROLL STOCK'!$C9) -> 86 | I9: =SUMIFS('PP F.G ROLL'!N:N,'PP F.G ROLL'!$A:$A,'PP ROLL STOCK'!$C9) -> 2404.73 | J9: =SUMIFS('PP F.G ROLL'!S:S,'PP F.G ROLL'!$A:$A,'PP ROLL STOCK'!$C9) -> 85 | K9: =SUMIFS('PP F.G ROLL'!T:T,'PP F.G ROLL'!$A:$A,'PP ROLL STOCK'!$C9) -> 2125 | L9: =+H9-J9 -> 1 | M9: =+I9-K9 -> 279.73 | N9: =IFERROR(VLOOKUP(C9,'[1]MIX SALE ORDER'!$A:$E,4,),"OTHERS") -> OTHERS | O9: =VLOOKUP(C9,'PP F.G ROLL'!A:T,4,0) -> PP | P9: #N/A | Q9: / | R9: =CONCATENATE(F9,Q9,G9,) -> 6/5
A10: 14/6.5 | C10: =+A10 -> 14/6.5 | D10: =_xlfn.MAXIFS('PP F.G ROLL'!J:J,'PP F.G ROLL'!A:A,'PP ROLL STOCK'!C10) -> 45870 | E10: {=IFERROR(VLOOKUP(C10,'PP F.G ROLL'!A:T,{2,5,6},0),"-")} -> STOCK | F10: 14 | G10: 6.5 | H10: =SUMIFS('PP F.G ROLL'!K:K,'PP F.G ROLL'!$A:$A,'PP ROLL STOCK'!$C10) -> 12 | I10: =SUMIFS('PP F.G ROLL'!N:N,'PP F.G ROLL'!$A:$A,'PP ROLL STOCK'!$C10) -> 478.2 | J10: =SUMIFS('PP F.G ROLL'!S:S,'PP F.G ROLL'!$A:$A,'PP ROLL STOCK'!$C10) -> 0 | K10: =SUMIFS('PP F.G ROLL'!T:T,'PP F.G ROLL'!$A:$A,'PP ROLL STOCK'!$C10) -> 0 | L10: =+H10-J10 -> 12 | M10: =+I10-K10 -> 478.2 | N10: =IFERROR(VLOOKUP(C10,'[1]MIX SALE ORDER'!$A:$E,4,),"OTHERS") -> OTHERS | O10: =VLOOKUP(C10,'PP F.G ROLL'!A:T,4,0) -> PP | P10: #N/A | Q10: / | R10: =CONCATENATE(F10,Q10,G10,) -> 14/6.5
A11: 15/6 | C11: =+A11 -> 15/6 | D11: =_xlfn.MAXIFS('PP F.G ROLL'!J:J,'PP F.G ROLL'!A:A,'PP ROLL STOCK'!C11) -> 45870 | E11: {=IFERROR(VLOOKUP(C11,'PP F.G ROLL'!A:T,{2,5,6},0),"-")} -> STOCK | F11: 15 | G11: 6 | H11: =SUMIFS('PP F.G ROLL'!K:K,'PP F.G ROLL'!$A:$A,'PP ROLL STOCK'!$C11) -> 7 | I11: =SUMIFS('PP F.G ROLL'!N:N,'PP F.G ROLL'!$A:$A,'PP ROLL STOCK'!$C11) -> 212.5 | J11: =SUMIFS('PP F.G ROLL'!S:S,'PP F.G ROLL'!$A:$A,'PP ROLL STOCK'!$C11) -> 0 | K11: =SUMIFS('PP F.G ROLL'!T:T,'PP F.G ROLL'!$A:$A,'PP ROLL STOCK'!$C11) -> 0 | L11: =+H11-J11 -> 7 | M11: =+I11-K11 -> 212.5 | N11: =IFERROR(VLOOKUP(C11,'[1]MIX SALE ORDER'!$A:$E,4,),"OTHERS") -> OTHERS | O11: =VLOOKUP(C11,'PP F.G ROLL'!A:T,4,0) -> PP | P11: FGPTPPR000034 | Q11: / | R11: =CONCATENATE(F11,Q11,G11,) -> 15/6
A12: 18/4 | C12: =+A12 -> 18/4 | D12: =_xlfn.MAXIFS('PP F.G ROLL'!J:J,'PP F.G ROLL'!A:A,'PP ROLL STOCK'!C12) -> 45870 | E12: {=IFERROR(VLOOKUP(C12,'PP F.G ROLL'!A:T,{2,5,6},0),"-")} -> STOCK | F12: 18 | G12: 4 | H12: =SUMIFS('PP F.G ROLL'!K:K,'PP F.G ROLL'!$A:$A,'PP ROLL STOCK'!$C12) -> 15 | I12: =SUMIFS('PP F.G ROLL'!N:N,'PP F.G ROLL'!$A:$A,'PP ROLL STOCK'!$C12) -> 670 | J12: =SUMIFS('PP F.G ROLL'!S:S,'PP F.G ROLL'!$A:$A,'PP ROLL STOCK'!$C12) -> 4 | K12: =SUMIFS('PP F.G ROLL'!T:T,'PP F.G ROLL'!$A:$A,'PP ROLL STOCK'!$C12) -> 100 | L12: =+H12-J12 -> 11 | M12: =+I12-K12 -> 570 | N12: =IFERROR(VLOOKUP(C12,'[1]MIX SALE ORDER'!$A:$E,4,),"OTHERS") -> OTHERS | O12: =VLOOKUP(C12,'PP F.G ROLL'!A:T,4,0) -> PP | P12: #N/A | Q12: / | R12: =CONCATENATE(F12,Q12,G12,) -> 18/4
A13: 7/4 | C13: =+A13 -> 7/4 | D13: =_xlfn.MAXIFS('PP F.G ROLL'!J:J,'PP F.G ROLL'!A:A,'PP ROLL STOCK'!C13) -> 45904 | E13: {=IFERROR(VLOOKUP(C13,'PP F.G ROLL'!A:T,{2,5,6},0),"-")} -> STOCK | F13: 7 | G13: 4 | H13: =SUMIFS('PP F.G ROLL'!K:K,'PP F.G ROLL'!$A:$A,'PP ROLL STOCK'!$C13) -> 8 | I13: =SUMIFS('PP F.G ROLL'!N:N,'PP F.G ROLL'!$A:$A,'PP ROLL STOCK'!$C13) -> 209.67 | J13: =SUMIFS('PP F.G ROLL'!S:S,'PP F.G ROLL'!$A:$A,'PP ROLL STOCK'!$C13) -> 8 | K13: =SUMIFS('PP F.G ROLL'!T:T,'PP F.G ROLL'!$A:$A,'PP ROLL STOCK'!$C13) -> 195 | L13: =+H13-J13 -> 0 | M13: =+I13-K13 -> 14.67 | N13: =IFERROR(VLOOKUP(C13,'[1]MIX SALE ORDER'!$A:$E,4,),"OTHERS") -> OTHERS | O13: =VLOOKUP(C13,'PP F.G ROLL'!A:T,4,0) -> PP | P13: #N/A | Q13: / | R13: =CONCATENATE(F13,Q13,G13,) -> 7/4
A14: 8/4 | C14: =+A14 -> 8/4 | D14: =_xlfn.MAXIFS('PP F.G ROLL'!J:J,'PP F.G ROLL'!A:A,'PP ROLL STOCK'!C14) -> 45870 | E14: {=IFERROR(VLOOKUP(C14,'PP F.G ROLL'!A:T,{2,5,6},0),"-")} -> STOCK | F14: 8 | G14: 4 | H14: =SUMIFS('PP F.G ROLL'!K:K,'PP F.G ROLL'!$A:$A,'PP ROLL STOCK'!$C14) -> 9 | I14: =SUMIFS('PP F.G ROLL'!N:N,'PP F.G ROLL'!$A:$A,'PP ROLL STOCK'!$C14) -> 272.8 | J14: =SUMIFS('PP F.G ROLL'!S:S,'PP F.G ROLL'!$A:$A,'PP ROLL STOCK'!$C14) -> 7 | K14: =SUMIFS('PP F.G ROLL'!T:T,'PP F.G ROLL'!$A:$A,'PP ROLL STOCK'!$C14) -> 175 | L14: =+H14-J14 -> 2 | M14: =+I14-K14 -> 97.8 | N14: =IFERROR(VLOOKUP(C14,'[1]MIX SALE ORDER'!$A:$E,4,),"OTHERS") -> OTHERS | O14: =VLOOKUP(C14,'PP F.G ROLL'!A:T,4,0) -> PP | P14: #N/A | Q14: / | R14: =CONCATENATE(F14,Q14,G14,) -> 8/4
A15: 9/4 | C15: =+A15 -> 9/4 | D15: =_xlfn.MAXIFS('PP F.G ROLL'!J:J,'PP F.G ROLL'!A:A,'PP ROLL STOCK'!C15) -> 45870 | E15: {=IFERROR(VLOOKUP(C15,'PP F.G ROLL'!A:T,{2,5,6},0),"-")} -> STOCK | F15: 9 | G15: 4 | H15: =SUMIFS('PP F.G ROLL'!K:K,'PP F.G ROLL'!$A:$A,'PP ROLL STOCK'!$C15) -> 3 | I15: =SUMIFS('PP F.G ROLL'!N:N,'PP F.G ROLL'!$A:$A,'PP ROLL STOCK'!$C15) -> 101.3 | J15: =SUMIFS('PP F.G ROLL'!S:S,'PP F.G ROLL'!$A:$A,'PP ROLL STOCK'!$C15) -> 4 | K15: =SUMIFS('PP F.G ROLL'!T:T,'PP F.G ROLL'!$A:$A,'PP ROLL STOCK'!$C15) -> 100 | L15: =+H15-J15 -> -1 | M15: =+I15-K15 -> 1.3 | N15: =IFERROR(VLOOKUP(C15,'[1]MIX SALE ORDER'!$A:$E,4,),"OTHERS") -> OTHERS | O15: =VLOOKUP(C15,'PP F.G ROLL'!A:T,4,0) -> PP | P15: #N/A | Q15: / | R15: =CONCATENATE(F15,Q15,G15,) -> 9/4
A16: 2/5.5-6 | C16: =+A16 -> 2/5.5-6 | D16: =_xlfn.MAXIFS('PP F.G ROLL'!J:J,'PP F.G ROLL'!A:A,'PP ROLL STOCK'!C16) -> 45930 | E16: {=IFERROR(VLOOKUP(C16,'PP F.G ROLL'!A:T,{2,5,6},0),"-")} -> جیلانی پولی سٹاک | F16: 2 | G16: 5.5-6 | H16: =SUMIFS('PP F.G ROLL'!K:K,'PP F.G ROLL'!$A:$A,'PP ROLL STOCK'!$C16) -> 6 | I16: =SUMIFS('PP F.G ROLL'!N:N,'PP F.G ROLL'!$A:$A,'PP ROLL STOCK'!$C16) -> 180 | J16: =SUMIFS('PP F.G ROLL'!S:S,'PP F.G ROLL'!$A:$A,'PP ROLL STOCK'!$C16) -> 6 | K16: =SUMIFS('PP F.G ROLL'!T:T,'PP F.G ROLL'!$A:$A,'PP ROLL STOCK'!$C16) -> 180 | L16: =+H16-J16 -> 0 | M16: =+I16-K16 -> 0 | N16: =IFERROR(VLOOKUP(C16,'[1]MIX SALE ORDER'!$A:$E,4,),"OTHERS") -> OTHERS | O16: =VLOOKUP(C16,'PP F.G ROLL'!A:T,4,0) -> PP | P16: #N/A | Q16: / | R16: =CONCATENATE(F16,Q16,G16,) -> 2/5.5-6
A17: 24/5 | C17: =+A17 -> 24/5 | D17: =_xlfn.MAXIFS('PP F.G ROLL'!J:J,'PP F.G ROLL'!A:A,'PP ROLL STOCK'!C17) -> 45930 | E17: {=IFERROR(VLOOKUP(C17,'PP F.G ROLL'!A:T,{2,5,6},0),"-")} -> STOCK | F17: 24 | G17: 5 | H17: =SUMIFS('PP F.G ROLL'!K:K,'PP F.G ROLL'!$A:$A,'PP ROLL STOCK'!$C17) -> 68 | I17: =SUMIFS('PP F.G ROLL'!N:N,'PP F.G ROLL'!$A:$A,'PP ROLL STOCK'!$C17) -> 2440.5 | J17: =SUMIFS('PP F.G ROLL'!S:S,'PP F.G ROLL'!$A:$A,'PP ROLL STOCK'!$C17) -> 68 | K17: =SUMIFS('PP F.G ROLL'!T:T,'PP F.G ROLL'!$A:$A,'PP ROLL STOCK'!$C17) -> 2440.5 | L17: =+H17-J17 -> 0 | M17: =+I17-K17 -> 0 | N17: =IFERROR(VLOOKUP(C17,'[1]MIX SALE ORDER'!$A:$E,4,),"OTHERS") -> OTHERS | O17: =VLOOKUP(C17,'PP F.G ROLL'!A:T,4,0) -> PP | P17: #N/A | Q17: / | R17: =CONCATENATE(F17,Q17,G17,) -> 24/5
A18: 20/5 | C18: =+A18 -> 20/5 | D18: =_xlfn.MAXIFS('PP F.G ROLL'!J:J,'PP F.G ROLL'!A:A,'PP ROLL STOCK'!C18) -> 45924 | E18: {=IFERROR(VLOOKUP(C18,'PP F.G ROLL'!A:T,{2,5,6},0),"-")} -> STOCK | F18: 20 | G18: 5 | H18: =SUMIFS('PP F.G ROLL'!K:K,'PP F.G ROLL'!$A:$A,'PP ROLL STOCK'!$C18) -> 39 | I18: =SUMIFS('PP F.G ROLL'!N:N,'PP F.G ROLL'!$A:$A,'PP ROLL STOCK'!$C18) -> 2062.64 | J18: =SUMIFS('PP F.G ROLL'!S:S,'PP F.G ROLL'!$A:$A,'PP ROLL STOCK'!$C18) -> 46 | K18: =SUMIFS('PP F.G ROLL'!T:T,'PP F.G ROLL'!$A:$A,'PP ROLL STOCK'!$C18) -> 1131.2 | L18: =+H18-J18 -> -7 | M18: =+I18-K18 -> 931.44 | N18: =IFERROR(VLOOKUP(C18,'[1]MIX SALE ORDER'!$A:$E,4,),"OTHERS") -> OTHERS | O18: =VLOOKUP(C18,'PP F.G ROLL'!A:T,4,0) -> PP | P18: #N/A | Q18: / | R18: =CONCATENATE(F18,Q18,G18,) -> 20/5
A19: 19/5 | C19: =+A19 -> 19/5 | D19: =_xlfn.MAXIFS('PP F.G ROLL'!J:J,'PP F.G ROLL'!A:A,'PP ROLL STOCK'!C19) -> 45870 | E19: {=IFERROR(VLOOKUP(C19,'PP F.G ROLL'!A:T,{2,5,6},0),"-")} -> STOCK | F19: 19 | G19: 5 | H19: =SUMIFS('PP F.G ROLL'!K:K,'PP F.G ROLL'!$A:$A,'PP ROLL STOCK'!$C19) -> 10 | I19: =SUMIFS('PP F.G ROLL'!N:N,'PP F.G ROLL'!$A:$A,'PP ROLL STOCK'!$C19) -> 547 | J19: =SUMIFS('PP F.G ROLL'!S:S,'PP F.G ROLL'!$A:$A,'PP ROLL STOCK'!$C19) -> 0 | K19: =SUMIFS('PP F.G ROLL'!T:T,'PP F.G ROLL'!$A:$A,'PP ROLL STOCK'!$C19) -> 0 | L19: =+H19-J19 -> 10 | M19: =+I19-K19 -> 547 | N19: =IFERROR(VLOOKUP(C19,'[1]MIX SALE ORDER'!$A:$E,4,),"OTHERS") -> OTHERS | O19: =VLOOKUP(C19,'PP F.G ROLL'!A:T,4,0) -> PP | P19: #N/A | Q19: / | R19: =CONCATENATE(F19,Q19,G19,) -> 19/5
A20: 17/5 | C20: =+A20 -> 17/5 | D20: =_xlfn.MAXIFS('PP F.G ROLL'!J:J,'PP F.G ROLL'!A:A,'PP ROLL STOCK'!C20) -> 45870 | E20: {=IFERROR(VLOOKUP(C20,'PP F.G ROLL'!A:T,{2,5,6},0),"-")} -> STOCK | F20: 17 | G20: 5 | H20: =SUMIFS('PP F.G ROLL'!K:K,'PP F.G ROLL'!$A:$A,'PP ROLL STOCK'!$C20) -> 4 | I20: =SUMIFS('PP F.G ROLL'!N:N,'PP F.G ROLL'!$A:$A,'PP ROLL STOCK'!$C20) -> 135.2 | J20: =SUMIFS('PP F.G ROLL'!S:S,'PP F.G ROLL'!$A:$A,'PP ROLL STOCK'!$C20) -> 4 | K20: =SUMIFS('PP F.G ROLL'!T:T,'PP F.G ROLL'!$A:$A,'PP ROLL STOCK'!$C20) -> 100 | L20: =+H20-J20 -> 0 | M20: =+I20-K20 -> 35.2 | N20: =IFERROR(VLOOKUP(C20,'[1]MIX SALE ORDER'!$A:$E,4,),"OTHERS") -> OTHERS | O20: =VLOOKUP(C20,'PP F.G ROLL'!A:T,4,0) -> PP | P20: FGPTPPR000012 | Q20: / | R20: =CONCATENATE(F20,Q20,G20,) -> 17/5
A21: 18/5 | C21: =+A21 -> 18/5 | D21: =_xlfn.MAXIFS('PP F.G ROLL'!J:J,'PP F.G ROLL'!A:A,'PP ROLL STOCK'!C21) -> 45930 | E21: {=IFERROR(VLOOKUP(C21,'PP F.G ROLL'!A:T,{2,5,6},0),"-")} -> STOCK | F21: 18 | G21: 5 | H21: =SUMIFS('PP F.G ROLL'!K:K,'PP F.G ROLL'!$A:$A,'PP ROLL STOCK'!$C21) -> 79 | I21: =SUMIFS('PP F.G ROLL'!N:N,'PP F.G ROLL'!$A:$A,'PP ROLL STOCK'!$C21) -> 1979.8 | J21: =SUMIFS('PP F.G ROLL'!S:S,'PP F.G ROLL'!$A:$A,'PP ROLL STOCK'!$C21) -> 79 | K21: =SUMIFS('PP F.G ROLL'!T:T,'PP F.G ROLL'!$A:$A,'PP ROLL STOCK'!$C21) -> 1979.8 | L21: =+H21-J21 -> 0 | M21: =+I21-K21 -> 0 | N21: =IFERROR(VLOOKUP(C21,'[1]MIX SALE ORDER'!$A:$E,4,),"OTHERS") -> OTHERS | O21: =VLOOKUP(C21,'PP F.G ROLL'!A:T,4,0) -> PP | P21: #N/A | Q21: / | R21: =CONCATENATE(F21,Q21,G21,) -> 18/5
A22: 16/5 | C22: =+A22 -> 16/5 | D22: =_xlfn.MAXIFS('PP F.G ROLL'!J:J,'PP F.G ROLL'!A:A,'PP ROLL STOCK'!C22) -> 45929 | E22: {=IFERROR(VLOOKUP(C22,'PP F.G ROLL'!A:T,{2,5,6},0),"-")} -> STOCK | F22: 16 | G22: 5 | H22: =SUMIFS('PP F.G ROLL'!K:K,'PP F.G ROLL'!$A:$A,'PP ROLL STOCK'!$C22) -> 74 | I22: =SUMIFS('PP F.G ROLL'!N:N,'PP F.G ROLL'!$A:$A,'PP ROLL STOCK'!$C22) -> 3245.28 | J22: =SUMIFS('PP F.G ROLL'!S:S,'PP F.G ROLL'!$A:$A,'PP ROLL STOCK'!$C22) -> 35 | K22: =SUMIFS('PP F.G ROLL'!T:T,'PP F.G ROLL'!$A:$A,'PP ROLL STOCK'!$C22) -> 951.31 | L22: =+H22-J22 -> 39 | M22: =+I22-K22 -> 2293.97 | N22: =IFERROR(VLOOKUP(C22,'[1]MIX SALE ORDER'!$A:$E,4,),"OTHERS") -> OTHERS | O22: =VLOOKUP(C22,'PP F.G ROLL'!A:T,4,0) -> PP | P22: FGPTPPR000011 | Q22: / | R22: =CONCATENATE(F22,Q22,G22,) -> 16/5
A23: 15/5 | C23: =+A23 -> 15/5 | D23: =_xlfn.MAXIFS('PP F.G ROLL'!J:J,'PP F.G ROLL'!A:A,'PP ROLL STOCK'!C23) -> 45870 | E23: {=IFERROR(VLOOKUP(C23,'PP F.G ROLL'!A:T,{2,5,6},0),"-")} -> STOCK | F23: 15 | G23: 5 | H23: =SUMIFS('PP F.G ROLL'!K:K,'PP F.G ROLL'!$A:$A,'PP ROLL STOCK'!$C23) -> 26 | I23: =SUMIFS('PP F.G ROLL'!N:N,'PP F.G ROLL'!$A:$A,'PP ROLL STOCK'!$C23) -> 957 | J23: =SUMIFS('PP F.G ROLL'!S:S,'PP F.G ROLL'!$A:$A,'PP ROLL STOCK'!$C23) -> 0 | K23: =SUMIFS('PP F.G ROLL'!T:T,'PP F.G ROLL'!$A:$A,'PP ROLL STOCK'!$C23) -> 0 | L23: =+H23-J23 -> 26 | M23: =+I23-K23 -> 957 | N23: =IFERROR(VLOOKUP(C23,'[1]MIX SALE ORDER'!$A:$E,4,),"OTHERS") -> OTHERS | O23: =VLOOKUP(C23,'PP F.G ROLL'!A:T,4,0) -> PP | P23: FGPTPPR000010 | Q23: / | R23: =CONCATENATE(F23,Q23,G23,) -> 15/5
A24: 2/6.5 | C24: =+A24 -> 2/6.5 | D24: =_xlfn.MAXIFS('PP F.G ROLL'!J:J,'PP F.G ROLL'!A:A,'PP ROLL STOCK'!C24) -> 45870 | E24: {=IFERROR(VLOOKUP(C24,'PP F.G ROLL'!A:T,{2,5,6},0),"-")} -> STOCK | F24: 2 | G24: 6.5 | H24: =SUMIFS('PP F.G ROLL'!K:K,'PP F.G ROLL'!$A:$A,'PP ROLL STOCK'!$C24) -> 4 | I24: =SUMIFS('PP F.G ROLL'!N:N,'PP F.G ROLL'!$A:$A,'PP ROLL STOCK'!$C24) -> 185.2 | J24: =SUMIFS('PP F.G ROLL'!S:S,'PP F.G ROLL'!$A:$A,'PP ROLL STOCK'!$C24) -> 0 | K24: =SUMIFS('PP F.G ROLL'!T:T,'PP F.G ROLL'!$A:$A,'PP ROLL STOCK'!$C24) -> 0 | L24: =+H24-J24 -> 4 | M24: =+I24-K24 -> 185.2 | N24: =IFERROR(VLOOKUP(C24,'[1]MIX SALE ORDER'!$A:$E,4,),"OTHERS") -> OTHERS | O24: =VLOOKUP(C24,'PP F.G ROLL'!A:T,4,0) -> PP | P24: #N/A | Q24: / | R24: =CONCATENATE(F24,Q24,G24,) -> 2/6.5
A25: 19/4 | C25: =+A25 -> 19/4 | D25: =_xlfn.MAXIFS('PP F.G ROLL'!J:J,'PP F.G ROLL'!A:A,'PP ROLL STOCK'!C25) -> 45870 | E25: {=IFERROR(VLOOKUP(C25,'PP F.G ROLL'!A:T,{2,5,6},0),"-")} -> STOCK | F25: 19 | G25: 4 | H25: =SUMIFS('PP F.G ROLL'!K:K,'PP F.G ROLL'!$A:$A,'PP ROLL STOCK'!$C25) -> 1 | I25: =SUMIFS('PP F.G ROLL'!N:N,'PP F.G ROLL'!$A:$A,'PP ROLL STOCK'!$C25) -> 20.1 | J25: =SUMIFS('PP F.G ROLL'!S:S,'PP F.G ROLL'!$A:$A,'PP ROLL STOCK'!$C25) -> 0 | K25: =SUMIFS('PP F.G ROLL'!T:T,'PP F.G ROLL'!$A:$A,'PP ROLL STOCK'!$C25) -> 0 | L25: =+H25-J25 -> 1 | M25: =+I25-K25 -> 20.1 | N25: =IFERROR(VLOOKUP(C25,'[1]MIX SALE ORDER'!$A:$E,4,),"OTHERS") -> OTHERS | O25: =VLOOKUP(C25,'PP F.G ROLL'!A:T,4,0) -> PP | P25: #N/A | Q25: / | R25: =CONCATENATE(F25,Q25,G25,) -> 19/4
A26: 24/4 | C26: =+A26 -> 24/4 | D26: =_xlfn.MAXIFS('PP F.G ROLL'!J:J,'PP F.G ROLL'!A:A,'PP ROLL STOCK'!C26) -> 45870 | E26: {=IFERROR(VLOOKUP(C26,'PP F.G ROLL'!A:T,{2,5,6},0),"-")} -> STOCK | F26: 24 | G26: 4 | H26: =SUMIFS('PP F.G ROLL'!K:K,'PP F.G ROLL'!$A:$A,'PP ROLL STOCK'!$C26) -> 1 | I26: =SUMIFS('PP F.G ROLL'!N:N,'PP F.G ROLL'!$A:$A,'PP ROLL STOCK'!$C26) -> 39.6 | J26: =SUMIFS('PP F.G ROLL'!S:S,'PP F.G ROLL'!$A:$A,'PP ROLL STOCK'!$C26) -> 0 | K26: =SUMIFS('PP F.G ROLL'!T:T,'PP F.G ROLL'!$A:$A,'PP ROLL STOCK'!$C26) -> 0 | L26: =+H26-J26 -> 1 | M26: =+I26-K26 -> 39.6 | N26: =IFERROR(VLOOKUP(C26,'[1]MIX SALE ORDER'!$A:$E,4,),"OTHERS") -> OTHERS | O26: =VLOOKUP(C26,'PP F.G ROLL'!A:T,4,0) -> PP | P26: #N/A | Q26: / | R26: =CONCATENATE(F26,Q26,G26,) -> 24/4
A27: 6/4 | C27: =+A27 -> 6/4 | D27: =_xlfn.MAXIFS('PP F.G ROLL'!J:J,'PP F.G ROLL'!A:A,'PP ROLL STOCK'!C27) -> 45870 | E27: {=IFERROR(VLOOKUP(C27,'PP F.G ROLL'!A:T,{2,5,6},0),"-")} -> STOCK | F27: 6 | G27: 4 | H27: =SUMIFS('PP F.G ROLL'!K:K,'PP F.G ROLL'!$A:$A,'PP ROLL STOCK'!$C27) -> 6 | I27: =SUMIFS('PP F.G ROLL'!N:N,'PP F.G ROLL'!$A:$A,'PP ROLL STOCK'!$C27) -> 191.4 | J27: =SUMIFS('PP F.G ROLL'!S:S,'PP F.G ROLL'!$A:$A,'PP ROLL STOCK'!$C27) -> 0 | K27: =SUMIFS('PP F.G ROLL'!T:T,'PP F.G ROLL'!$A:$A,'PP ROLL STOCK'!$C27) -> 0 | L27: =+H27-J27 -> 6 | M27: =+I27-K27 -> 191.4 | N27: =IFERROR(VLOOKUP(C27,'[1]MIX SALE ORDER'!$A:$E,4,),"OTHERS") -> OTHERS | O27: =VLOOKUP(C27,'PP F.G ROLL'!A:T,4,0) -> PP | P27: #N/A | Q27: / | R27: =CONCATENATE(F27,Q27,G27,) -> 6/4
A28: 12/6.5 | C28: =+A28 -> 12/6.5 | D28: =_xlfn.MAXIFS('PP F.G ROLL'!J:J,'PP F.G ROLL'!A:A,'PP ROLL STOCK'!C28) -> 45918 | E28: {=IFERROR(VLOOKUP(C28,'PP F.G ROLL'!A:T,{2,5,6},0),"-")} -> STOCK | F28: 12 | G28: 6.5 | H28: =SUMIFS('PP F.G ROLL'!K:K,'PP F.G ROLL'!$A:$A,'PP ROLL STOCK'!$C28) -> 13 | I28: =SUMIFS('PP F.G ROLL'!N:N,'PP F.G ROLL'!$A:$A,'PP ROLL STOCK'!$C28) -> 395.74 | J28: =SUMIFS('PP F.G ROLL'!S:S,'PP F.G ROLL'!$A:$A,'PP ROLL STOCK'!$C28) -> 8 | K28: =SUMIFS('PP F.G ROLL'!T:T,'PP F.G ROLL'!$A:$A,'PP ROLL STOCK'!$C28) -> 277.39 | L28: =+H28-J28 -> 5 | M28: =+I28-K28 -> 118.35 | N28: =IFERROR(VLOOKUP(C28,'[1]MIX SALE ORDER'!$A:$E,4,),"OTHERS") -> OTHERS | O28: =VLOOKUP(C28,'PP F.G ROLL'!A:T,4,0) -> PP | P28: #N/A | Q28: / | R28: =CONCATENATE(F28,Q28,G28,) -> 12/6.5
A29: 17/7 | C29: =+A29 -> 17/7 | D29: =_xlfn.MAXIFS('PP F.G ROLL'!J:J,'PP F.G ROLL'!A:A,'PP ROLL STOCK'!C29) -> 45870 | E29: {=IFERROR(VLOOKUP(C29,'PP F.G ROLL'!A:T,{2,5,6},0),"-")} -> STOCK | F29: 17 | G29: 7 | H29: =SUMIFS('PP F.G ROLL'!K:K,'PP F.G ROLL'!$A:$A,'PP ROLL STOCK'!$C29) -> 7 | I29: =SUMIFS('PP F.G ROLL'!N:N,'PP F.G ROLL'!$A:$A,'PP ROLL STOCK'!$C29) -> 333.1 | J29: =SUMIFS('PP F.G ROLL'!S:S,'PP F.G ROLL'!$A:$A,'PP ROLL STOCK'!$C29) -> 8 | K29: =SUMIFS('PP F.G ROLL'!T:T,'PP F.G ROLL'!$A:$A,'PP ROLL STOCK'!$C29) -> 200 | L29: =+H29-J29 -> -1 | M29: =+I29-K29 -> 133.1 | N29: =IFERROR(VLOOKUP(C29,'[1]MIX SALE ORDER'!$A:$E,4,),"OTHERS") -> OTHERS | O29: =VLOOKUP(C29,'PP F.G ROLL'!A:T,4,0) -> PP | P29: #N/A | Q29: / | R29: =CONCATENATE(F29,Q29,G29,) -> 17/7
A30: 15/4 | C30: =+A30 -> 15/4 | D30: =_xlfn.MAXIFS('PP F.G ROLL'!J:J,'PP F.G ROLL'!A:A,'PP ROLL STOCK'!C30) -> 45870 | E30: {=IFERROR(VLOOKUP(C30,'PP F.G ROLL'!A:T,{2,5,6},0),"-")} -> STOCK | F30: 15 | G30: 4 | H30: =SUMIFS('PP F.G ROLL'!K:K,'PP F.G ROLL'!$A:$A,'PP ROLL STOCK'!$C30) -> 7 | I30: =SUMIFS('PP F.G ROLL'!N:N,'PP F.G ROLL'!$A:$A,'PP ROLL STOCK'!$C30) -> 489.5 | J30: =SUMIFS('PP F.G ROLL'!S:S,'PP F.G ROLL'!$A:$A,'PP ROLL STOCK'!$C30) -> 0 | K30: =SUMIFS('PP F.G ROLL'!T:T,'PP F.G ROLL'!$A:$A,'PP ROLL STOCK'!$C30) -> 0 | L30: =+H30-J30 -> 7 | M30: =+I30-K30 -> 489.5 | N30: =IFERROR(VLOOKUP(C30,'[1]MIX SALE ORDER'!$A:$E,4,),"OTHERS") -> OTHERS | O30: =VLOOKUP(C30,'PP F.G ROLL'!A:T,4,0) -> PP | P30: #N/A | Q30: / | R30: =CONCATENATE(F30,Q30,G30,) -> 15/4
A31: 16/8 | C31: =+A31 -> 16/8 | D31: =_xlfn.MAXIFS('PP F.G ROLL'!J:J,'PP F.G ROLL'!A:A,'PP ROLL STOCK'!C31) -> 45905 | E31: {=IFERROR(VLOOKUP(C31,'PP F.G ROLL'!A:T,{2,5,6},0),"-")} -> STOCK | F31: 16 | G31: 8 | H31: =SUMIFS('PP F.G ROLL'!K:K,'PP F.G ROLL'!$A:$A,'PP ROLL STOCK'!$C31) -> 15 | I31: =SUMIFS('PP F.G ROLL'!N:N,'PP F.G ROLL'!$A:$A,'PP ROLL STOCK'!$C31) -> 307.83 | J31: =SUMIFS('PP F.G ROLL'!S:S,'PP F.G ROLL'!$A:$A,'PP ROLL STOCK'!$C31) -> 0 | K31: =SUMIFS('PP F.G ROLL'!T:T,'PP F.G ROLL'!$A:$A,'PP ROLL STOCK'!$C31) -> 0 | L31: =+H31-J31 -> 15 | M31: =+I31-K31 -> 307.83 | N31: =IFERROR(VLOOKUP(C31,'[1]MIX SALE ORDER'!$A:$E,4,),"OTHERS") -> OTHERS | O31: =VLOOKUP(C31,'PP F.G ROLL'!A:T,4,0) -> PP | P31: #N/A | Q31: / | R31: =CONCATENATE(F31,Q31,G31,) -> 16/8
A32: 15/7 | C32: =+A32 -> 15/7 | D32: =_xlfn.MAXIFS('PP F.G ROLL'!J:J,'PP F.G ROLL'!A:A,'PP ROLL STOCK'!C32) -> 45925 | E32: {=IFERROR(VLOOKUP(C32,'PP F.G ROLL'!A:T,{2,5,6},0),"-")} -> STOCK | F32: 15 | G32: 7 | H32: =SUMIFS('PP F.G ROLL'!K:K,'PP F.G ROLL'!$A:$A,'PP ROLL STOCK'!$C32) -> 17 | I32: =SUMIFS('PP F.G ROLL'!N:N,'PP F.G ROLL'!$A:$A,'PP ROLL STOCK'!$C32) -> 633.98 | J32: =SUMIFS('PP F.G ROLL'!S:S,'PP F.G ROLL'!$A:$A,'PP ROLL STOCK'!$C32) -> 24 | K32: =SUMIFS('PP F.G ROLL'!T:T,'PP F.G ROLL'!$A:$A,'PP ROLL STOCK'!$C32) -> 605.7 | L32: =+H32-J32 -> -7 | M32: =+I32-K32 -> 28.28 | N32: =IFERROR(VLOOKUP(C32,'[1]MIX SALE ORDER'!$A:$E,4,),"OTHERS") -> OTHERS | O32: =VLOOKUP(C32,'PP F.G ROLL'!A:T,4,0) -> PP | P32: #N/A | Q32: / | R32: =CONCATENATE(F32,Q32,G32,) -> 15/7
A33: 8/6.5 | C33: =+A33 -> 8/6.5 | D33: =_xlfn.MAXIFS('PP F.G ROLL'!J:J,'PP F.G ROLL'!A:A,'PP ROLL STOCK'!C33) -> 45870 | E33: {=IFERROR(VLOOKUP(C33,'PP F.G ROLL'!A:T,{2,5,6},0),"-")} -> STOCK | F33: 8 | G33: 6.5 | H33: =SUMIFS('PP F.G ROLL'!K:K,'PP F.G ROLL'!$A:$A,'PP ROLL STOCK'!$C33) -> 2 | I33: =SUMIFS('PP F.G ROLL'!N:N,'PP F.G ROLL'!$A:$A,'PP ROLL STOCK'!$C33) -> 271.4 | J33: =SUMIFS('PP F.G ROLL'!S:S,'PP F.G ROLL'!$A:$A,'PP ROLL STOCK'!$C33) -> 0 | K33: =SUMIFS('PP F.G ROLL'!T:T,'PP F.G ROLL'!$A:$A,'PP ROLL STOCK'!$C33) -> 0 | L33: =+H33-J33 -> 2 | M33: =+I33-K33 -> 271.4 | N33: =IFERROR(VLOOKUP(C33,'[1]MIX SALE ORDER'!$A:$E,4,),"OTHERS") -> OTHERS | O33: =VLOOKUP(C33,'PP F.G ROLL'!A:T,4,0) -> PP | P33: #N/A | Q33: / | R33: =CONCATENATE(F33,Q33,G33,) -> 8/6.5
A34: 18/7 | C34: =+A34 -> 18/7 | D34: =_xlfn.MAXIFS('PP F.G ROLL'!J:J,'PP F.G ROLL'!A:A,'PP ROLL STOCK'!C34) -> 45905 | E34: {=IFERROR(VLOOKUP(C34,'PP F.G ROLL'!A:T,{2,5,6},0),"-")} -> STOCK | F34: 18 | G34: 7 | H34: =SUMIFS('PP F.G ROLL'!K:K,'PP F.G ROLL'!$A:$A,'PP ROLL STOCK'!$C34) -> 13 | I34: =SUMIFS('PP F.G ROLL'!N:N,'PP F.G ROLL'!$A:$A,'PP ROLL STOCK'!$C34) -> 309.52 | J34: =SUMIFS('PP F.G ROLL'!S:S,'PP F.G ROLL'!$A:$A,'PP ROLL STOCK'!$C34) -> 7 | K34: =SUMIFS('PP F.G ROLL'!T:T,'PP F.G ROLL'!$A:$A,'PP ROLL STOCK'!$C34) -> 287.03 | L34: =+H34-J34 -> 6 | M34: =+I34-K34 -> 22.49 | N34: =IFERROR(VLOOKUP(C34,'[1]MIX SALE ORDER'!$A:$E,4,),"OTHERS") -> OTHERS | O34: =VLOOKUP(C34,'PP F.G ROLL'!A:T,4,0) -> PP | P34: #N/A | Q34: / | R34: =CONCATENATE(F34,Q34,G34,) -> 18/7
A35: 8/10 | C35: =+A35 -> 8/10 | D35: =_xlfn.MAXIFS('PP F.G ROLL'!J:J,'PP F.G ROLL'!A:A,'PP ROLL STOCK'!C35) -> 45915 | E35: {=IFERROR(VLOOKUP(C35,'PP F.G ROLL'!A:T,{2,5,6},0),"-")} -> STOCK | F35: 8 | G35: 10 | H35: =SUMIFS('PP F.G ROLL'!K:K,'PP F.G ROLL'!$A:$A,'PP ROLL STOCK'!$C35) -> 7 | I35: =SUMIFS('PP F.G ROLL'!N:N,'PP F.G ROLL'!$A:$A,'PP ROLL STOCK'!$C35) -> 189.34 | J35: =SUMIFS('PP F.G ROLL'!S:S,'PP F.G ROLL'!$A:$A,'PP ROLL STOCK'!$C35) -> 6 | K35: =SUMIFS('PP F.G ROLL'!T:T,'PP F.G ROLL'!$A:$A,'PP ROLL STOCK'!$C35) -> 160.25 | L35: =+H35-J35 -> 1 | M35: =+I35-K35 -> 29.09 | N35: =IFERROR(VLOOKUP(C35,'[1]MIX SALE ORDER'!$A:$E,4,),"OTHERS") -> OTHERS | O35: =VLOOKUP(C35,'PP F.G ROLL'!A:T,4,0) -> PP | P35: #N/A | Q35: / | R35: =CONCATENATE(F35,Q35,G35,) -> 8/10
A36: 9/10 | C36: =+A36 -> 9/10 | D36: =_xlfn.MAXIFS('PP F.G ROLL'!J:J,'PP F.G ROLL'!A:A,'PP ROLL STOCK'!C36) -> 45870 | E36: {=IFERROR(VLOOKUP(C36,'PP F.G ROLL'!A:T,{2,5,6},0),"-")} -> STOCK | F36: 9 | G36: 10 | H36: =SUMIFS('PP F.G ROLL'!K:K,'PP F.G ROLL'!$A:$A,'PP ROLL STOCK'!$C36) -> 1 | I36: =SUMIFS('PP F.G ROLL'!N:N,'PP F.G ROLL'!$A:$A,'PP ROLL STOCK'!$C36) -> 30.1 | J36: =SUMIFS('PP F.G ROLL'!S:S,'PP F.G ROLL'!$A:$A,'PP ROLL STOCK'!$C36) -> 0 | K36: =SUMIFS('PP F.G ROLL'!T:T,'PP F.G ROLL'!$A:$A,'PP ROLL STOCK'!$C36) -> 0 | L36: =+H36-J36 -> 1 | M36: =+I36-K36 -> 30.1 | N36: =IFERROR(VLOOKUP(C36,'[1]MIX SALE ORDER'!$A:$E,4,),"OTHERS") -> OTHERS | O36: =VLOOKUP(C36,'PP F.G ROLL'!A:T,4,0) -> PP | P36: #N/A | Q36: / | R36: =CONCATENATE(F36,Q36,G36,) -> 9/10
A37: 16/7 | C37: =+A37 -> 16/7 | D37: =_xlfn.MAXIFS('PP F.G ROLL'!J:J,'PP F.G ROLL'!A:A,'PP ROLL STOCK'!C37) -> 45870 | E37: {=IFERROR(VLOOKUP(C37,'PP F.G ROLL'!A:T,{2,5,6},0),"-")} -> STOCK | F37: 16 | G37: 7 | H37: =SUMIFS('PP F.G ROLL'!K:K,'PP F.G ROLL'!$A:$A,'PP ROLL STOCK'!$C37) -> 2 | I37: =SUMIFS('PP F.G ROLL'!N:N,'PP F.G ROLL'!$A:$A,'PP ROLL STOCK'!$C37) -> 169.8 | J37: =SUMIFS('PP F.G ROLL'!S:S,'PP F.G ROLL'!$A:$A,'PP ROLL STOCK'!$C37) -> 0 | K37: =SUMIFS('PP F.G ROLL'!T:T,'PP F.G ROLL'!$A:$A,'PP ROLL STOCK'!$C37) -> 0 | L37: =+H37-J37 -> 2 | M37: =+I37-K37 -> 169.8 | N37: =IFERROR(VLOOKUP(C37,'[1]MIX SALE ORDER'!$A:$E,4,),"OTHERS") -> OTHERS | O37: =VLOOKUP(C37,'PP F.G ROLL'!A:T,4,0) -> PP | P37: FGPTPPR000038 | Q37: / | R37: =CONCATENATE(F37,Q37,G37,) -> 16/7
A38: 20/12 | C38: =+A38 -> 20/12 | D38: =_xlfn.MAXIFS('PP F.G ROLL'!J:J,'PP F.G ROLL'!A:A,'PP ROLL STOCK'!C38) -> 45870 | E38: {=IFERROR(VLOOKUP(C38,'PP F.G ROLL'!A:T,{2,5,6},0),"-")} -> STOCK | F38: 20 | G38: 12 | H38: =SUMIFS('PP F.G ROLL'!K:K,'PP F.G ROLL'!$A:$A,'PP ROLL STOCK'!$C38) -> 1 | I38: =SUMIFS('PP F.G ROLL'!N:N,'PP F.G ROLL'!$A:$A,'PP ROLL STOCK'!$C38) -> 33 | J38: =SUMIFS('PP F.G ROLL'!S:S,'PP F.G ROLL'!$A:$A,'PP ROLL STOCK'!$C38) -> 0 | K38: =SUMIFS('PP F.G ROLL'!T:T,'PP F.G ROLL'!$A:$A,'PP ROLL STOCK'!$C38) -> 0 | L38: =+H38-J38 -> 1 | M38: =+I38-K38 -> 33 | N38: =IFERROR(VLOOKUP(C38,'[1]MIX SALE ORDER'!$A:$E,4,),"OTHERS") -> OTHERS | O38: =VLOOKUP(C38,'PP F.G ROLL'!A:T,4,0) -> PP | P38: #N/A | Q38: / | R38: =CONCATENATE(F38,Q38,G38,) -> 20/12
A39: 22/15 | C39: =+A39 -> 22/15 | D39: =_xlfn.MAXIFS('PP F.G ROLL'!J:J,'PP F.G ROLL'!A:A,'PP ROLL STOCK'!C39) -> 45870 | E39: {=IFERROR(VLOOKUP(C39,'PP F.G ROLL'!A:T,{2,5,6},0),"-")} -> STOCK | F39: 22 | G39: 15 | H39: =SUMIFS('PP F.G ROLL'!K:K,'PP F.G ROLL'!$A:$A,'PP ROLL STOCK'!$C39) -> 1 | I39: =SUMIFS('PP F.G ROLL'!N:N,'PP F.G ROLL'!$A:$A,'PP ROLL STOCK'!$C39) -> 43.8 | J39: =SUMIFS('PP F.G ROLL'!S:S,'PP F.G ROLL'!$A:$A,'PP ROLL STOCK'!$C39) -> 0 | K39: =SUMIFS('PP F.G ROLL'!T:T,'PP F.G ROLL'!$A:$A,'PP ROLL STOCK'!$C39) -> 0 | L39: =+H39-J39 -> 1 | M39: =+I39-K39 -> 43.8 | N39: =IFERROR(VLOOKUP(C39,'[1]MIX SALE ORDER'!$A:$E,4,),"OTHERS") -> OTHERS | O39: =VLOOKUP(C39,'PP F.G ROLL'!A:T,4,0) -> PP | P39: #N/A | Q39: / | R39: =CONCATENATE(F39,Q39,G39,) -> 22/15
A40: 18/10 | C40: =+A40 -> 18/10 | D40: =_xlfn.MAXIFS('PP F.G ROLL'!J:J,'PP F.G ROLL'!A:A,'PP ROLL STOCK'!C40) -> 45870 | E40: {=IFERROR(VLOOKUP(C40,'PP F.G ROLL'!A:T,{2,5,6},0),"-")} -> STOCK | F40: 18 | G40: 10 | H40: =SUMIFS('PP F.G ROLL'!K:K,'PP F.G ROLL'!$A:$A,'PP ROLL STOCK'!$C40) -> 2 | I40: =SUMIFS('PP F.G ROLL'!N:N,'PP F.G ROLL'!$A:$A,'PP ROLL STOCK'!$C40) -> 111.4 | J40: =SUMIFS('PP F.G ROLL'!S:S,'PP F.G ROLL'!$A:$A,'PP ROLL STOCK'!$C40) -> 0 | K40: =SUMIFS('PP F.G ROLL'!T:T,'PP F.G ROLL'!$A:$A,'PP ROLL STOCK'!$C40) -> 0 | L40: =+H40-J40 -> 2 | M40: =+I40-K40 -> 111.4 | N40: =IFERROR(VLOOKUP(C40,'[1]MIX SALE ORDER'!$A:$E,4,),"OTHERS") -> OTHERS | O40: =VLOOKUP(C40,'PP F.G ROLL'!A:T,4,0) -> PP | P40: #N/A | Q40: / | R40: =CONCATENATE(F40,Q40,G40,) -> 18/10
...

Sheet Sheet3
F1: 45902 | G1: 45905
A2: Size | B2: Guage | C2: Opening | D2: Production INN | E2: BOTTOM | F2: SIDE | G2: STOCK | H2: 45905 | N2: PREV SOCK
A3: 14 | B3: 5 | C3: 1165 | D3: =SUMIFS('[2]PP PRD'!$Q:$Q,'[2]PP PRD'!$G:$G,A:A,'[2]PP PRD'!$H:$H,B:B,'[2]PP PRD'!$D:$D,$H$2) -> 735.44 | E3: =SUMIFS('[2]PP BOTTOM SEAL'!$L:$L,'[2]PP BOTTOM SEAL'!$I:$I,A3,'[2]PP BOTTOM SEAL'!$H:$H,B3,'[2]PP BOTTOM SEAL'!$D:$D,$F$1) -> 0 | F3: =SUMIFS('[2]PP SIDE SEAL'!$L:$L,'[2]PP SIDE SEAL'!$I:$I,A3,'[2]PP SIDE SEAL'!$H:$H,B3,'[2]PP SIDE SEAL'!$D:$D,$F$1) -> 0 | G3: =+C3-E3 -> 1165 | L3: 14 | M3: 5 | N3: =38+44+45+65+25+29+61+57+51+38+41+50+58+60+32+54+52+50+44+50+36+50+26+52+57 -> 1165
A4: 13 | B4: 5 | C4: -765 | D4: =SUMIFS('[2]PP PRD'!$Q:$Q,'[2]PP PRD'!$G:$G,A:A,'[2]PP PRD'!$H:$H,B:B,'[2]PP PRD'!$D:$D,$H$2) -> 0 | E4: =SUMIFS('[2]PP BOTTOM SEAL'!$L:$L,'[2]PP BOTTOM SEAL'!$I:$I,A4,'[2]PP BOTTOM SEAL'!$H:$H,B4,'[2]PP BOTTOM SEAL'!$D:$D,$F$1) -> 400 | F4: =SUMIFS('[2]PP SIDE SEAL'!$L:$L,'[2]PP SIDE SEAL'!$I:$I,A4,'[2]PP SIDE SEAL'!$H:$H,B4,'[2]PP SIDE SEAL'!$D:$D,$F$1) -> 225 | G4: =+C4-E4 -> -1165 | L4: 13 | M4: 5 | N4: =45+40+54+37+36+49+32+44+38+43+25+47+51+51+65+34+28+38+50+15+13 -> 835
A5: 12 | B5: 5 | C5: 1365 | D5: =SUMIFS('[2]PP PRD'!$Q:$Q,'[2]PP PRD'!$G:$G,A:A,'[2]PP PRD'!$H:$H,B:B,'[2]PP PRD'!$D:$D,$H$2) -> 356.22 | E5: =SUMIFS('[2]PP BOTTOM SEAL'!$L:$L,'[2]PP BOTTOM SEAL'!$I:$I,A5,'[2]PP BOTTOM SEAL'!$H:$H,B5,'[2]PP BOTTOM SEAL'!$D:$D,$F$1) -> 0 | F5: =SUMIFS('[2]PP SIDE SEAL'!$L:$L,'[2]PP SIDE SEAL'!$I:$I,A5,'[2]PP SIDE SEAL'!$H:$H,B5,'[2]PP SIDE SEAL'!$D:$D,$F$1) -> 0 | G5: =+C5-E5 -> 1365 | L5: 12 | M5: 5 | N5: =41+51+55+44+43+41+43+38+41+48+48+43+44+41+18+43+44+45+44+23+16+54+45+49+43+41+35+53+46+53+50+42 -> 1365
A6: 11 | B6: 5 | C6: 1113 | D6: =SUMIFS('[2]PP PRD'!$Q:$Q,'[2]PP PRD'!$G:$G,A:A,'[2]PP PRD'!$H:$H,B:B,'[2]PP PRD'!$D:$D,$H$2) -> 0 | E6: =SUMIFS('[2]PP BOTTOM SEAL'!$L:$L,'[2]PP BOTTOM SEAL'!$I:$I,A6,'[2]PP BOTTOM SEAL'!$H:$H,B6,'[2]PP BOTTOM SEAL'!$D:$D,$F$1) -> 0 | F6: =SUMIFS('[2]PP SIDE SEAL'!$L:$L,'[2]PP SIDE SEAL'!$I:$I,A6,'[2]PP SIDE SEAL'!$H:$H,B6,'[2]PP SIDE SEAL'!$D:$D,$F$1) -> 150 | G6: =+C6-E6 -> 1113 | L6: 11 | M6: 5 | N6: =60+43+50+46+22+17+44+39+50+44+47+42+42+43+43+47+46+53+48+47+44+46+51+55+37+32 -> 1138
A7: 8 | B7: 5 | C7: -565 | D7: =SUMIFS('[2]PP PRD'!$Q:$Q,'[2]PP PRD'!$G:$G,A:A,'[2]PP PRD'!$H:$H,B:B,'[2]PP PRD'!$D:$D,$H$2) -> 409.52 | E7: =SUMIFS('[2]PP BOTTOM SEAL'!$L:$L,'[2]PP BOTTOM SEAL'!$I:$I,A7,'[2]PP BOTTOM SEAL'!$H:$H,B7,'[2]PP BOTTOM SEAL'!$D:$D,$F$1) -> 450 | F7: =SUMIFS('[2]PP SIDE SEAL'!$L:$L,'[2]PP SIDE SEAL'!$I:$I,A7,'[2]PP SIDE SEAL'!$H:$H,B7,'[2]PP SIDE SEAL'!$D:$D,$F$1) -> 0 | G7: =+C7-E7 -> -1015 | L7: 8 | M7: 5 | N7: =16+34+27+30+41+40+38+45+34+34+31+34+27+27+34+21+39+30+21+28+34+44+39+42+34+27+38+35+35+36+21+25+23+31+31+39+30+40 -> 1235
A8: 7 | B8: 5 | C8: 3 | D8: =SUMIFS('[2]PP PRD'!$Q:$Q,'[2]PP PRD'!$G:$G,A:A,'[2]PP PRD'!$H:$H,B:B,'[2]PP PRD'!$D:$D,$H$2) -> 0 | E8: =SUMIFS('[2]PP BOTTOM SEAL'!$L:$L,'[2]PP BOTTOM SEAL'!$I:$I,A8,'[2]PP BOTTOM SEAL'!$H:$H,B8,'[2]PP BOTTOM SEAL'!$D:$D,$F$1) -> 0 | F8: =SUMIFS('[2]PP SIDE SEAL'!$L:$L,'[2]PP SIDE SEAL'!$I:$I,A8,'[2]PP SIDE SEAL'!$H:$H,B8,'[2]PP SIDE SEAL'!$D:$D,$F$1) -> 0 | G8: =+C8-E8 -> 3 | L8: 7 | M8: 5 | N8: =29+34+36+38+33+40+44+10+18+32+39 -> 353
A9: 6 | B9: 5 | C9: 1029 | D9: =SUMIFS('[2]PP PRD'!$Q:$Q,'[2]PP PRD'!$G:$G,A:A,'[2]PP PRD'!$H:$H,B:B,'[2]PP PRD'!$D:$D,$H$2) -> 0 | E9: =SUMIFS('[2]PP BOTTOM SEAL'!$L:$L,'[2]PP BOTTOM SEAL'!$I:$I,A9,'[2]PP BOTTOM SEAL'!$H:$H,B9,'[2]PP BOTTOM SEAL'!$D:$D,$F$1) -> 0 | F9: =SUMIFS('[2]PP SIDE SEAL'!$L:$L,'[2]PP SIDE SEAL'!$I:$I,A9,'[2]PP SIDE SEAL'!$H:$H,B9,'[2]PP SIDE SEAL'!$D:$D,$F$1) -> 0 | G9: =+C9-E9 -> 1029 | L9: 6 | M9: 5 | N9: =36+33+33+34+25+22+28+28+14+11+32+29+28+30+31+33+31+33+32+33+32+35+34+36+34+34+30+35+36+36+35+38+38 -> 1029
A10: 14 | B10: 6.5 | C10: 495 | D10: =SUMIFS('[2]PP PRD'!$Q:$Q,'[2]PP PRD'!$G:$G,A:A,'[2]PP PRD'!$H:$H,B:B,'[2]PP PRD'!$D:$D,$H$2) -> 0 | E10: =SUMIFS('[2]PP BOTTOM SEAL'!$L:$L,'[2]PP BOTTOM SEAL'!$I:$I,A10,'[2]PP BOTTOM SEAL'!$H:$H,B10,'[2]PP BOTTOM SEAL'!$D:$D,$F$1) -> 0 | F10: =SUMIFS('[2]PP SIDE SEAL'!$L:$L,'[2]PP SIDE SEAL'!$I:$I,A10,'[2]PP SIDE SEAL'!$H:$H,B10,'[2]PP SIDE SEAL'!$D:$D,$F$1) -> 0 | G10: =+C10-E10 -> 495 | L10: 14 | M10: 6.5 | N10: =49+36+45+44+41+41+43+48+35+35+35+43 -> 495
A11: 15 | B11: 6 | C11: 223 | D11: =SUMIFS('[2]PP PRD'!$Q:$Q,'[2]PP PRD'!$G:$G,A:A,'[2]PP PRD'!$H:$H,B:B,'[2]PP PRD'!$D:$D,$H$2) -> 0 | E11: =SUMIFS('[2]PP BOTTOM SEAL'!$L:$L,'[2]PP BOTTOM SEAL'!$I:$I,A11,'[2]PP BOTTOM SEAL'!$H:$H,B11,'[2]PP BOTTOM SEAL'!$D:$D,$F$1) -> 0 | F11: =SUMIFS('[2]PP SIDE SEAL'!$L:$L,'[2]PP SIDE SEAL'!$I:$I,A11,'[2]PP SIDE SEAL'!$H:$H,B11,'[2]PP SIDE SEAL'!$D:$D,$F$1) -> 0 | G11: =+C11-E11 -> 223 | L11: 15 | M11: 6 | N11: =24+32+36+32+31+34+34 -> 223
A12: 18 | B12: 4 | C12: 697 | D12: =SUMIFS('[2]PP PRD'!$Q:$Q,'[2]PP PRD'!$G:$G,A:A,'[2]PP PRD'!$H:$H,B:B,'[2]PP PRD'!$D:$D,$H$2) -> 0 | E12: =SUMIFS('[2]PP BOTTOM SEAL'!$L:$L,'[2]PP BOTTOM SEAL'!$I:$I,A12,'[2]PP BOTTOM SEAL'!$H:$H,B12,'[2]PP BOTTOM SEAL'!$D:$D,$F$1) -> 0 | F12: =SUMIFS('[2]PP SIDE SEAL'!$L:$L,'[2]PP SIDE SEAL'!$I:$I,A12,'[2]PP SIDE SEAL'!$H:$H,B12,'[2]PP SIDE SEAL'!$D:$D,$F$1) -> 0 | G12: =+C12-E12 -> 697 | L12: 18 | M12: 4 | N12: =46+48+40+33+50+42+43+53+52+52+55+30+53+47+53 -> 697
A13: 7 | B13: 4 | C13: 81 | D13: =SUMIFS('[2]PP PRD'!$Q:$Q,'[2]PP PRD'!$G:$G,A:A,'[2]PP PRD'!$H:$H,B:B,'[2]PP PRD'!$D:$D,$H$2) -> 0 | E13: =SUMIFS('[2]PP BOTTOM SEAL'!$L:$L,'[2]PP BOTTOM SEAL'!$I:$I,A13,'[2]PP BOTTOM SEAL'!$H:$H,B13,'[2]PP BOTTOM SEAL'!$D:$D,$F$1) -> 0 | F13: =SUMIFS('[2]PP SIDE SEAL'!$L:$L,'[2]PP SIDE SEAL'!$I:$I,A13,'[2]PP SIDE SEAL'!$H:$H,B13,'[2]PP SIDE SEAL'!$D:$D,$F$1) -> 0 | G13: =+C13-E13 -> 81 | L13: 7 | M13: 4 | N13: =14+23+24+20 -> 81
A14: 8 | B14: 4 | C14: 256 | D14: =SUMIFS('[2]PP PRD'!$Q:$Q,'[2]PP PRD'!$G:$G,A:A,'[2]PP PRD'!$H:$H,B:B,'[2]PP PRD'!$D:$D,$H$2) -> 0 | E14: =SUMIFS('[2]PP BOTTOM SEAL'!$L:$L,'[2]PP BOTTOM SEAL'!$I:$I,A14,'[2]PP BOTTOM SEAL'!$H:$H,B14,'[2]PP BOTTOM SEAL'!$D:$D,$F$1) -> 0 | F14: =SUMIFS('[2]PP SIDE SEAL'!$L:$L,'[2]PP SIDE SEAL'!$I:$I,A14,'[2]PP SIDE SEAL'!$H:$H,B14,'[2]PP SIDE SEAL'!$D:$D,$F$1) -> 0 | G14: =+C14-E14 -> 256 | L14: 8 | M14: 4 | N14: =35+37+34+34+33+31+32+20 -> 256
A15: 9 | B15: 4 | C15: 104 | D15: =SUMIFS('[2]PP PRD'!$Q:$Q,'[2]PP PRD'!$G:$G,A:A,'[2]PP PRD'!$H:$H,B:B,'[2]PP PRD'!$D:$D,$H$2) -> 0 | E15: =SUMIFS('[2]PP BOTTOM SEAL'!$L:$L,'[2]PP BOTTOM SEAL'!$I:$I,A15,'[2]PP BOTTOM SEAL'!$H:$H,B15,'[2]PP BOTTOM SEAL'!$D:$D,$F$1) -> 0 | F15: =SUMIFS('[2]PP SIDE SEAL'!$L:$L,'[2]PP SIDE SEAL'!$I:$I,A15,'[2]PP SIDE SEAL'!$H:$H,B15,'[2]PP SIDE SEAL'!$D:$D,$F$1) -> 0 | G15: =+C15-E15 -> 104 | L15: 9 | M15: 4 | N15: =42+31+31 -> 104
A16: 2 | B16: 5.5-6 | C16: 184 | D16: =SUMIFS('[2]PP PRD'!$Q:$Q,'[2]PP PRD'!$G:$G,A:A,'[2]PP PRD'!$H:$H,B:B,'[2]PP PRD'!$D:$D,$H$2) -> 0 | E16: =SUMIFS('[2]PP BOTTOM SEAL'!$L:$L,'[2]PP BOTTOM SEAL'!$I:$I,A16,'[2]PP BOTTOM SEAL'!$H:$H,B16,'[2]PP BOTTOM SEAL'!$D:$D,$F$1) -> 0 | F16: =SUMIFS('[2]PP SIDE SEAL'!$L:$L,'[2]PP SIDE SEAL'!$I:$I,A16,'[2]PP SIDE SEAL'!$H:$H,B16,'[2]PP SIDE SEAL'!$D:$D,$F$1) -> 0 | G16: =+C16-E16 -> 184 | L16: 2 | M16: 5.5-6 | N16: =20+20+21+21+21+22+23+20+21+20+18+18+19+20+20 -> 304
A17: 24 | B17: 5 | C17: 895 | D17: =SUMIFS('[2]PP PRD'!$Q:$Q,'[2]PP PRD'!$G:$G,A:A,'[2]PP PRD'!$H:$H,B:B,'[2]PP PRD'!$D:$D,$H$2) -> 0 | E17: =SUMIFS('[2]PP BOTTOM SEAL'!$L:$L,'[2]PP BOTTOM SEAL'!$I:$I,A17,'[2]PP BOTTOM SEAL'!$H:$H,B17,'[2]PP BOTTOM SEAL'!$D:$D,$F$1) -> 0 | F17: =SUMIFS('[2]PP SIDE SEAL'!$L:$L,'[2]PP SIDE SEAL'!$I:$I,A17,'[2]PP SIDE SEAL'!$H:$H,B17,'[2]PP SIDE SEAL'!$D:$D,$F$1) -> 0 | G17: =+C17-E17 -> 895 | L17: 24 | M17: 5 | N17: =51+66+62+56+54+61+55+63+55+55+54+56+56+57+22+23+49 -> 895
A18: 20 | B18: 5 | C18: 1666 | D18: =SUMIFS('[2]PP PRD'!$Q:$Q,'[2]PP PRD'!$G:$G,A:A,'[2]PP PRD'!$H:$H,B:B,'[2]PP PRD'!$D:$D,$H$2) -> 0 | E18: =SUMIFS('[2]PP BOTTOM SEAL'!$L:$L,'[2]PP BOTTOM SEAL'!$I:$I,A18,'[2]PP BOTTOM SEAL'!$H:$H,B18,'[2]PP BOTTOM SEAL'!$D:$D,$F$1) -> 0 | F18: =SUMIFS('[2]PP SIDE SEAL'!$L:$L,'[2]PP SIDE SEAL'!$I:$I,A18,'[2]PP SIDE SEAL'!$H:$H,B18,'[2]PP SIDE SEAL'!$D:$D,$F$1) -> 305 | G18: =+C18-E18 -> 1666 | L18: 20 | M18: 5 | N18: =35+41+42+66+58+62+51+70+66+44+53+49+64+54+47+58+49+64+54+47+58+49+54+44+49+60+62+51+48+65+52 -> 1666
A19: 19 | B19: 5 | C19: 566 | D19: =SUMIFS('[2]PP PRD'!$Q:$Q,'[2]PP PRD'!$G:$G,A:A,'[2]PP PRD'!$H:$H,B:B,'[2]PP PRD'!$D:$D,$H$2) -> 0 | E19: =SUMIFS('[2]PP BOTTOM SEAL'!$L:$L,'[2]PP BOTTOM SEAL'!$I:$I,A19,'[2]PP BOTTOM SEAL'!$H:$H,B19,'[2]PP BOTTOM SEAL'!$D:$D,$F$1) -> 0 | F19: =SUMIFS('[2]PP SIDE SEAL'!$L:$L,'[2]PP SIDE SEAL'!$I:$I,A19,'[2]PP SIDE SEAL'!$H:$H,B19,'[2]PP SIDE SEAL'!$D:$D,$F$1) -> 0 | G19: =+C19-E19 -> 566 | L19: 19 | M19: 5 | N19: =69+57+32+52+64+57+60+60+50+65 -> 566
A20: 17 | B20: 5 | C20: 142 | D20: =SUMIFS('[2]PP PRD'!$Q:$Q,'[2]PP PRD'!$G:$G,A:A,'[2]PP PRD'!$H:$H,B:B,'[2]PP PRD'!$D:$D,$H$2) -> 0 | E20: =SUMIFS('[2]PP BOTTOM SEAL'!$L:$L,'[2]PP BOTTOM SEAL'!$I:$I,A20,'[2]PP BOTTOM SEAL'!$H:$H,B20,'[2]PP BOTTOM SEAL'!$D:$D,$F$1) -> 0 | F20: =SUMIFS('[2]PP SIDE SEAL'!$L:$L,'[2]PP SIDE SEAL'!$I:$I,A20,'[2]PP SIDE SEAL'!$H:$H,B20,'[2]PP SIDE SEAL'!$D:$D,$F$1) -> 0 | G20: =+C20-E20 -> 142 | L20: 17 | M20: 5 | N20: =25+27+34+56 -> 142
A21: 22 | B21: 5 | C21: 225 | D21: =SUMIFS('[2]PP PRD'!$Q:$Q,'[2]PP PRD'!$G:$G,A:A,'[2]PP PRD'!$H:$H,B:B,'[2]PP PRD'!$D:$D,$H$2) -> 0 | E21: =SUMIFS('[2]PP BOTTOM SEAL'!$L:$L,'[2]PP BOTTOM SEAL'!$I:$I,A21,'[2]PP BOTTOM SEAL'!$H:$H,B21,'[2]PP BOTTOM SEAL'!$D:$D,$F$1) -> 0 | F21: =SUMIFS('[2]PP SIDE SEAL'!$L:$L,'[2]PP SIDE SEAL'!$I:$I,A21,'[2]PP SIDE SEAL'!$H:$H,B21,'[2]PP SIDE SEAL'!$D:$D,$F$1) -> 0 | G21: =+C21-E21 -> 225 | L21: 22 | M21: 5 | N21: =63+74+33+55 -> 225
A22: 18 | B22: 5 | C22: 298 | D22: =SUMIFS('[2]PP PRD'!$Q:$Q,'[2]PP PRD'!$G:$G,A:A,'[2]PP PRD'!$H:$H,B:B,'[2]PP PRD'!$D:$D,$H$2) -> 0 | E22: =SUMIFS('[2]PP BOTTOM SEAL'!$L:$L,'[2]PP BOTTOM SEAL'!$I:$I,A22,'[2]PP BOTTOM SEAL'!$H:$H,B22,'[2]PP BOTTOM SEAL'!$D:$D,$F$1) -> 0 | F22: =SUMIFS('[2]PP SIDE SEAL'!$L:$L,'[2]PP SIDE SEAL'!$I:$I,A22,'[2]PP SIDE SEAL'!$H:$H,B22,'[2]PP SIDE SEAL'!$D:$D,$F$1) -> 0 | G22: =+C22-E22 -> 298 | L22: 18 | M22: 5 | N22: =31+30+40+46+46+56+49 -> 298
A23: 16 | B23: 5 | C23: 180 | D23: =SUMIFS('[2]PP PRD'!$Q:$Q,'[2]PP PRD'!$G:$G,A:A,'[2]PP PRD'!$H:$H,B:B,'[2]PP PRD'!$D:$D,$H$2) -> 606.47 | E23: =SUMIFS('[2]PP BOTTOM SEAL'!$L:$L,'[2]PP BOTTOM SEAL'!$I:$I,A23,'[2]PP BOTTOM SEAL'!$H:$H,B23,'[2]PP BOTTOM SEAL'!$D:$D,$F$1) -> 0 | F23: =SUMIFS('[2]PP SIDE SEAL'!$L:$L,'[2]PP SIDE SEAL'!$I:$I,A23,'[2]PP SIDE SEAL'!$H:$H,B23,'[2]PP SIDE SEAL'!$D:$D,$F$1) -> 0 | G23: =+C23-E23 -> 180 | L23: 16 | M23: 5 | N23: =12+20+18+34+33+25+38 -> 180
A24: 15 | B24: 5 | C24: 996 | D24: =SUMIFS('[2]PP PRD'!$Q:$Q,'[2]PP PRD'!$G:$G,A:A,'[2]PP PRD'!$H:$H,B:B,'[2]PP PRD'!$D:$D,$H$2) -> 0 | E24: =SUMIFS('[2]PP BOTTOM SEAL'!$L:$L,'[2]PP BOTTOM SEAL'!$I:$I,A24,'[2]PP BOTTOM SEAL'!$H:$H,B24,'[2]PP BOTTOM SEAL'!$D:$D,$F$1) -> 0 | F24: =SUMIFS('[2]PP SIDE SEAL'!$L:$L,'[2]PP SIDE SEAL'!$I:$I,A24,'[2]PP SIDE SEAL'!$H:$H,B24,'[2]PP SIDE SEAL'!$D:$D,$F$1) -> 0 | G24: =+C24-E24 -> 996 | L24: 15 | M24: 5 | N24: =18+38+34+54+56+42+29+33+29+25+27+54+51+48+44+52+53+31+21+26+37+24+42+51+38+39 -> 996
A25: 2 | B25: 6.5 | C25: 186 | D25: =SUMIFS('[2]PP PRD'!$Q:$Q,'[2]PP PRD'!$G:$G,A:A,'[2]PP PRD'!$H:$H,B:B,'[2]PP PRD'!$D:$D,$H$2) -> 0 | E25: =SUMIFS('[2]PP BOTTOM SEAL'!$L:$L,'[2]PP BOTTOM SEAL'!$I:$I,A25,'[2]PP BOTTOM SEAL'!$H:$H,B25,'[2]PP BOTTOM SEAL'!$D:$D,$F$1) -> 0 | F25: =SUMIFS('[2]PP SIDE SEAL'!$L:$L,'[2]PP SIDE SEAL'!$I:$I,A25,'[2]PP SIDE SEAL'!$H:$H,B25,'[2]PP SIDE SEAL'!$D:$D,$F$1) -> 0 | G25: =+C25-E25 -> 186 | L25: 2 | M25: 6.5 | N25: =37+52+50+47 -> 186
A26: 19 | B26: 4 | C26: 22 | D26: =SUMIFS('[2]PP PRD'!$Q:$Q,'[2]PP PRD'!$G:$G,A:A,'[2]PP PRD'!$H:$H,B:B,'[2]PP PRD'!$D:$D,$H$2) -> 0 | E26: =SUMIFS('[2]PP BOTTOM SEAL'!$L:$L,'[2]PP BOTTOM SEAL'!$I:$I,A26,'[2]PP BOTTOM SEAL'!$H:$H,B26,'[2]PP BOTTOM SEAL'!$D:$D,$F$1) -> 0 | F26: =SUMIFS('[2]PP SIDE SEAL'!$L:$L,'[2]PP SIDE SEAL'!$I:$I,A26,'[2]PP SIDE SEAL'!$H:$H,B26,'[2]PP SIDE SEAL'!$D:$D,$F$1) -> 0 | G26: =+C26-E26 -> 22 | L26: 19 | M26: 4 | N26: 22
A27: 24 | B27: 4 | C27: 42 | D27: =SUMIFS('[2]PP PRD'!$Q:$Q,'[2]PP PRD'!$G:$G,A:A,'[2]PP PRD'!$H:$H,B:B,'[2]PP PRD'!$D:$D,$H$2) -> 0 | E27: =SUMIFS('[2]PP BOTTOM SEAL'!$L:$L,'[2]PP BOTTOM SEAL'!$I:$I,A27,'[2]PP BOTTOM SEAL'!$H:$H,B27,'[2]PP BOTTOM SEAL'!$D:$D,$F$1) -> 0 | F27: =SUMIFS('[2]PP SIDE SEAL'!$L:$L,'[2]PP SIDE SEAL'!$I:$I,A27,'[2]PP SIDE SEAL'!$H:$H,B27,'[2]PP SIDE SEAL'!$D:$D,$F$1) -> 0 | G27: =+C27-E27 -> 42 | L27: 24 | M27: 4 | N27: 42
A28: 11 | B28: 6.5 | C28: 129 | D28: =SUMIFS('[2]PP PRD'!$Q:$Q,'[2]PP PRD'!$G:$G,A:A,'[2]PP PRD'!$H:$H,B:B,'[2]PP PRD'!$D:$D,$H$2) -> 0 | E28: =SUMIFS('[2]PP BOTTOM SEAL'!$L:$L,'[2]PP BOTTOM SEAL'!$I:$I,A28,'[2]PP BOTTOM SEAL'!$H:$H,B28,'[2]PP BOTTOM SEAL'!$D:$D,$F$1) -> 0 | F28: =SUMIFS('[2]PP SIDE SEAL'!$L:$L,'[2]PP SIDE SEAL'!$I:$I,A28,'[2]PP SIDE SEAL'!$H:$H,B28,'[2]PP SIDE SEAL'!$D:$D,$F$1) -> 0 | G28: =+C28-E28 -> 129 | L28: 11 | M28: 6.5 | N28: =41+45+15+28 -> 129
A29: 6 | B29: 4 | C29: 195 | D29: =SUMIFS('[2]PP PRD'!$Q:$Q,'[2]PP PRD'!$G:$G,A:A,'[2]PP PRD'!$H:$H,B:B,'[2]PP PRD'!$D:$D,$H$2) -> 0 | E29: =SUMIFS('[2]PP BOTTOM SEAL'!$L:$L,'[2]PP BOTTOM SEAL'!$I:$I,A29,'[2]PP BOTTOM SEAL'!$H:$H,B29,'[2]PP BOTTOM SEAL'!$D:$D,$F$1) -> 0 | F29: =SUMIFS('[2]PP SIDE SEAL'!$L:$L,'[2]PP SIDE SEAL'!$I:$I,A29,'[2]PP SIDE SEAL'!$H:$H,B29,'[2]PP SIDE SEAL'!$D:$D,$F$1) -> 0 | G29: =+C29-E29 -> 195 | L29: 6 | M29: 4 | N29: =29+29+35+30+38+34 -> 195
A30: 13 | B30: 6.5 | C30: 71 | D30: =SUMIFS('[2]PP PRD'!$Q:$Q,'[2]PP PRD'!$G:$G,A:A,'[2]PP PRD'!$H:$H,B:B,'[2]PP PRD'!$D:$D,$H$2) -> 0 | E30: =SUMIFS('[2]PP BOTTOM SEAL'!$L:$L,'[2]PP BOTTOM SEAL'!$I:$I,A30,'[2]PP BOTTOM SEAL'!$H:$H,B30,'[2]PP BOTTOM SEAL'!$D:$D,$F$1) -> 0 | F30: =SUMIFS('[2]PP SIDE SEAL'!$L:$L,'[2]PP SIDE SEAL'!$I:$I,A30,'[2]PP SIDE SEAL'!$H:$H,B30,'[2]PP SIDE SEAL'!$D:$D,$F$1) -> 0 | G30: =+C30-E30 -> 71 | L30: 13 | M30: 6.5 | N30: =26+45 -> 71
A31: 12 | B31: 6.5 | C31: 189 | D31: =SUMIFS('[2]PP PRD'!$Q:$Q,'[2]PP PRD'!$G:$G,A:A,'[2]PP PRD'!$H:$H,B:B,'[2]PP PRD'!$D:$D,$H$2) -> 0 | E31: =SUMIFS('[2]PP BOTTOM SEAL'!$L:$L,'[2]PP BOTTOM SEAL'!$I:$I,A31,'[2]PP BOTTOM SEAL'!$H:$H,B31,'[2]PP BOTTOM SEAL'!$D:$D,$F$1) -> 0 | F31: =SUMIFS('[2]PP SIDE SEAL'!$L:$L,'[2]PP SIDE SEAL'!$I:$I,A31,'[2]PP SIDE SEAL'!$H:$H,B31,'[2]PP SIDE SEAL'!$D:$D,$F$1) -> 0 | G31: =+C31-E31 -> 189 | L31: 12 | M31: 6.5 | N31: =20+26+26+51+17+16+33 -> 189
A32: 17 | B32: 7 | C32: 345 | D32: =SUMIFS('[2]PP PRD'!$Q:$Q,'[2]PP PRD'!$G:$G,A:A,'[2]PP PRD'!$H:$H,B:B,'[2]PP PRD'!$D:$D,$H$2) -> 0 | E32: =SUMIFS('[2]PP BOTTOM SEAL'!$L:$L,'[2]PP BOTTOM SEAL'!$I:$I,A32,'[2]PP BOTTOM SEAL'!$H:$H,B32,'[2]PP BOTTOM SEAL'!$D:$D,$F$1) -> 0 | F32: =SUMIFS('[2]PP SIDE SEAL'!$L:$L,'[2]PP SIDE SEAL'!$I:$I,A32,'[2]PP SIDE SEAL'!$H:$H,B32,'[2]PP SIDE SEAL'!$D:$D,$F$1) -> 0 | G32: =+C32-E32 -> 345 | L32: 17 | M32: 7 | N32: =20+23+65+60+57+62+58 -> 345
A33: 15 | B33: 4 | C33: 500 | D33: =SUMIFS('[2]PP PRD'!$Q:$Q,'[2]PP PRD'!$G:$G,A:A,'[2]PP PRD'!$H:$H,B:B,'[2]PP PRD'!$D:$D,$H$2) -> 0 | E33: =SUMIFS('[2]PP BOTTOM SEAL'!$L:$L,'[2]PP BOTTOM SEAL'!$I:$I,A33,'[2]PP BOTTOM SEAL'!$H:$H,B33,'[2]PP BOTTOM SEAL'!$D:$D,$F$1) -> 0 | F33: =SUMIFS('[2]PP SIDE SEAL'!$L:$L,'[2]PP SIDE SEAL'!$I:$I,A33,'[2]PP SIDE SEAL'!$H:$H,B33,'[2]PP SIDE SEAL'!$D:$D,$F$1) -> 0 | G33: =+C33-E33 -> 500 | L33: 15 | M33: 4 | N33: =34+51+53+54+47+66+51+50+39+55 -> 500
A34: 16 | B34: 8 | C34: 58 | D34: =SUMIFS('[2]PP PRD'!$Q:$Q,'[2]PP PRD'!$G:$G,A:A,'[2]PP PRD'!$H:$H,B:B,'[2]PP PRD'!$D:$D,$H$2) -> 265.83 | E34: =SUMIFS('[2]PP BOTTOM SEAL'!$L:$L,'[2]PP BOTTOM SEAL'!$I:$I,A34,'[2]PP BOTTOM SEAL'!$H:$H,B34,'[2]PP BOTTOM SEAL'!$D:$D,$F$1) -> 0 | F34: =SUMIFS('[2]PP SIDE SEAL'!$L:$L,'[2]PP SIDE SEAL'!$I:$I,A34,'[2]PP SIDE SEAL'!$H:$H,B34,'[2]PP SIDE SEAL'!$D:$D,$F$1) -> 0 | G34: =+C34-E34 -> 58 | L34: 16 | M34: 8 | N34: =28+30 -> 58
A35: 15 | B35: 7 | C35: 35 | D35: =SUMIFS('[2]PP PRD'!$Q:$Q,'[2]PP PRD'!$G:$G,A:A,'[2]PP PRD'!$H:$H,B:B,'[2]PP PRD'!$D:$D,$H$2) -> 0 | E35: =SUMIFS('[2]PP BOTTOM SEAL'!$L:$L,'[2]PP BOTTOM SEAL'!$I:$I,A35,'[2]PP BOTTOM SEAL'!$H:$H,B35,'[2]PP BOTTOM SEAL'!$D:$D,$F$1) -> 0 | F35: =SUMIFS('[2]PP SIDE SEAL'!$L:$L,'[2]PP SIDE SEAL'!$I:$I,A35,'[2]PP SIDE SEAL'!$H:$H,B35,'[2]PP SIDE SEAL'!$D:$D,$F$1) -> 0 | G35: =+C35-E35 -> 35 | L35: 15 | M35: 7 | N35: =17+18 -> 35
A36: 8 | B36: 6.5 | C36: 273 | D36: =SUMIFS('[2]PP PRD'!$Q:$Q,'[2]PP PRD'!$G:$G,A:A,'[2]PP PRD'!$H:$H,B:B,'[2]PP PRD'!$D:$D,$H$2) -> 0 | E36: =SUMIFS('[2]PP BOTTOM SEAL'!$L:$L,'[2]PP BOTTOM SEAL'!$I:$I,A36,'[2]PP BOTTOM SEAL'!$H:$H,B36,'[2]PP BOTTOM SEAL'!$D:$D,$F$1) -> 0 | F36: =SUMIFS('[2]PP SIDE SEAL'!$L:$L,'[2]PP SIDE SEAL'!$I:$I,A36,'[2]PP SIDE SEAL'!$H:$H,B36,'[2]PP SIDE SEAL'!$D:$D,$F$1) -> 0 | G36: =+C36-E36 -> 273 | L36: 8 | M36: 6.5 | N36: =27+46+40+40+40+40+40 -> 273
A37: 18 | B37: 7 | C37: 51 | D37: =SUMIFS('[2]PP PRD'!$Q:$Q,'[2]PP PRD'!$G:$G,A:A,'[2]PP PRD'!$H:$H,B:B,'[2]PP PRD'!$D:$D,$H$2) -> 121.98 | E37: =SUMIFS('[2]PP BOTTOM SEAL'!$L:$L,'[2]PP BOTTOM SEAL'!$I:$I,A37,'[2]PP BOTTOM SEAL'!$H:$H,B37,'[2]PP BOTTOM SEAL'!$D:$D,$F$1) -> 0 | F37: =SUMIFS('[2]PP SIDE SEAL'!$L:$L,'[2]PP SIDE SEAL'!$I:$I,A37,'[2]PP SIDE SEAL'!$H:$H,B37,'[2]PP SIDE SEAL'!$D:$D,$F$1) -> 0 | G37: =+C37-E37 -> 51 | L37: 18 | M37: 7 | N37: 51
A38: 8 | B38: 4 | C38: 24 | D38: =SUMIFS('[2]PP PRD'!$Q:$Q,'[2]PP PRD'!$G:$G,A:A,'[2]PP PRD'!$H:$H,B:B,'[2]PP PRD'!$D:$D,$H$2) -> 0 | E38: =SUMIFS('[2]PP BOTTOM SEAL'!$L:$L,'[2]PP BOTTOM SEAL'!$I:$I,A38,'[2]PP BOTTOM SEAL'!$H:$H,B38,'[2]PP BOTTOM SEAL'!$D:$D,$F$1) -> 0 | F38: =SUMIFS('[2]PP SIDE SEAL'!$L:$L,'[2]PP SIDE SEAL'!$I:$I,A38,'[2]PP SIDE SEAL'!$H:$H,B38,'[2]PP SIDE SEAL'!$D:$D,$F$1) -> 0 | G38: =+C38-E38 -> 24 | L38: 8 | M38: 4 | N38: 24
A39: 8 | B39: 10 | C39: 27 | D39: =SUMIFS('[2]PP PRD'!$Q:$Q,'[2]PP PRD'!$G:$G,A:A,'[2]PP PRD'!$H:$H,B:B,'[2]PP PRD'!$D:$D,$H$2) -> 0 | E39: =SUMIFS('[2]PP BOTTOM SEAL'!$L:$L,'[2]PP BOTTOM SEAL'!$I:$I,A39,'[2]PP BOTTOM SEAL'!$H:$H,B39,'[2]PP BOTTOM SEAL'!$D:$D,$F$1) -> 0 | F39: =SUMIFS('[2]PP SIDE SEAL'!$L:$L,'[2]PP SIDE SEAL'!$I:$I,A39,'[2]PP SIDE SEAL'!$H:$H,B39,'[2]PP SIDE SEAL'!$D:$D,$F$1) -> 0 | G39: =+C39-E39 -> 27 | L39: 8 | M39: 10 | N39: 27
A40: 9 | B40: 10 | C40: 31 | D40: =SUMIFS('[2]PP PRD'!$Q:$Q,'[2]PP PRD'!$G:$G,A:A,'[2]PP PRD'!$H:$H,B:B,'[2]PP PRD'!$D:$D,$H$2) -> 0 | E40: =SUMIFS('[2]PP BOTTOM SEAL'!$L:$L,'[2]PP BOTTOM SEAL'!$I:$I,A40,'[2]PP BOTTOM SEAL'!$H:$H,B40,'[2]PP BOTTOM SEAL'!$D:$D,$F$1) -> 0 | F40: =SUMIFS('[2]PP SIDE SEAL'!$L:$L,'[2]PP SIDE SEAL'!$I:$I,A40,'[2]PP SIDE SEAL'!$H:$H,B40,'[2]PP SIDE SEAL'!$D:$D,$F$1) -> 0 | G40: =+C40-E40 -> 31 | L40: 9 | M40: 10 | N40: 31
...

Sheet LD F.G ROLL
A1: SO# | B1: Party Name | C1: MATERIAL | D1: JOB NAME | E1: Roll Size | F1: Guage | G1: Seal | H1: Section IN | I1: TR # | J1: DATE | K1: I.BAGS | L1: WEIGHT | M1: CORE | N1: NET WEIGHT | O1: TO Section OUT | P1: PO# | Q1: BILL # | R1: DATE 2 | S1: O.ROLLS | T1: O.KGS
A2: =CONCATENATE(E2,"/",F2) -> 19/12 | B2: Usman Amin | C2: LDN | D2: LDN | E2: 19 | F2: 12 | H2: LD PRO | J2: 45904 | K2: 1 | L2: 43 | M2: 2.2 | N2: =+L2-M2 -> 40.8
A3: =CONCATENATE(E3,"/",F3) -> 18/7 | B3: Usman Amin | C3: LDN | D3: LDN | E3: 18 | F3: 7 | H3: LD PRO | J3: 45904 | K3: 4 | L3: 244 | M3: 8.4 | N3: 235.6
A4: =CONCATENATE(E4,"/",F4) -> 18/7 | B4: Usman Amin | C4: LDN | D4: LDN | E4: 18 | F4: 7 | H4: LD PRO | J4: 45904 | K4: 2 | L4: 105.6 | M4: 4.3 | N4: =+L4-M4 -> 101.3
A5: =CONCATENATE(E5,"/",F5) -> 19/7 | B5: Usman Amin | C5: LDN | D5: LDN | E5: 19 | F5: 7 | H5: LD PRO | J5: 45904 | K5: 3 | L5: 175.2 | M5: 6.6 | N5: =+L5-M5 -> 168.6
A6: =CONCATENATE(E6,"/",F6) -> 8/15-16 | B6: DW Organic Dairy Farms Kasur | C6: LDM | D6: LDN | E6: 8 | F6: 15-16 | H6: LD PRO | J6: 45904 | K6: 3 | L6: 104.8 | M6: 3 | N6: =+L6-M6 -> 101.8
A7: =CONCATENATE(E7,"/",F7) -> 7/20 | B7: Moazmi Plastic Sahiwal | C7: LDM | D7: LDN | E7: 7 | F7: 20 | H7: LD PRO | J7: 45904 | K7: 3 | L7: 108.4 | M7: 2.7 | N7: =+L7-M7 -> 105.7
A8: =CONCATENATE(E8,"/",F8) -> 7/20 | B8: Moazmi Plastic Sahiwal | C8: LDM | D8: LDN | E8: 7 | F8: 20 | H8: LD PRO | J8: 45904 | K8: 2 | L8: 101.2 | M8: 1.9 | N8: =+L8-M8 -> 99.3
A9: =CONCATENATE(E9,"/",F9) -> 5/9 | B9: GOGA PLASTIC GJW | C9: PT MILKY | D9: LDN | E9: 5 | F9: 9 | H9: LD PRO | J9: 45904 | K9: 4 | L9: 115.6 | M9: 2.5 | N9: =+L9-M9 -> 113.1
A10: =CONCATENATE(E10,"/",F10) -> 30/12-13 | B10: HONDA ATLAS (CARS) LTD | C10: LDN | D10: LDN | E10: 30 | F10: 12-13 | H10: LD PRO | J10: 45904 | K10: 3 | L10: 293.2 | M10: 9.9 | N10: =+L10-M10 -> 283.3
A11: =CONCATENATE(E11,"/",F11) -> 23-23.5/70 GRAM | B11: MATCO FOOD | C11: LDN | D11: LDN | E11: 23-23.5 | F11: 70 GRAM | H11: LD PRO | J11: 45904 | K11: 2 | L11: 202.2 | M11: 5.6 | N11: =+L11-M11 -> 196.6
