Workbook

Sheet PP PRD
A1: SHIFT | B1: MCH# | C1: SO# | D1: DATE | E1: JOB NAME | F1: MATERIAL | G1: SIZE | H1: GUAGE | I1: QUALITY | J1: ORDER WEIGHT | K1: SECTION | L1: NO OF ROLLS | M1: G. WEIGHT | N1: CORE WEIGHT | O1: PRD WATSE | P1: SAMPLE WASTE | Q1: NET WEIGHT | R1: FOREMAN | S1: کوالٹی CHANGE | T1: ھیٹنگ | U1: MACHINE ON | V1: TOTAL MIN | W1: P.S HOURS | X1: الیکٹریکل | Y1: ڈایی صاف | Z1: مکینیکل | AA1: سائز کم | AB1: سیمپل چیک | AC1: OTHER | AD1: جالی تبدیل | AE1: TREET | AF1: TOTAL MIN_1 | AG1: U.P.S HOURS | AH1: T.S HOURS | AI1: RUNNING | AJ1: TOTAL HOURS | AK1: WASTAGE/KGs | AL1: KWH/KG | AM1: TOTAL PRODUCTION | AN1: TARGET | AO1: RECIPE | AP1: WEEK NO. | AQ1: REMARKS | AR1: ACTION | AS1: ACTION PLAN | AT1: REMARKS_2
A2: A | B2: 1 | C2: 4 P | D2: 45658 | E2: سادہ لفافہ | F2: PP | G2: 3 | H2: رول | I2: 0 | J2: - | K2: PP | L2: 8 | M2: 131.23 | N2: 2.4 | O2: 54.5 | Q2: 128.83 | R2: ARFAN
A3: B | B3: 1 | C3: 4 P | D3: 45658 | E3: سادہ لفافہ | F3: PP | G3: 3 | H3: رول | I3: 0 | J3: - | K3: PP | L3: 2 | M3: 36.35 | N3: 0.6 | O3: 54.5 | Q3: 35.75 | R3: ARFAN
A4: A | B4: 2 | C4: 2 P | D4: 45658 | E4: سادہ لفافہ | F4: PP | G4: 2 | H4: رول | I4: 0 | J4: - | K4: PP | L4: 7 | M4: 64.41 | N4: 1.4 | Q4: 63.01 | R4: ARFAN
A5: B | B5: 2 | C5: 2 P | D5: 45658 | E5: سادہ لفافہ | F5: PP | G5: 2 | H5: رول | I5: 0 | J5: - | K5: PP | L5: 2 | M5: 18.85 | N5: 0.4 | Q5: 18.45 | R5: ARFAN
A6: A | B6: 3 | C6: 10 P | D6: 45658 | E6: سادہ لفافہ | F6: PP | G6: 7 | H6: رول | I6: 0 | J6: - | K6: PP | L6: 3 | M6: 115.13 | N6: 2.4 | Q6: 112.73 | R6: ARFAN
A7: A | B7: 3 | C7: 6454/6 | D7: 45658 | E7: لفافہ | F7: PP | G7: 7 | H7: 6 | I7: 0 | J7: 100 | K7: PP | L7: 4 | M7: 107.91 | N7: 2.8 | Q7: 105.11 | R7: ARFAN
A8: A | B8: 3 | C8: 15 P | D8: 45658 | E8: سادہ لفافہ | F8: PP | G8: 12 | H8: رول | I8: 0 | J8: - | K8: PP | L8: 2 | M8: 91.06 | N8: 3.25 | Q8: 87.81 | R8: ARFAN
A9: B | B9: 3 | C9: 15 P | D9: 45658 | E9: سادہ لفافہ | F9: PP | G9: 12 | H9: رول | I9: 0 | J9: - | K9: PP | L9: 5 | M9: 263.63 | N9: 8 | Q9: 255.63 | R9: ARFAN
A10: A | B10: 4 | C10: 817 F | D10: 45658 | E10: وارننگ LEVIES | F10: PP | G10: 16.2 | H10: - | I10: - | J10: 4000 | K10: PP | L10: 13 | M10: 627.12 | N10: 12.8 | Q10: 614.32 | R10: ARFAN
A11: A | B11: 4 | C11: 6470/1 | D11: 45658 | E11: لفافہ | F11: PP | G11: 16 | H11: 5.5/6 | I11: 0 | J11: 500 | K11: PP | L11: 4 | M11: 196.9 | N11: 8.95 | Q11: 187.95 | R11: ARFAN
A12: B | B12: 4 | C12: 6470/1 | D12: 45658 | E12: لفافہ | F12: PP | G12: 16 | H12: 5.5/6 | I12: 0 | J12: 500 | K12: PP | L12: 7 | M12: 299.5 | N12: 9.9 | Q12: 289.6 | R12: ARFAN
A13: B | B13: 4 | C13: 817 F | D13: 45658 | E13: وارننگ LEVIES | F13: PP | G13: 16.2 | H13: - | I13: - | J13: 4000 | K13: PP | L13: 10 | M13: 485.21 | N13: 4 | Q13: 481.21 | R13: ARFAN
A14: A | B14: 5 | C14: 170 P | D14: 45658 | E14: سادہ لفافہ | F14: PP | G14: 15 | H14: 6.5-7 | I14: 0 | J14: - | K14: PP | L14: 7 | M14: 381.33 | N14: 11.51 | Q14: 369.82 | R14: ARFAN
A15: A | B15: 5 | C15: 6469/1 | D15: 45658 | E15: لفافہ | F15: PP | G15: 4 | H15: 14 | I15: 0 | J15: 500 | K15: PP | L15: 5 | M15: 254.38 | N15: 6.54 | Q15: 247.84 | R15: ARFAN
A16: B | B16: 5 | C16: 6469/1 | D16: 45658 | E16: لفافہ | F16: PP | G16: 4 | H16: 14 | I16: 0 | J16: 500 | K16: PP | L16: 8 | M16: 365.62 | N16: 2 | Q16: 363.62 | R16: ARFAN
A17: B | B17: 5 | C17: 13 P | D17: 45658 | E17: سادہ لفافہ | F17: PP | G17: 10 | H17: رول | I17: 0 | J17: - | K17: PP | L17: 4 | M17: 206.04 | N17: 2 | Q17: 204.04 | R17: ARFAN
A18: A | B18: 1 | C18: 4 P | D18: 45659 | E18: سادہ لفافہ | F18: PP | G18: 3 | H18: رول | I18: 0 | J18: - | K18: PP | L18: 9 | M18: 133.58 | N18: 2.7 | O18: 22 | Q18: 130.88 | R18: ARFAN
A19: B | B19: 1 | C19: 4 P | D19: 45659 | E19: سادہ لفافہ | F19: PP | G19: 3 | H19: رول | I19: 0 | J19: - | K19: PP | L19: 7 | M19: 120.94 | N19: 2.1 | O19: 30 | Q19: 118.84 | R19: SHAHID
A20: A | B20: 2 | C20: 2 P | D20: 45659 | E20: سادہ لفافہ | F20: PP | G20: 2 | H20: رول | I20: 0 | J20: - | K20: PP | L20: 9 | M20: 88.17 | N20: 1.8 | Q20: 86.37 | R20: ARFAN
A21: B | B21: 2 | C21: 2 P | D21: 45659 | E21: سادہ لفافہ | F21: PP | G21: 2 | H21: رول | I21: 0 | J21: - | K21: PP | L21: 8 | M21: 73.99 | N21: 1.6 | Q21: 72.39 | R21: SHAHID
A22: A | B22: 4 | C22: 817 F | D22: 45659 | E22: وارننگ LEVIES | F22: PP | G22: 16.2 | H22: - | I22: - | J22: 4000 | K22: PP | L22: 11 | M22: 562.83 | N22: 7.5 | Q22: 555.33 | R22: ARFAN
A23: A | B23: 4 | C23: 6453/3 | D23: 45659 | E23: لفافہ | F23: PP | G23: 8 | H23: 10 | I23: 0 | J23: 100 | K23: PP | L23: 2 | M23: 110.24 | N23: 3.98 | Q23: 106.26 | R23: ARFAN
A24: A | B24: 4 | C24: 6469/2 | D24: 45659 | E24: لفافہ | F24: PP | G24: 6 | H24: 14 | I24: 0 | J24: 125 | K24: PP | L24: 5 | M24: 224.05 | N24: 9.76 | Q24: 214.29 | R24: ARFAN
A25: B | B25: 4 | C25: 817 F | D25: 45659 | E25: وارننگ LEVIES | F25: PP | G25: 16.2 | H25: - | I25: - | J25: 4000 | K25: PP | L25: 15 | M25: 750.83 | N25: 30 | Q25: 720.83 | R25: SHAHID
A26: B | B26: 4 | C26: 19 P | D26: 45659 | E26: سادہ لفافہ | F26: PP | G26: 16 | H26: رول | I26: 0 | J26: - | K26: PP | L26: 1 | M26: 47.2 | N26: 2 | Q26: 45.2 | R26: SHAHID
A27: A | B27: 3 | C27: 15 P | D27: 45659 | E27: سادہ لفافہ | F27: PP | G27: 12 | H27: رول | I27: 0 | J27: - | K27: PP | L27: 4 | M27: 183.96 | Q27: 183.96 | R27: ARFAN
A28: A | B28: 3 | C28: 6453/1 | D28: 45659 | E28: لفافہ | F28: PP | G28: 6 | H28: 10 | I28: 0 | J28: 100 | K28: PP | L28: 3 | M28: 115.51 | N28: 1.6 | Q28: 113.91 | R28: ARFAN
A29: B | B29: 3 | C29: 15 P | D29: 45659 | E29: سادہ لفافہ | F29: PP | G29: 12 | H29: رول | I29: 0 | J29: - | K29: PP | L29: 7 | M29: 329.22 | N29: 8.4 | Q29: 320.82 | R29: SHAHID
A30: A | B30: 5 | C30: 13 P | D30: 45659 | E30: سادہ لفافہ | F30: PP | G30: 10 | H30: رول | I30: 0 | J30: - | K30: PP | L30: 9 | M30: 451.55 | N30: 11.72 | Q30: 439.83 | R30: ARFAN
A31: B | B31: 5 | C31: 13 P | D31: 45659 | E31: سادہ لفافہ | F31: PP | G31: 10 | H31: رول | I31: 0 | J31: - | K31: PP | L31: 11 | M31: 552.78 | N31: 14.3 | Q31: 538.48 | R31: SHAHID
A32: A | B32: 1 | C32: 4 P | D32: 45660 | E32: سادہ لفافہ | F32: PP | G32: 3 | H32: رول | I32: 0 | J32: - | K32: PP | L32: 8 | M32: 146.12 | O32: 40 | Q32: 146.12 | R32: ARFAN
A33: B | B33: 1 | C33: 4 P | D33: 45660 | E33: سادہ لفافہ | F33: PP | G33: 3 | H33: رول | I33: 0 | J33: - | K33: PP | L33: 7 | M33: 128.62 | O33: 30 | Q33: 128.62 | R33: SHAHID
A34: A | B34: 2 | C34: 6442/4 | D34: 45660 | E34: لفافہ | F34: PP | G34: 2 | H34: 5 | I34: 0 | J34: 500 | K34: PP | L34: 7 | M34: 77.15 | Q34: 77.15 | R34: ARFAN
A35: B | B35: 2 | C35: 2 P | D35: 45660 | E35: سادہ لفافہ | F35: PP | G35: 2 | H35: رول | I35: 0 | J35: - | K35: PP | L35: 9 | M35: 91.46 | Q35: 91.46 | R35: SHAHID
A36: A | B36: 3 | C36: 15 P | D36: 45660 | E36: سادہ لفافہ | F36: PP | G36: 12 | H36: رول | I36: 0 | J36: - | K36: PP | L36: 5 | M36: 203.45 | Q36: 203.45 | R36: ARFAN
A37: A | B37: 3 | C37: 15 P | D37: 45660 | E37: سادہ لفافہ | F37: PP | G37: 12 | H37: رول | I37: 0 | J37: - | K37: PP | L37: 2 | M37: 88.08 | Q37: 88.08 | R37: ARFAN
A38: B | B38: 3 | C38: 15 P | D38: 45660 | E38: سادہ لفافہ | F38: PP | G38: 12 | H38: رول | I38: 0 | J38: - | K38: PP | L38: 6 | M38: 299.44 | N38: 9.6 | Q38: 289.84 | R38: SHAHID
A39: A | B39: 4 | C39: 817 F | D39: 45660 | E39: وارننگ LEVIES | F39: PP | G39: 16.2 | H39: - | I39: - | J39: 4000 | K39: PP | L39: 16 | M39: 797.05 | Q39: 797.05 | R39: ARFAN
A40: B | B40: 4 | C40: 817 F | D40: 45660 | E40: وارننگ LEVIES | F40: PP | G40: 16.2 | H40: - | I40: - | J40: 4000 | K40: PP | L40: 17 | M40: 860.54 | N40: 34 | Q40: 826.54 | R40: SHAHID
...

Sheet PP JOB CARD PRD
A1: DATE | B1: SO | C1: PARTY NAME | D1: SIZE | E1: GUAGE | F1: QUALITY | G1: ORDER WT | H1: PAPER PRO | I1: CARD PRO | J1: DIFF | K1: REMARKS
A2: 45894 | B2: 11P/1 | C2: {=VLOOKUP(B2,'PP PRD'!C:R,{3,5,6,4,8},0)} -> - | D2: - | E2: - | F2: - | G2: - | H2: =SUMIFS('PP PRD'!M:M,'PP PRD'!C:C,'PP JOB CARD PRD'!B2) -> 631.1 | I2: =30.43+35.27+35.58+26.44+33.57+24.82+37.08+39.48+39.1+36.4+40.96+49+41.26+31.5+31.35+34.68+29.78+34.4 -> 631.1 | J2: =+H2-I2 -> 0
A3: 45895 | B3: 12P/1 | C3: {=VLOOKUP(B3,'PP PRD'!C:R,{3,5,6,4,8},0)} -> - | D3: 0 | E3: 0 | F3: 0 | G3: 0 | H3: =SUMIFS('PP PRD'!M:M,'PP PRD'!C:C,'PP JOB CARD PRD'!B3) -> 592.94 | I3: =29.11+32.17+28.52+28.35+48.5+42.71+26.78+42.52+47.33+40.12+35.84+37.8+34.69+34.48+35.24 -> 544.16 | J3: =+H3-I3 -> 48.78 | K3: JOB CARD PER AIK ROLL KA WZN NHI LIKHA
A4: 45895 | B4: 7204/1 | C4: {=VLOOKUP(B4,'PP PRD'!C:R,{3,5,6,4,8},0)} -> اسلم پلاسٹک ملتان | D4: 11 | E4: 6.5-7 | F4: PP | G4: 50 | H4: =SUMIFS('PP PRD'!M:M,'PP PRD'!C:C,'PP JOB CARD PRD'!B4) -> 126.78 | I4: =37.09+27.33+34.27+27.49 -> 126.18 | J4: =+H4-I4 -> 0.6
A5: 45895 | B5: 7194/3 | C5: {=VLOOKUP(B5,'PP PRD'!C:R,{3,5,6,4,8},0)} -> ایم عمران پاکستان مارکیٹ | D5: 11 | E5: 6.5 | F5: PP | G5: 800 | H5: =SUMIFS('PP PRD'!M:M,'PP PRD'!C:C,'PP JOB CARD PRD'!B5) -> 949.54 | I5: =34.34+30.43+29.39+27.87+28.97+49.9+54.33+40.17+47.59+38.27+40.12+40.72+39.9+37.55+43.22+35.37+34.86+34.66+38.3+37.36+37.19+37.31 -> 837.82 | J5: =+H5-I5 -> 111.72 | K5: JOB CARD PER WZN KM LIKHA HAI OR PRO CARD PER ZYADA HAI
A6: 45895 | B6: 19P/1 | C6: {=VLOOKUP(B6,'PP PRD'!C:R,{3,5,6,4,8},0)} -> 0 | D6: 0 | E6: - | F6: 0 | G6: 1000 | H6: =SUMIFS('PP PRD'!M:M,'PP PRD'!C:C,'PP JOB CARD PRD'!B6) -> 1104.69 | I6: =52.27+36.17+50.4+50.78+45.68+44.1+50.9+42.23+48.7+50.33+52.82+48.61+47.93+42.4+58.02+47.73+53.11+60.74+55.04+56.7+52.54 -> 1047.2 | J6: =+H6-I6 -> 57.49 | K6: JOB CARD PER AIK ROLL KA WZN NHI LIKHA
A7: 45895 | B7: 7173/6 | C7: {=VLOOKUP(B7,'PP PRD'!C:R,{3,5,6,4,8},0)} -> الحبیب پلاسٹک اوکاڑہ | D7: 20 | E7: 4.5 | F7: PP | G7: 100 | H7: =SUMIFS('PP PRD'!M:M,'PP PRD'!C:C,'PP JOB CARD PRD'!B7) -> 104.5 | I7: =52.26+52.24 -> 104.5 | J7: =+H7-I7 -> 0
A8: 45893 | B8: 7173/8 | C8: {=VLOOKUP(B8,'PP PRD'!C:R,{3,5,6,4,8},0)} -> الحبیب پلاسٹک اوکاڑہ | D8: 18 | E8: 5 | F8: PP | G8: 600 | H8: =SUMIFS('PP PRD'!M:M,'PP PRD'!C:C,'PP JOB CARD PRD'!B8) -> 1269.86 | I8: =55.32+53.07+54.42+52.45+52.87+62.2+53.25+40.23+58.32+69.53+62.03 -> 613.69 | J8: =+H8-I8 -> 656.17 | K8: JOB CARD PER 2 ROLL KA WZN NHI LIKHA
A9: 45893 | B9: 7169/1 | C9: {=VLOOKUP(B9,'PP PRD'!C:R,{3,5,6,4,8},0)} -> محبوب مقبول گوجرانوالہ | D9: 18 | E9: 7.5-8 | F9: PP | G9: 150 | H9: =SUMIFS('PP PRD'!M:M,'PP PRD'!C:C,'PP JOB CARD PRD'!B9) -> 166.34 | I9: =53.54+59.63+53.17 -> 166.34 | J9: =+H9-I9 -> 0
A10: 45892 | B10: 7160/1 | C10: {=VLOOKUP(B10,'PP PRD'!C:R,{3,5,6,4,8},0)} -> ایم دین پنڈی | D10: 7 | E10: 15 | F10: PP | G10: 600 | H10: =SUMIFS('PP PRD'!M:M,'PP PRD'!C:C,'PP JOB CARD PRD'!B10) -> 703.56 | I10: =19.65+27.6+33.05+33+30.39+32.3+23.05+19.72+20.77+19.9+20.19+21.04+21.43+19.6+19.88+19.57+22.35+21.31+26.37+19.94+21.45+20.02+32.46+32.62+30.97+32.43+25.51 -> 666.57 | J10: =+H10-I10 -> 36.99 | K10: JOB CARD PER 1 ROLL KA WZN NHI LIKHA
A11: 45893 | B11: 7173/1 | C11: {=VLOOKUP(B11,'PP PRD'!C:R,{3,5,6,4,8},0)} -> الحبیب پلاسٹک اوکاڑہ | D11: 8 | E11: 4.5 | F11: PP | G11: 300 | H11: =SUMIFS('PP PRD'!M:M,'PP PRD'!C:C,'PP JOB CARD PRD'!B11) -> 334.15 | I11: =33.51+40.9+34.25+47.24+35.02+35.26+40.2+26.7+37.43+39.61+36.44+37.79 -> 444.35 | J11: =+H11-I11 -> -110.2 | K11: JOB CARD PER 2 ROLL KA WZN NHI LIKHA
A12: 45893 | B12: 7171/1 | C12: {=VLOOKUP(B12,'PP PRD'!C:R,{3,5,6,4,8},0)} -> شاہد رمضان اوکاڑہ | D12: 18 | E12: 4.5 | F12: PP | G12: 200 | H12: =SUMIFS('PP PRD'!M:M,'PP PRD'!C:C,'PP JOB CARD PRD'!B12) -> 1232.34 | I12: =55.4+58.13 -> 113.53 | J12: =+H12-I12 -> 1118.81
A13: 45890 | B13: 7170/1 | C13: {=VLOOKUP(B13,'PP PRD'!C:R,{3,5,6,4,8},0)} -> بلال ازعظم مال کینٹ | D13: 12 | E13: 8 | F13: PP | G13: 50 | H13: =SUMIFS('PP PRD'!M:M,'PP PRD'!C:C,'PP JOB CARD PRD'!B13) -> 62.72 | I13: =25.68+40.09 -> 65.77 | J13: =+H13-I13 -> -3.05
A14: 45897 | B14: 7191/3 | C14: {=VLOOKUP(B14,'PP PRD'!C:R,{3,5,6,4,8},0)} -> العمر پلاسٹک گوجرانوالہ | D14: 18 | E14: 6 | F14: PP | G14: 250 | H14: =SUMIFS('PP PRD'!M:M,'PP PRD'!C:C,'PP JOB CARD PRD'!B14) -> 416.07 | I14: =60.23+56.13+59.1+61.52+57.43+51.74+69.92 -> 416.07 | J14: =+H14-I14 -> 0
A15: 45897 | B15: 3885 J | C15: {=VLOOKUP(B15,'PP PRD'!C:R,{3,5,6,4,8},0)} -> Bundu Khan Lahore | D15: 18" شیٹ | E15: 4-4.5/8-9 | F15: PP | G15: 150 | H15: =SUMIFS('PP PRD'!M:M,'PP PRD'!C:C,'PP JOB CARD PRD'!B15) -> 147.52 | I15: =35.5+33.9+40.87+37.25 -> 147.52 | J15: =+H15-I15 -> 0
A16: 45897 | B16: 7204/3 | C16: {=VLOOKUP(B16,'PP PRD'!C:R,{3,5,6,4,8},0)} -> اسلم پلاسٹک ملتان | D16: 12 | E16: 6.5-7 | F16: PP | G16: 50 | H16: =SUMIFS('PP PRD'!M:M,'PP PRD'!C:C,'PP JOB CARD PRD'!B16) -> 62.83 | I16: 62.83 | J16: =+H16-I16 -> 0
A17: 45898 | B17: 3886 J | C17: {=VLOOKUP(B17,'PP PRD'!C:R,{3,5,6,4,8},0)} -> Bundu Khan Lahore | D17: 18" شیٹ | E17: 4-4.5/8-9 | F17: PP | G17: 150 | H17: =SUMIFS('PP PRD'!M:M,'PP PRD'!C:C,'PP JOB CARD PRD'!B17) -> 152.96 | I17: =41.36+38.68+37.8+35.12 -> 152.96 | J17: =+H17-I17 -> 0
A18: 45898 | B18: 10 P | C18: {=VLOOKUP(B18,'PP PRD'!C:R,{3,5,6,4,8},0)} -> سادہ لفافہ | D18: 7 | E18: رول | F18: PP | G18: - | H18: =SUMIFS('PP PRD'!M:M,'PP PRD'!C:C,'PP JOB CARD PRD'!B18) -> 29929.27 | I18: =23.24+26.39+23.97+29.03+28.81+17+30.95+28.5+16.33+29.06+28.29+29.2+27.13+29.52+29.9+37.46+29.13+24.47+24.28+32.13+29.93+35.46+33.58+31.68+27.59+30.09+29.09+29.2+27.8+26.52+26.72+33.9+25.94+18.44+35.91+35.4+36.48 -> 1058.52 | J18: =+H18-I18 -> 28870.75
A19: 45898 | B19: 7191/5 | C19: {=VLOOKUP(B19,'PP PRD'!C:R,{3,5,6,4,8},0)} -> العمر پلاسٹک گوجرانوالہ | D19: 22 | E19: 6 | F19: PP | G19: 250 | H19: =SUMIFS('PP PRD'!M:M,'PP PRD'!C:C,'PP JOB CARD PRD'!B19) -> 266.9 | I19: =50.48+48.62+54.45+51.5+61.85 -> 266.9 | J19: =+H19-I19 -> 0
A20: 45898 | B20: 3883 J | C20: {=VLOOKUP(B20,'PP PRD'!C:R,{3,5,6,4,8},0)} -> Bundu Khan Lahore | D20: 22" شیٹ | E20: 4-4.5/8-9 | F20: PP | G20: 150 | H20: =SUMIFS('PP PRD'!M:M,'PP PRD'!C:C,'PP JOB CARD PRD'!B20) -> 140.95 | I20: =28.8+36.25+41.9+34 -> 140.95 | J20: =+H20-I20 -> 0
A21: 45898 | B21: 3917 J | C21: {=VLOOKUP(B21,'PP PRD'!C:R,{3,5,6,4,8},0)} -> Cakes and Bakes Lahore | D21: 16 | E21: 5.5-6 | F21: PP | G21: 250 | H21: =SUMIFS('PP PRD'!M:M,'PP PRD'!C:C,'PP JOB CARD PRD'!B21) -> 241.43 | I21: =47.56+43.4+53.28+47.9+49.29 -> 241.43 | J21: =+H21-I21 -> 0
A22: 45898 | B22: 7191/2 | C22: {=VLOOKUP(B22,'PP PRD'!C:R,{3,5,6,4,8},0)} -> العمر پلاسٹک گوجرانوالہ | D22: 16 | E22: 6 | F22: PP | G22: 1000 | H22: =SUMIFS('PP PRD'!M:M,'PP PRD'!C:C,'PP JOB CARD PRD'!B22) -> 1365.41 | I22: =33.37+48.76+52.34+49.23+50.7+46.9+52.73+51.68+52.01+41.98+48.19+54.25+33.71+42.81+61.75+50.5+35.4+47.7+54.3+50.9+33.8+45.73+49.29+46.61+51.39+47.65+36.53 -> 1270.21 | J22: =+H22-I22 -> 95.2
A23: 45898 | B23: 7171/10 | C23: {=VLOOKUP(B23,'PP PRD'!C:R,{3,5,6,4,8},0)} -> شاہد رمضان اوکاڑہ | D23: 8 | E23: 4.5 | F23: PP | G23: 100 | H23: =SUMIFS('PP PRD'!M:M,'PP PRD'!C:C,'PP JOB CARD PRD'!B23) -> 533.16 | I23: =20.98+21.78+44.22+36.51+33.9+33.8+32.69+29.42+31.54+34.08+32.68+39.42+34.96+34.38+37.45+35.76 -> 533.57 | J23: =+H23-I23 -> -0.41
A24: 45898 | B24: 7192/1 | C24: {=VLOOKUP(B24,'PP PRD'!C:R,{3,5,6,4,8},0)} -> ریفلیکٹ پیک لاہور | D24: 17 | E24: 5.5-6 | F24: PP | G24: 5000 | H24: =SUMIFS('PP PRD'!M:M,'PP PRD'!C:C,'PP JOB CARD PRD'!B24) -> 2803.38 | I24: =34.61+52.37+55.93+55+56.39+51.96+47.28+47.28+45.19+51.78+50.27+52.95+45.24+56.13+47.8+45.5+49.45+57.81+54.4+59.57+54.59+64.65+56.55+53.34+56.94+59.22+55.68+51.852+55.15+57.33+55.86+923.77+55.49+44.04 -> 2661.372 | J24: =+H24-I24 -> 142.008
A25: 45898 | B25: 7191/1 | C25: {=VLOOKUP(B25,'PP PRD'!C:R,{3,5,6,4,8},0)} -> العمر پلاسٹک گوجرانوالہ | D25: 14 | E25: 10 | F25: PP | G25: 250 | H25: =SUMIFS('PP PRD'!M:M,'PP PRD'!C:C,'PP JOB CARD PRD'!B25) -> 265.98 | I25: =45.56+48.46+34.12+48.04+44.23+45.57 -> 265.98 | J25: =+H25-I25 -> 0
A26: 45898 | B26: 11/1 | C26: {=VLOOKUP(B26,'PP PRD'!C:R,{3,5,6,4,8},0)} -> سٹاک | D26: 11 | E26: 5-5.5 | F26: PP | G26: 1000 | H26: =SUMIFS('PP PRD'!M:M,'PP PRD'!C:C,'PP JOB CARD PRD'!B26) -> 1223.5 | I26: =53.46+42.11+43+50.46+48.3+47.46+47.01+46.81+46.45+50.25+53.37+46.49+39.9+46.61+44.15+48.43+44+46.16+51.46+44.91+55.86 -> 996.65 | J26: =+H26-I26 -> 226.85
A27: 45898 | B27: 7168/1 | C27: {=VLOOKUP(B27,'PP PRD'!C:R,{3,5,6,4,8},0)} -> ریفلیکٹ پیک لاہور | D27: 16 | E27: 5.5-6 | F27: PP | G27: 2000 | H27: =SUMIFS('PP PRD'!M:M,'PP PRD'!C:C,'PP JOB CARD PRD'!B27) -> 298.4 | I27: =51.01+42.46+45.42+52.45+59.04+49.02+52.2+54.65+49.02+47.18+47.1 -> 549.55 | J27: =+H27-I27 -> -251.15
A28: 45903 | B28: 7202/11 | C28: {=VLOOKUP(B28,'PP PRD'!C:R,{3,5,6,4,8},0)} -> ہیڈ افس سٹاک لاہور | D28: 13 | E28: 7 | F28: PP | G28: 200 | H28: =SUMIFS('PP PRD'!M:M,'PP PRD'!C:C,'PP JOB CARD PRD'!B28) -> 319.87 | I28: =44.85+45.84+39.73+39.03+48+50.21+50.21 -> 317.87 | J28: =+H28-I28 -> 2
A29: 45903 | B29: 2101 F | C29: {=VLOOKUP(B29,'PP PRD'!C:R,{3,5,6,4,8},0)} -> Usman Amin | D29: 13 | E29: 8 | F29: PP | G29: 100 | H29: =SUMIFS('PP PRD'!M:M,'PP PRD'!C:C,'PP JOB CARD PRD'!B29) -> 100.38 | I29: =33.02+33.89+33.47 -> 100.38 | J29: =+H29-I29 -> 0
A30: 45903 | B30: 7194/6 | C30: {=VLOOKUP(B30,'PP PRD'!C:R,{3,5,6,4,8},0)} -> ایم عمران پاکستان مارکیٹ | D30: 19 | E30: 7 | F30: PP | G30: 400 | H30: =SUMIFS('PP PRD'!M:M,'PP PRD'!C:C,'PP JOB CARD PRD'!B30) -> 411.47 | I30: =34.52+35.48+39.5+39.3+41.66+32.2+39.24+33.6+39.02+35.9+41 -> 411.42 | J30: =+H30-I30 -> 0.05
A31: 45903 | B31: 7191/4 | C31: {=VLOOKUP(B31,'PP PRD'!C:R,{3,5,6,4,8},0)} -> العمر پلاسٹک گوجرانوالہ | D31: 20 | E31: 6 | F31: PP | G31: 1000 | H31: =SUMIFS('PP PRD'!M:M,'PP PRD'!C:C,'PP JOB CARD PRD'!B31) -> 1051.98 | I31: =55.22+60+57.29+62.75+59.32+54.93+52.59+51.25+56.76+60.12+50.32+51.09+55.55+51.72+58.09+62.9+53.92+58.05+48.12 -> 1059.99 | J31: =+H31-I31 -> -8.01
A32: 45903 | B32: 9/1 | C32: {=VLOOKUP(B32,'PP PRD'!C:R,{3,5,6,4,8},0)} -> سٹاک | D32: 9 | E32: 5-5.5 | F32: PP | G32: 500 | H32: =SUMIFS('PP PRD'!M:M,'PP PRD'!C:C,'PP JOB CARD PRD'!B32) -> 1914.89 | I32: =34.3+21.43+44.97+39.14+42.62+41.28+43.7+41.78+47.86+30.31+24+37.22+32.39+18.32+35.16+38.44+39.42+24.94+31.58+33.17+43.94+45.57+45+35.9+23.12+26.71+45.55+48.76+37.6+37.2+45.92+25+39.69+24.85+31.77+40.5+34+45.44+43.13+39.4+53+39.41+45.93+28.37+36.24+32.9+42.6+32 -> 1771.53 | J32: =+H32-I32 -> 143.36
A33: 45906 | B33: 7222/3 | C33: {=VLOOKUP(B33,'PP PRD'!C:R,{3,5,6,4,8},0)} -> اصف پلاسٹک سرگودھا | D33: 18 | E33: 4.5 | F33: PP | G33: 100 | H33: =SUMIFS('PP PRD'!M:M,'PP PRD'!C:C,'PP JOB CARD PRD'!B33) -> 88.95 | I33: =34.48+54.47 -> 88.95 | J33: =+H33-I33 -> 0
A34: 45906 | B34: 7/2 | C34: {=VLOOKUP(B34,'PP PRD'!C:R,{3,5,6,4,8},0)} -> سٹاک | D34: 7 | E34: 5 | F34: PP | G34: 800 | H34: =SUMIFS('PP PRD'!M:M,'PP PRD'!C:C,'PP JOB CARD PRD'!B34) -> 662.86 | I34: =30.7+34.38+29.33+38.2+35.52+36.23+34.01+34.1+36.87+35.61+39.4+32.77+31.75+32.47+28.1+31.35+31.63+30.3+29.78+38.56 -> 671.06 | J34: =+H34-I34 -> -8.2
A35: 45906 | B35: 7218/1 | C35: {=VLOOKUP(B35,'PP PRD'!C:R,{3,5,6,4,8},0)} -> اسد پلاسٹک ملتان | D35: 7 | E35: 4 | F35: PP | G35: 200 | H35: =SUMIFS('PP PRD'!M:M,'PP PRD'!C:C,'PP JOB CARD PRD'!B35) -> 134.67 | I35: =30.77+33.89+35.53+34.48+13.47 -> 148.14 | J35: =+H35-I35 -> -13.47
A36: 45906 | B36: 14/1 | C36: {=VLOOKUP(B36,'PP PRD'!C:R,{3,5,6,4,8},0)} -> سٹاک | D36: 14 | E36: 5 | F36: PP | G36: 1000 | H36: =SUMIFS('PP PRD'!M:M,'PP PRD'!C:C,'PP JOB CARD PRD'!B36) -> 850.24 | I36: =53.31+45.21+43.69+35.2+52.73+50.75+46.6+49.77+42.91+55.9+52.39+44.18+54.58+32.73+46.08+52.28+59.82+42.03 -> 860.16 | J36: =+H36-I36 -> -9.92
A37: 45906 | B37: 7222/6 | C37: {=VLOOKUP(B37,'PP PRD'!C:R,{3,5,6,4,8},0)} -> اصف پلاسٹک سرگودھا | D37: 3.5 | E37: 5 | F37: PP | G37: 125 | H37: =SUMIFS('PP PRD'!M:M,'PP PRD'!C:C,'PP JOB CARD PRD'!B37) -> 332.75 | I37: =14.05+14.08+14.72+13.23+13.03+10.86 -> 79.97 | J37: =+H37-I37 -> 252.78
A38: 45906 | B38: 7228/2 | C38: {=VLOOKUP(B38,'PP PRD'!C:R,{3,5,6,4,8},0)} -> بلال سویاں سرگودھا | D38: 4.5 | E38: 5 | F38: PP | G38: 160 | H38: =SUMIFS('PP PRD'!M:M,'PP PRD'!C:C,'PP JOB CARD PRD'!B38) -> 139.7 | I38: =15.3+17+17.56+17.46+19.79+15.69+18.63+18.27 -> 139.7 | J38: =+H38-I38 -> 0
A39: 45906 | B39: 16/2 | C39: {=VLOOKUP(B39,'PP PRD'!C:R,{3,5,6,4,8},0)} -> سٹاک | D39: 16 | E39: 5 | F39: PP | G39: 500 | H39: =SUMIFS('PP PRD'!M:M,'PP PRD'!C:C,'PP JOB CARD PRD'!B39) -> 1474.71 | I39: =48.64+46.58+49.84+58.5+43.8+55.55+38.17+47.59+49.48+44.57+51.46+51.89 -> 586.07 | J39: =+H39-I39 -> 888.64
A40: 45906 | B40: 2098 F | C40: {=VLOOKUP(B40,'PP PRD'!C:R,{3,5,6,4,8},0)} -> Usman Amin | D40: 16 | E40: 8 | F40: PP | G40: 100 | H40: =SUMIFS('PP PRD'!M:M,'PP PRD'!C:C,'PP JOB CARD PRD'!B40) -> 275.59 | I40: =54.49+52.98+55.31+53.88+58.93 -> 275.59 | J40: =+H40-I40 -> 0
...

Sheet PP SIDE SEAL 
A1: SHIFT | B1: MCH# | C1: SO# | D1: DATE | E1: JOB NAME | F1: MATERIAL | G1: SIZE | H1: GUAGE | I1: TUBE SIZE | J1: ORDER WEIGHT | K1: NO OF BAGS | L1: NET WEIGHT | M1: PRD WATSE | N1: OPERTAOR
A2: A | B2: 1 | C2: 6448/6 | D2: 45658 | E2: حاجی اسلماعیل وہاڑی | F2: PP | G2: 7X14 | H2: 5 | I2: 0 | J2: 125 | K2: 5 | L2: 125 | M2: 0.6 | N2: ALI HASSAN
A3: A | B3: 1 | C3: 6448/5 | D3: 45658 | E3: حاجی اسلماعیل وہاڑی | F3: PP | G3: 10X14 | H3: 5 | I3: 0 | J3: 125 | K3: 1 | L3: 25 | M3: 0.2 | N3: ALI HASSAN
A4: A | B4: 1 | C4: 6442/1 | D4: 45658 | E4: العمر پلاسٹک گوجرانوالہ | F4: PP | G4: 6X7 | H4: 5 | I4: 0 | J4: 375 | K4: 3 | L4: 75 | M4: 0.4 | N4: ALI HASSAN
A5: A | B5: 2 | C5: 6453/2 | D5: 45658 | E5: کراچی پلاسٹک فیصل آباد | F5: PP | G5: 5X7 | H5: 10 | I5: 0 | J5: 100 | K5: 3 | L5: 75 | M5: 1.6 | N5: ZAHAD
A6: A | B6: 2 | C6: 6453/4 | D6: 45658 | E6: کراچی پلاسٹک فیصل آباد | F6: PP | G6: 7X10 | H6: 10 | I6: 0 | J6: 100 | K6: 4 | L6: 104.5 | M6: 2.1 | N6: ZAHAD
A7: B | B7: 1 | C7: 6460/1 | D7: 45658 | E7: ایم سلمان پاکستان مارکیٹ | F7: PP | G7: 9X28 | H7: 5 | I7: 0 | J7: 150 | K7: 6 | L7: 150 | M7: 0.6 | N7: NAEEM
A8: B | B8: 1 | C8: 6460/2 | D8: 45658 | E8: ایم سلمان پاکستان مارکیٹ | F8: PP | G8: 10X28 | H8: 5 | I8: 0 | J8: 100 | K8: 4 | L8: 100 | M8: 0.6 | N8: NAEEM
A9: B | B9: 1 | C9: 6448/8 | D9: 45658 | E9: حاجی اسلماعیل وہاڑی | F9: PP | G9: 12X28 | H9: 5 | I9: 0 | J9: 125 | K9: 1 | L9: 25 | M9: 0.6 | N9: NAEEM
A10: B | B10: 1 | C10: 6448/7 | D10: 45658 | E10: حاجی اسلماعیل وہاڑی | F10: PP | G10: 12X26 | H10: 5 | I10: 0 | J10: 75 | K10: 3 | L10: 75 | M10: 0.2 | N10: NAEEM
A11: B | B11: 2 | C11: 6451/1 | D11: 45658 | E11: ایم بوٹا اعظم مارکیٹ | F11: PP | G11: 9X27 | H11: 6 | I11: 0 | J11: 100 | K11: 4 | L11: 100 | M11: 0.3 | N11: ZAIN
A12: B | B12: 2 | C12: 6451/2 | D12: 45658 | E12: - | F12: - | G12: - | H12: - | I12: - | J12: - | K12: 3 | L12: 75 | M12: 0.1 | N12: ZAIN
A13: B | B13: 2 | C13: 6448/1 | D13: 45658 | E13: حاجی اسلماعیل وہاڑی | F13: PP | G13: 6X9 | H13: 5 | I13: 0 | J13: 150 | K13: 4 | L13: 100 | M13: 0.4 | N13: ZAIN
A14: B | B14: 2 | C14: 6453/2 | D14: 45658 | E14: کراچی پلاسٹک فیصل آباد | F14: PP | G14: 5X7 | H14: 10 | I14: 0 | J14: 100 | K14: 1 | L14: 16.5 | M14: 0.1 | N14: ZAIN
A15: A | B15: 2 | C15: 6470/1 | D15: 45659 | E15: ریفلکٹ پیک | F15: PP | G15: 13X16 | H15: 5.5/6 | I15: 0 | J15: 500 | K15: 11 | L15: 275 | M15: 1.1 | N15: ZAHAD
A16: A | B16: 2 | C16: 6457/1 | D16: 45659 | E16: راجکپور کریانہ سٹور گھوٹکی | F16: PP | G16: 11X20 | H16: 5 | I16: 0 | J16: 125 | K16: 1 | L16: 25 | M16: 0.5 | N16: ZAHAD
A17: A | B17: 1 | C17: 6470/1 | D17: 45659 | E17: ریفلکٹ پیک | F17: PP | G17: 13X16 | H17: 5.5/6 | I17: 0 | J17: 500 | K17: 9 | L17: 225 | M17: 1 | N17: ALI HASSAN
A18: A | B18: 1 | C18: 6448/4 | D18: 45659 | E18: حاجی اسلماعیل وہاڑی | F18: PP | G18: 9X13 | H18: 5 | I18: 0 | J18: 125 | K18: 2 | L18: 50 | M18: 0.8 | N18: ALI HASSAN
A19: B | B19: 1 | C19: 6448/4 | D19: 45659 | E19: حاجی اسلماعیل وہاڑی | F19: PP | G19: 9X13 | H19: 5 | I19: 0 | J19: 125 | K19: 3 | L19: 75 | M19: 0.2 | N19: NAEEM
A20: B | B20: 1 | C20: 6448/2 | D20: 45659 | E20: حاجی اسلماعیل وہاڑی | F20: PP | G20: 7X11 | H20: 5 | I20: 0 | J20: 125 | K20: 5 | L20: 130 | M20: 0.6 | N20: NAEEM
A21: B | B21: 1 | C21: 6453/3 | D21: 45659 | E21: کراچی پلاسٹک فیصل آباد | F21: PP | G21: 6X8 | H21: 10 | I21: 0 | J21: 100 | K21: 2 | L21: 55.6 | M21: 0.3 | N21: NAEEM
A22: B | B22: 2 | C22: 6453/3 | D22: 45659 | E22: کراچی پلاسٹک فیصل آباد | F22: PP | G22: 6X8 | H22: 10 | I22: 0 | J22: 100 | K22: 2 | L22: 50 | M22: 0.2 | N22: ZAIN
A23: B | B23: 2 | C23: 6457/1 | D23: 45659 | E23: راجکپور کریانہ سٹور گھوٹکی | F23: PP | G23: 11X20 | H23: 5 | I23: 0 | J23: 125 | K23: 4 | L23: 100 | M23: 0.2 | N23: ZAIN
A24: B | B24: 2 | C24: 6453/1 | D24: 45659 | E24: کراچی پلاسٹک فیصل آباد | F24: PP | G24: 4.5X6 | H24: 10 | I24: 0 | J24: 100 | K24: 3 | L24: 75 | M24: 0.2 | N24: ZAIN
A25: A | B25: 1 | C25: 6453/1 | D25: 45660 | E25: کراچی پلاسٹک فیصل آباد | F25: PP | G25: 4.5X6 | H25: 10 | I25: 0 | J25: 100 | K25: 1 | L25: 36.35 | M25: 1 | N25: ALI HASSAN
A26: A | B26: 1 | C26: 6444/15 | D26: 45660 | E26: فضل سعید صادق آباد | F26: PP | G26: 7.5X11 | H26: 5 | I26: 0 | J26: 150 | K26: 5 | L26: 125 | M26: 0.8 | N26: ALI HASSAN
A27: A | B27: 1 | C27: 6469/1 | D27: 45660 | E27: ایم دین بند ل | F27: PP | G27: 4X5 | H27: 14 | I27: 0 | J27: 500 | K27: 1 | L27: 30 | M27: 0.6 | N27: ALI HASSAN
A28: A | B28: 2 | C28: 6499/1 | D28: 45660 | E28: ہیڈآفس لاہور | F28: PP | G28: 9X6.5+1.5 | H28: 5 | I28: 0 | J28: 100 | K28: 4 | L28: 100 | M28: 0.8 | N28: ZAHAD
A29: B | B29: 1 | C29: 6469/1 | D29: 45660 | E29: ایم دین بند ل | F29: PP | G29: 4X5 | H29: 14 | I29: 0 | J29: 500 | K29: 2 | L29: 60 | M29: 0.1 | N29: NAEEM
... A35: A | B35: 1 | C35: 6469/2 | D35: 45663 | E35: ایم دین بند ل | F35: PP | G35: 6X8 | H35: 14 | I35: 0 | J35: 125 | K35: 6 | L35: 164 | M35: 0.5 | N35: NAEEM
A36: A | B36: 1 | C36: 6482/1 | D36: 45663 | E36: ریفلکٹ پیک | F36: PP | G36: 15X16 | H36: 5.5-6 | I36: 0 | J36: 1000 | K36: 4 | L36: 100 | M36: 0.2 | N36: NAEEM
A37: A | B37: 2 | C37: 6469/1 | D37: 45663 | E37: ایم دین بند ل | F37: PP | G37: 4X5 | H37: 14 | I37: 0 | J37: 500 | K37: 1 | L37: 22.7 | M37: 0.1 | N37: ZAIN
A38: A | B38: 2 | C38: 6482/1 | D38: 45663 | E38: ریفلکٹ پیک | F38: PP | G38: 15X16 | H38: 5.5-6 | I38: 0 | J38: 1000 | K38: 11 | L38: 275 | M38: 1.9 | N38: ZAIN
A39: B | B39: 2 | C39: 6482/1 | D39: 45663 | E39: ریفلکٹ پیک | F39: PP | G39: 15X16 | H39: 5.5-6 | I39: 0 | J39: 1000 | K39: 10 | L39: 250 | M39: 0.4 | N39: NAEEM
A40: B | B40: 2 | C40: 6482/2 | D40: 45663 | E40: ریفلکٹ پیک | F40: PP | G40: 12X20 | H40: 5.5-6 | I40: 0 | J40: 500 | K40: 14 | L40: 350 | M40: 1.1 | N40: ALI HASSAN
A41: A | B41: 1 | C41: 6482/1 | D41: 45664 | E41: ریفلکٹ پیک | F41: PP | G41: 15X16 | H41: 5.5-6 | I41: 0 | J41: 1000 | K41: 15 | L41: 375 | M41: 0.8 | N41: NAEEM
A42: A | B42: 2 | C42: 6437/4 | D42: 45664 | E42: ہیڈآفس لاہور | F42: PP | G42: 14X20+2 | H42: 5 | I42: 0 | J42: 250 | K42: 10 | L42: 250 | N42: ZAIN
A43: A | B43: 2 | C43: 6482/2 | D43: 45664 | E43: ریفلکٹ پیک | F43: PP | G43: 12X20 | H43: 5.5-6 | I43: 0 | J43: 500 | K43: 3 | L43: 75 | M43: 0.2 | N43: ZAIN
A44: B | B44: 1 | C44: 6492/1 | D44: 45664 | E44: ہیڈآفس لاہور | F44: PP | G44: 9X28 | H44: 5 | I44: 0 | J44: 625 | K44: 11 | L44: 275 | M44: 0.9 | N44: ZAIN
A45: B | B45: 2 | C45: 6482/2 | D45: 45664 | E45: ریفلکٹ پیک | F45: PP | G45: 12X20 | H45: 5.5-6 | I45: 0 | J45: 500 | K45: 3 | L45: 75 | M45: 0.6 | N45: ALI HASSAN
...

Sheet PP SIDE SEAL JOB CARD
A1: DATE | B1: SO | C1: PARTY NAME | D1: SIZE | E1: GUAGE | F1: QUALITY | G1: ORDER WT | H1: PAPER PRO | I1: BAGS | J1: CARD PRO | K1: DIFF
A2: 45887 | B2: 7173/8 | C2: {=VLOOKUP(B2,'PP SIDE SEAL '!C:N,{3,5,6,4,8},0)} -> الحبیب پلاسٹک اوکاڑہ | D2: 09.50X18 | E2: 5 | F2: PP | G2: 600 | H2: =SUMIFS('PP SIDE SEAL '!L:L,'PP SIDE SEAL '!C:C,B2) -> 350 | J2: =125+250+225 -> 600 | K2: =+H2-J2 -> -250
A3: 45887 | B3: 7186/1 | C3: {=VLOOKUP(B3,'PP SIDE SEAL '!C:N,{3,5,6,4,8},0)} -> اقبال پلاسٹک کوٹ ادو | D3: 05X06 | E3: 5 | F3: PP | G3: 125 | H3: =SUMIFS('PP SIDE SEAL '!L:L,'PP SIDE SEAL '!C:C,B3) -> 75 | J3: =50+25 -> 75 | K3: =+H3-J3 -> 0
A4: 45887 | B4: 7176/3 | C4: {=VLOOKUP(B4,'PP SIDE SEAL '!C:N,{3,5,6,4,8},0)} -> حاجی اسلماعیل وہاڑی | D4: 08X12 | E4: 5 | F4: PP | G4: 200 | H4: =SUMIFS('PP SIDE SEAL '!L:L,'PP SIDE SEAL '!C:C,B4) -> 200 | J4: 200 | K4: =+H4-J4 -> 0
A5: 45887 | B5: 7176/2 | C5: {=VLOOKUP(B5,'PP SIDE SEAL '!C:N,{3,5,6,4,8},0)} -> حاجی اسلماعیل وہاڑی | D5: 07X11 | E5: 5 | F5: PP | G5: 150 | H5: =SUMIFS('PP SIDE SEAL '!L:L,'PP SIDE SEAL '!C:C,B5) -> 143.2 | J5: =118.2+25 -> 143.2 | K5: =+H5-J5 -> 0
A6: 45887 | B6: 7176/1 | C6: {=VLOOKUP(B6,'PP SIDE SEAL '!C:N,{3,5,6,4,8},0)} -> حاجی اسلماعیل وہاڑی | D6: 06X09 | E6: 5 | F6: PP | G6: 175 | H6: =SUMIFS('PP SIDE SEAL '!L:L,'PP SIDE SEAL '!C:C,B6) -> 175 | J6: =50+125 -> 175 | K6: =+H6-J6 -> 0
A7: 45887 | B7: 7176/5 | C7: {=VLOOKUP(B7,'PP SIDE SEAL '!C:N,{3,5,6,4,8},0)} -> حاجی اسلماعیل وہاڑی | D7: 06X12 | E7: 5 | F7: PP | G7: 100 | H7: =SUMIFS('PP SIDE SEAL '!L:L,'PP SIDE SEAL '!C:C,B7) -> 100 | J7: 100 | K7: =+H7-J7 -> 0
A8: 45892 | B8: 7182/1 | C8: {=VLOOKUP(B8,'PP SIDE SEAL '!C:N,{3,5,6,4,8},0)} -> عامر شہزاد ساہیوال | D8: 14X16 | E8: 5 | F8: PP | G8: 500 | H8: =SUMIFS('PP SIDE SEAL '!L:L,'PP SIDE SEAL '!C:C,B8) -> 500 | J8: =225+125+150 -> 500 | K8: =+H8-J8 -> 0
A9: 45875 | B9: 7139/6 | C9: {=VLOOKUP(B9,'PP SIDE SEAL '!C:N,{3,5,6,4,8},0)} -> لفافہ | D9: 09.50X18 | E9: 5 | F9: PP | G9: 50 | H9: =SUMIFS('PP SIDE SEAL '!L:L,'PP SIDE SEAL '!C:C,B9) -> 50 | J9: 50 | K9: =+H9-J9 -> 0
A10: 45891 | B10: 7184/1 | C10: {=VLOOKUP(B10,'PP SIDE SEAL '!C:N,{3,5,6,4,8},0)} -> ریفلیکٹ پیک لاہور | D10: 13.5X16 | E10: 5.5-6 | F10: PP | G10: 100 | H10: =SUMIFS('PP SIDE SEAL '!L:L,'PP SIDE SEAL '!C:C,B10) -> 100 | J10: 100 | K10: =+H10-J10 -> 0
A11: 45890 | B11: 7176/10 | C11: {=VLOOKUP(B11,'PP SIDE SEAL '!C:N,{3,5,6,4,8},0)} -> حاجی اسلماعیل وہاڑی | D11: 12X26 | E11: 5 | F11: PP | G11: 125 | H11: =SUMIFS('PP SIDE SEAL '!L:L,'PP SIDE SEAL '!C:C,B11) -> 119.5 | J11: 119.5 | K11: =+H11-J11 -> 0
A12: 45890 | B12: 7176/12 | C12: {=VLOOKUP(B12,'PP SIDE SEAL '!C:N,{3,5,6,4,8},0)} -> حاجی اسلماعیل وہاڑی | D12: 05X06 | E12: 5 | F12: PP | G12: 100 | H12: =SUMIFS('PP SIDE SEAL '!L:L,'PP SIDE SEAL '!C:C,B12) -> 150 | J12: =75+25 -> 100 | K12: =+H12-J12 -> 50
A13: 45889 | B13: 7176/11 | C13: {=VLOOKUP(B13,'PP SIDE SEAL '!C:N,{3,5,6,4,8},0)} -> حاجی اسلماعیل وہاڑی | D13: 14X20 | E13: 5 | F13: PP | G13: 150 | H13: =SUMIFS('PP SIDE SEAL '!L:L,'PP SIDE SEAL '!C:C,B13) -> 150 | J13: 150 | K13: =+H13-J13 -> 0
A14: 45888 | B14: 7171/13 | C14: {=VLOOKUP(B14,'PP SIDE SEAL '!C:N,{3,5,6,4,8},0)} -> شاہد رمضان اوکاڑہ | D14: 08.50X18 | E14: 4.5 | F14: PP | G14: 100 | H14: =SUMIFS('PP SIDE SEAL '!L:L,'PP SIDE SEAL '!C:C,B14) -> 125 | J14: =75+25 -> 100 | K14: =+H14-J14 -> 25
A15: 45888 | B15: 7171/12 | C15: {=VLOOKUP(B15,'PP SIDE SEAL '!C:N,{3,5,6,4,8},0)} -> شاہد رمضان اوکاڑہ | D15: 09.50X18 | E15: 4.5 | F15: PP | G15: 100 | H15: =SUMIFS('PP SIDE SEAL '!L:L,'PP SIDE SEAL '!C:C,B15) -> 200 | J15: 200 | K15: =+H15-J15 -> 0
A16: 45894 | B16: 7200/1 | C16: {=VLOOKUP(B16,'PP SIDE SEAL '!C:N,{3,5,6,4,8},0)} -> ایم دین پنڈی | D16: 05X06 | E16: 15 | F16: PP | G16: 900 | H16: =SUMIFS('PP SIDE SEAL '!L:L,'PP SIDE SEAL '!C:C,B16) -> 887.2 | J16: =120+150+120+180+180+30+117.2 -> 897.2 | K16: =+H16-J16 -> -10
A17: 45894 | B17: 7109/1 | C17: {=VLOOKUP(B17,'PP SIDE SEAL '!C:N,{3,5,6,4,8},0)} -> رول | D17: 5X7 | E17: 15 | F17: PP | G17: 300 | H17: =SUMIFS('PP SIDE SEAL '!L:L,'PP SIDE SEAL '!C:C,B17) -> 351 | J17: =210+141 -> 351 | K17: =+H17-J17 -> 0
A18: 45894 | B18: 7109/2 | C18: {=VLOOKUP(B18,'PP SIDE SEAL '!C:N,{3,5,6,4,8},0)} -> رول | D18: 6X8 | E18: 15 | F18: PP | G18: 175 | H18: =SUMIFS('PP SIDE SEAL '!L:L,'PP SIDE SEAL '!C:C,B18) -> 73.8 | J18: =150+73.8 -> 223.8 | K18: =+H18-J18 -> -150
A19: 45894 | B19: 7109/3 | C19: {=VLOOKUP(B19,'PP SIDE SEAL '!C:N,{3,5,6,4,8},0)} -> رول | D19: 4X5 | E19: 15 | F19: PP | G19: 375 | H19: =SUMIFS('PP SIDE SEAL '!L:L,'PP SIDE SEAL '!C:C,B19) -> 350.8 | J19: =120+180.8 -> 300.8 | K19: =+H19-J19 -> 50
A20: 45894 | B20: 7210/2 | C20: {=VLOOKUP(B20,'PP SIDE SEAL '!C:N,{3,5,6,4,8},0)} -> جہانگیر حسین گودام گوجراوالا | D20: 10X18 | E20: 6-6.5 | F20: PP | G20: 100 | H20: =SUMIFS('PP SIDE SEAL '!L:L,'PP SIDE SEAL '!C:C,B20) -> 101.65 | J20: 101.65 | K20: =+H20-J20 -> 0
A21: 45895 | B21: 7169/1 | C21: {=VLOOKUP(B21,'PP SIDE SEAL '!C:N,{3,5,6,4,8},0)} -> محبوب مقبول گوجرانوالہ | D21: 06.50X18 | E21: 7.5-8 | F21: PP | G21: 150 | H21: =SUMIFS('PP SIDE SEAL '!L:L,'PP SIDE SEAL '!C:C,B21) -> 158.1 | J21: 158.1 | K21: =+H21-J21 -> 0
A22: 45895 | B22: 7210/1 | C22: {=VLOOKUP(B22,'PP SIDE SEAL '!C:N,{3,5,6,4,8},0)} -> جہانگیر حسین گودام گوجراوالا | D22: 08.25X16 | E22: 6-6.5 | F22: PP | G22: 100 | H22: =SUMIFS('PP SIDE SEAL '!L:L,'PP SIDE SEAL '!C:C,B22) -> 100 | J22: 100 | K22: =+H22-J22 -> 0
A23: 45895 | B23: 7202/10 | C23: {=VLOOKUP(B23,'PP SIDE SEAL '!C:N,{3,5,6,4,8},0)} -> ہیڈ افس سٹاک لاہور | D23: 07X12 | E23: 5 | F23: PP | G23: 375 | H23: =SUMIFS('PP SIDE SEAL '!L:L,'PP SIDE SEAL '!C:C,B23) -> 375 | J23: =150+175+50 -> 375 | K23: =+H23-J23 -> 0
A24: 45895 | B24: 7202/12 | C24: {=VLOOKUP(B24,'PP SIDE SEAL '!C:N,{3,5,6,4,8},0)} -> ہیڈ افس سٹاک لاہور | D24: 10X14+02 | E24: 7 | F24: PP | G24: 200 | H24: =SUMIFS('PP SIDE SEAL '!L:L,'PP SIDE SEAL '!C:C,B24) -> 211 | I24: 8 | J24: 211 | K24: =+H24-J24 -> 0
A25: 45896 | B25: 7204/2 | C25: {=VLOOKUP(B25,'PP SIDE SEAL '!C:N,{3,5,6,4,8},0)} -> اسلم پلاسٹک ملتان | D25: 10X10+02 | E25: 6.5-7 | F25: PP | G25: 50 | H25: =SUMIFS('PP SIDE SEAL '!L:L,'PP SIDE SEAL '!C:C,B25) -> 50 | I25: 2 | J25: 50 | K25: =+H25-J25 -> 0
A26: 45896 | B26: 7209/1 | C26: {=VLOOKUP(B26,'PP SIDE SEAL '!C:N,{3,5,6,4,8},0)} -> MTM شاہ عالم | D26: 05X10+02 | E26: 6-6.5 | F26: PP | G26: 100 | H26: =SUMIFS('PP SIDE SEAL '!L:L,'PP SIDE SEAL '!C:C,B26) -> 104 | I26: 4 | J26: =79+25 -> 104 | K26: =+H26-J26 -> 0
A27: 45896 | B27: 7202/11 | C27: {=VLOOKUP(B27,'PP SIDE SEAL '!C:N,{3,5,6,4,8},0)} -> ہیڈ افس سٹاک لاہور | D27: 10X12+02 | E27: 7 | F27: PP | G27: 200 | H27: =SUMIFS('PP SIDE SEAL '!L:L,'PP SIDE SEAL '!C:C,B27) -> 209.5 | I27: =6+2 -> 8 | J27: =25*6+59.5 -> 209.5 | K27: =+H27-J27 -> 0
A28: 45896 | B28: 7190/1 | C28: {=VLOOKUP(B28,'PP SIDE SEAL '!C:N,{3,5,6,4,8},0)} -> فوڈ سٹار ٹریڈرز | D28: 14X16 | E28: 5 | F28: PP | G28: 100 | H28: =SUMIFS('PP SIDE SEAL '!L:L,'PP SIDE SEAL '!C:C,B28) -> 100 | I28: 4 | J28: 100 | K28: =+H28-J28 -> 0
A29: 45897 | B29: 7204/3 | C29: {=VLOOKUP(B29,'PP SIDE SEAL '!C:N,{3,5,6,4,8},0)} -> اسلم پلاسٹک ملتان | D29: 10X11+02 | E29: 6.5-7 | F29: PP | G29: 50 | H29: =SUMIFS('PP SIDE SEAL '!L:L,'PP SIDE SEAL '!C:C,B29) -> 50 | I29: 2 | J29: 50 | K29: =+H29-J29 -> 0
A30: 45899 | B30: 7167/1 | C30: {=VLOOKUP(B30,'PP SIDE SEAL '!C:N,{3,5,6,4,8},0)} -> ریفلیکٹ پیک لاہور | D30: 08X12 | E30: 5.5-6 | F30: PP | G30: 3000 | H30: =SUMIFS('PP SIDE SEAL '!L:L,'PP SIDE SEAL '!C:C,B30) -> 1390 | I30: =6+7+7+7+7+6 -> 40 | J30: =210+245+245+245+245+210 -> 1400 | K30: =+H30-J30 -> -10
A31: 45899 | B31: 7204/1 | C31: {=VLOOKUP(B31,'PP SIDE SEAL '!C:N,{3,5,6,4,8},0)} -> اسلم پلاسٹک ملتان | D31: 07.50X10+01.50 | E31: 6.5-7 | F31: PP | G31: 50 | H31: =SUMIFS('PP SIDE SEAL '!L:L,'PP SIDE SEAL '!C:C,B31) -> 50 | I31: 2 | J31: 50 | K31: =+H31-J31 -> 0
A32: 45899 | B32: 3525 J | C32: {=VLOOKUP(B32,'PP SIDE SEAL '!C:N,{3,5,6,4,8},0)} -> Ibtsam Traders Sheikhupura | D32: 4.5X5+2 | E32: 7.5-8 | F32: PP | G32: 100 | H32: =SUMIFS('PP SIDE SEAL '!L:L,'PP SIDE SEAL '!C:C,B32) -> 36.2 | I32: 4 | J32: =28.3+26.3+27.2+28.8 -> 110.6 | K32: =+H32-J32 -> -74.4
A33: 45899 | B33: 7122/1 | C33: {=VLOOKUP(B33,'PP SIDE SEAL '!C:N,{3,5,6,4,8},0)} -> رول | D33: 10X22 | E33: 5-5.5 | F33: PP | G33: 400 | H33: =SUMIFS('PP SIDE SEAL '!L:L,'PP SIDE SEAL '!C:C,B33) -> 401.8 | I33: 16 | J33: =25*I33 -> 400 | K33: =+H33-J33 -> 1.8
A34: 45899 | B34: 7220/1 | C34: {=VLOOKUP(B34,'PP SIDE SEAL '!C:N,{3,5,6,4,8},0)} -> فہیم پلاسٹک ملتان | D34: 09X10+02 | E34: 7 | F34: PP | G34: 100 | H34: =SUMIFS('PP SIDE SEAL '!L:L,'PP SIDE SEAL '!C:C,B34) -> 92.9 | I34: 4 | J34: 92.9 | K34: =+H34-J34 -> 0
A35: 45899 | B35: 4021 J | C35: {=VLOOKUP(B35,'PP SIDE SEAL '!C:N,{3,5,6,4,8},0)} -> Jilani plastic | D35: 7X10 (10X13) | E35: 5-5.5 | F35: PP | G35: 400 | H35: =SUMIFS('PP SIDE SEAL '!L:L,'PP SIDE SEAL '!C:C,B35) -> 415.9 | I35: 7 | J35: 240.9 | K35: =+H35-J35 -> 175
A36: 45899 | B36: 7168/1 | C36: {=VLOOKUP(B36,'PP SIDE SEAL '!C:N,{3,5,6,4,8},0)} -> ریفلیکٹ پیک لاہور | D36: 15X16 | E36: 5.5-6 | F36: PP | G36: 2000 | H36: =SUMIFS('PP SIDE SEAL '!L:L,'PP SIDE SEAL '!C:C,B36) -> 1993.4 | I36: =8+12+2+12+13+12+13+5+3 -> 80 | J36: =200+300+50+300+325+300+325+125+68.4 -> 1993.4 | K36: =+H36-J36 -> 0
A37: 45904 | B37: 7058/1 | C37: {=VLOOKUP(B37,'PP SIDE SEAL '!C:N,{3,5,6,4,8},0)} -> لفافہ | D37: 8X11 | E37: 5/5.5 | F37: PP | G37: 750 | H37: =SUMIFS('PP SIDE SEAL '!L:L,'PP SIDE SEAL '!C:C,B37) -> 750 | I37: =8+8+8+6 -> 30 | J37: =25*I37 -> 750 | K37: =+H37-J37 -> 0
A38: 45904 | B38: 7239/2 | C38: {=VLOOKUP(B38,'PP SIDE SEAL '!C:N,{3,5,6,4,8},0)} -> محبوب مقبول گوجرانوالہ | D38: 12X13 | E38: 5 | F38: PP | G38: 500 | H38: =SUMIFS('PP SIDE SEAL '!L:L,'PP SIDE SEAL '!C:C,B38) -> 500 | I38: =9+11 -> 20 | J38: =25*I38 -> 500 | K38: =+H38-J38 -> 0
A39: 45904 | B39: 7232/1 | C39: {=VLOOKUP(B39,'PP SIDE SEAL '!C:N,{3,5,6,4,8},0)} -> اسد بلال بہاورلپور | D39: 09.50X20 | E39: 5 | F39: PP | G39: 100 | H39: =SUMIFS('PP SIDE SEAL '!L:L,'PP SIDE SEAL '!C:C,B39) -> 105 | I39: =2+2 -> 4 | J39: =25*I39 -> 100 | K39: =+H39-J39 -> 5
A40: 45904 | B40: 7220/2 | C40: {=VLOOKUP(B40,'PP SIDE SEAL '!C:N,{3,5,6,4,8},0)} -> فہیم پلاسٹک ملتان | D40: 10X12+02 | E40: 7 | F40: PP | G40: 200 | H40: =SUMIFS('PP SIDE SEAL '!L:L,'PP SIDE SEAL '!C:C,B40) -> 211 | I40: =2+2+4 -> 8 | J40: =50+50+19+92 -> 211 | K40: =+H40-J40 -> 0
...

Sheet PP BOTTOM SEAL
A1: SHIFT | B1: MCH# | C1: SO# | D1: DATE | E1: JOB NAME | F1: MATERIAL | G1: SIZE | H1: GUAGE | I1: TUBE | J1: ORDER WEIGHT | K1: NO OF BAGS | L1: NET WEIGHT | M1: PRD WASTE | N1: OPERATOR
A2: A | B2: 1 | C2: 6306/1 | D2: 45658 | E2: عثمان امین لاہور | F2: PP | G2: 7X15 | H2: 0 | I2: 0 | J2: 10000 | K2: 12 | L2: 420 | M2: 15
A3: A | B3: 2 | C3: 95 P | D3: 45658 | E3: جیلانی پولی سٹاک | F3: PP | G3: 9X14 | H3: 5 | I3: 0 | J3: - | K3: 13 | L3: 325
A4: A | B4: 3 | C4: 106 P | D4: 45658 | E4: جیلانی پولی سٹاک | F4: PP | G4: 10X18 | H4: 5 | I4: 0 | J4: - | K4: 17 | L4: 425
A5: A | B5: 4 | C5: 37 P | D5: 45658 | E5: جیلانی پولی سٹاک | F5: PP | G5: 4X5 | H5: 5 | I5: 0 | J5: - | K5: 4 | L5: 100
A6: A | B6: 5 | C6: 6441/1 | D6: 45658 | E6: العمر پلاسٹک گوجرانوالہ | F6: PP | G6: 3X10 | H6: 5 | I6: 0 | J6: 500 | K6: 6 | L6: 150
A7: A | B7: 6 | C7: 6465/1 | D7: 45658 | E7: عثمان امین لاہور | F7: PP | G7: 2X6 | H7: 12 | I7: 0 | J7: 500 | K7: 12 | L7: 321
A8: A | B8: 2 | C8: 6306/1 | D8: 45659 | E8: عثمان امین لاہور | F8: PP | G8: 7X15 | H8: 0 | I8: 0 | J8: 10000 | K8: 13 | L8: 346 | M8: 10
A9: A | B9: 3 | C9: 646/2 | D9: 45659 | E9: - | F9: - | G9: - | H9: - | I9: - | J9: - | K9: 8 | L9: 242.1
A10: A | B10: 3 | C10: 6440/15 | D10: 45659 | E10: العمر پلاسٹک گوجرانوالہ | F10: PP | G10: 24X24 | H10: 10 | I10: 0 | J10: 125 | K10: 4 | L10: 130
A11: A | B11: 3 | C11: 124 P | D11: 45659 | E11: جیلانی پولی سٹاک | F11: PP | G11: 12X18 | H11: 5 | I11: 0 | J11: - | K11: 1 | L11: 25
A12: A | B12: 4 | C12: 95 P | D12: 45659 | E12: جیلانی پولی سٹاک | F12: PP | G12: 9X14 | H12: 5 | I12: 0 | J12: - | K12: 6 | L12: 150
A13: A | B13: 4 | C13: 94 P | D13: 45659 | E13: جیلانی پولی سٹاک | F13: PP | G13: 9X13 | H13: 5 | I13: 0 | J13: - | K13: 6 | L13: 150
A14: A | B14: 6 | C14: 103 P | D14: 45659 | E14: جیلانی پولی سٹاک | F14: PP | G14: 10X12 | H14: 5 | I14: 0 | J14: - | K14: 1 | L14: 25
A15: A | B15: 6 | C15: 6444/9 | D15: 45659 | E15: فضل سعید صادق آباد | F15: PP | G15: 10X30 | H15: 5 | I15: 0 | J15: 100 | K15: 5 | L15: 125
A16: A | B16: 6 | C16: 107 P | D16: 45659 | E16: جیلانی پولی سٹاک | F16: PP | G16: 10X20 | H16: 5 | I16: 0 | J16: - | K16: 5 | L16: 125
A17: A | B17: 6 | C17: 106 P | D17: 45659 | E17: جیلانی پولی سٹاک | F17: PP | G17: 10X18 | H17: 5 | I17: 0 | J17: - | K17: 3 | L17: 75
A18: A | B18: 5 | C18: 37 P | D18: 45659 | E18: جیلانی پولی سٹاک | F18: PP | G18: 4X5 | H18: 5 | I18: 0 | J18: - | K18: 7 | L18: 175
A19: A | B19: 5 | C19: 6441/1 | D19: 45659 | E19: العمر پلاسٹک گوجرانوالہ | F19: PP | G19: 3X10 | H19: 5 | I19: 0 | J19: 500 | K19: 9 | L19: 225
A20: A | B20: 2 | C20: 6306/1 | D20: 45660 | E20: عثمان امین لاہور | F20: PP | G20: 7X15 | H20: 0 | I20: 0 | J20: 10000 | K20: 4 | L20: 140 | M20: 15
A21: A | B21: 2 | C21: 83 P | D21: 45660 | E21: جیلانی پولی سٹاک | F21: PP | G21: 8X14 | H21: 5 | I21: 0 | J21: - | K21: 11 | L21: 275
A22: A | B22: 3 | C22: 122 P | D22: 45660 | E22: جیلانی پولی سٹاک | F22: PP | G22: 12X14 | H22: 5 | I22: 0 | J22: - | K22: 4 | L22: 100
A23: A | B23: 3 | C23: 124 P | D23: 45660 | E23: جیلانی پولی سٹاک | F23: PP | G23: 12X18 | H23: 5 | I23: 0 | J23: - | K23: 1 | L23: 25
A24: A | B24: 3 | C24: 114 P | D24: 45660 | E24: جیلانی پولی سٹاک | F24: PP | G24: 11X16 | H24: 5 | I24: 0 | J24: - | K24: 10 | L24: 250
A25: A | B25: 4 | C25: 94 P | D25: 45660 | E25: جیلانی پولی سٹاک | F25: PP | G25: 9X13 | H25: 5 | I25: 0 | J25: - | K25: 15 | L25: 375
A26: A | B26: 7 | C26: 103 P | D26: 45660 | E26: جیلانی پولی سٹاک | F26: PP | G26: 10X12 | H26: 5 | I26: 0 | J26: - | K26: 14 | L26: 350
A27: A | B27: 6 | C27: 34 P | D27: 45660 | E27: جیلانی پولی سٹاک | F27: PP | G27: 3X10 | H27: 5 | I27: 0 | J27: - | K27: 6 | L27: 150
A28: A | B28: 6 | C28: 31 P | D28: 45660 | E28: جیلانی پولی سٹاک | F28: PP | G28: 3X4 | H28: 5 | I28: 0 | J28: - | K28: 5 | L28: 125
A29: A | B29: 5 | C29: 37 P | D29: 45660 | E29: جیلانی پولی سٹاک | F29: PP | G29: 4X5 | H29: 5 | I29: 0 | J29: - | K29: 7 | L29: 175
A30: A | B30: 5 | C30: 6464/1 | D30: 45660 | E30: ارسلان پلاسٹک گوجراوالہ | F30: PP | G30: 2X7.5 | H30: 5 | I30: 0 | J30: 300 | K30: 2 | L30: 50
A31: A | B31: 3 | C31: 129 P | D31: 45661 | E31: جیلانی پولی سٹاک | F31: PP | G31: 12X28 | H31: 5 | I31: 0 | J31: - | K31: 10 | L31: 250 | M31: 15
A32: A | B32: 3 | C32: 114 P | D32: 45661 | E32: جیلانی پولی سٹاک | F32: PP | G32: 11X16 | H32: 5 | I32: 0 | J32: - | K32: 2 | L32: 50
A33: A | B33: 3 | C33: 123 P | D33: 45661 | E33: جیلانی پولی سٹاک | F33: PP | G33: 12X16 | H33: 5 | I33: 0 | J33: - | K33: 1 | L33: 25
A34: A | B34: 7 | C34: 103 P | D34: 45661 | E34: جیلانی پولی سٹاک | F34: PP | G34: 10X12 | H34: 5 | I34: 0 | J34: - | K34: 1 | L34: 25
A35: A | B35: 7 | C35: 105 P | D35: 45661 | E35: جیلانی پولی سٹاک | F35: PP | G35: 10X16 | H35: 5 | I35: 0 | J35: - | K35: 6 | L35: 150
A36: A | B36: 7 | C36: 6477/11 | D36: 45661 | E36: حنان پلاسٹک فیصل آباد | F36: PP | G36: 10X23 | H36: 5 | I36: 0 | J36: 125 | K36: 5 | L36: 125
A37: A | B37: 4 | C37: 96 P | D37: 45661 | E37: جیلانی پولی سٹاک | F37: PP | G37: 9X16 | H37: 5 | I37: 0 | J37: - | K37: 12 | L37: 300
A38: A | B38: 4 | C38: 94 P | D38: 45661 | E38: جیلانی پولی سٹاک | F38: PP | G38: 9X13 | H38: 5 | I38: 0 | J38: - | K38: 1 | L38: 25
A39: A | B39: 2 | C39: 80 P | D39: 45661 | E39: جیلانی پولی سٹاک | F39: PP | G39: 8X10 | H39: 5 | I39: 0 | J39: - | K39: 8 | L39: 200
A40: A | B40: 2 | C40: 83 P | D40: 45661 | E40: جیلانی پولی سٹاک | F40: PP | G40: 8X14 | H40: 5 | I40: 0 | J40: - | K40: 10 | L40: 250
...

Sheet PP BOTTOM SEAL JOB CARD
A1: DATE | B1: SO | C1: PARTY NAME | D1: SIZE | E1: GUAGE | F1: QUALITY | G1: ORDER WT | H1: PAPER PRO | I1: BAGS | J1: CARD PRO | K1: DIFF
A2: 45892 | B2: 7170/1 | C2: {=VLOOKUP(B2,'PP BOTTOM SEAL'!C:N,{3,5,6,4,8},0)} -> بلال ازعظم مال کینٹ | D2: 12X30 | E2: 8 | F2: PP | G2: 50 | H2: =SUMIFS('PP BOTTOM SEAL'!L:L,'PP BOTTOM SEAL'!C:C,'PP BOTTOM SEAL JOB CARD'!B2) -> 64.7 | J2: =50+14.7 -> 64.7 | K2: =+H2-J2 -> 0
A3: 45892 | B3: 7199/2 | C3: {=VLOOKUP(B3,'PP BOTTOM SEAL'!C:N,{3,5,6,4,8},0)} -> العمر پلاسٹک گوجرانوالہ | D3: 14X16 | E3: 6 | F3: PP | G3: 100 | H3: =SUMIFS('PP BOTTOM SEAL'!L:L,'PP BOTTOM SEAL'!C:C,'PP BOTTOM SEAL JOB CARD'!B3) -> 97.1 | J3: =75+22.1 -> 97.1 | K3: =+H3-J3 -> 0
A4: 45892 | B4: 7183/1 | C4: {=VLOOKUP(B4,'PP BOTTOM SEAL'!C:N,{3,5,6,4,8},0)} -> ریفلیکٹ پیک لاہور | D4: 14X15 | E4: 5-5.5 | F4: PP | G4: 500 | H4: =SUMIFS('PP BOTTOM SEAL'!L:L,'PP BOTTOM SEAL'!C:C,'PP BOTTOM SEAL JOB CARD'!B4) -> 503.2 | J4: =25*19+28.2 -> 503.2 | K4: =+H4-J4 -> 0
A5: 45888 | B5: 7188/4 | C5: {=VLOOKUP(B5,'PP BOTTOM SEAL'!C:N,{3,5,6,4,8},0)} -> ارشد افضل حاصلپور | D5: 11X16 | E5: 5 | F5: PP | G5: 100 | H5: =SUMIFS('PP BOTTOM SEAL'!L:L,'PP BOTTOM SEAL'!C:C,'PP BOTTOM SEAL JOB CARD'!B5) -> 425 | J5: =25*4+25*13 -> 425 | K5: =+H5-J5 -> 0
A6: 45888 | B6: 7189/3 | C6: {=VLOOKUP(B6,'PP BOTTOM SEAL'!C:N,{3,5,6,4,8},0)} -> محبوب مقبول گوجرانوالہ | D6: 04X12 | E6: 5 | F6: PP | G6: 250 | H6: =SUMIFS('PP BOTTOM SEAL'!L:L,'PP BOTTOM SEAL'!C:C,'PP BOTTOM SEAL JOB CARD'!B6) -> 240 | J6: =20*12 -> 240 | K6: =+H6-J6 -> 0
A7: 45895 | B7: 7196/1 | C7: {=VLOOKUP(B7,'PP BOTTOM SEAL'!C:N,{3,5,6,4,8},0)} -> عظیم ٹوائز لاہور | D7: 05.50X12 | E7: 10 | F7: PP | G7: 50 | H7: =SUMIFS('PP BOTTOM SEAL'!L:L,'PP BOTTOM SEAL'!C:C,'PP BOTTOM SEAL JOB CARD'!B7) -> 48.3 | J7: =25+23.3 -> 48.3 | K7: =+H7-J7 -> 0
A8: 45895 | B8: 7196/2 | C8: {=VLOOKUP(B8,'PP BOTTOM SEAL'!C:N,{3,5,6,4,8},0)} -> عظیم ٹوائز لاہور | D8: 05.50X13 | E8: 10 | F8: PP | G8: 50 | H8: =SUMIFS('PP BOTTOM SEAL'!L:L,'PP BOTTOM SEAL'!C:C,'PP BOTTOM SEAL JOB CARD'!B8) -> 50 | J8: 50 | K8: =+H8-J8 -> 0
A9: 45896 | B9: 7203/9 | C9: {=VLOOKUP(B9,'PP BOTTOM SEAL'!C:N,{3,5,6,4,8},0)} -> فضل سعید صادق اباد | D9: 09X16 | E9: 5 | F9: PP | G9: 50 | H9: =SUMIFS('PP BOTTOM SEAL'!L:L,'PP BOTTOM SEAL'!C:C,'PP BOTTOM SEAL JOB CARD'!B9) -> 50 | J9: 50 | K9: =+H9-J9 -> 0
A10: 45896 | B10: 116p/1 | C10: {=VLOOKUP(B10,'PP BOTTOM SEAL'!C:N,{3,5,6,4,8},0)} -> - | D10: 0 | E10: 0 | F10: 0 | G10: 0 | H10: =SUMIFS('PP BOTTOM SEAL'!L:L,'PP BOTTOM SEAL'!C:C,'PP BOTTOM SEAL JOB CARD'!B10) -> 250 | J10: 250 | K10: =+H10-J10 -> 0
A11: 45896 | B11: 7160/2 | C11: {=VLOOKUP(B11,'PP BOTTOM SEAL'!C:N,{3,5,6,4,8},0)} -> ایم دین پنڈی | D11: 18X24 | E11: 6-6.5 | F11: PP | G11: 600 | H11: =SUMIFS('PP BOTTOM SEAL'!L:L,'PP BOTTOM SEAL'!C:C,'PP BOTTOM SEAL JOB CARD'!B11) -> 559.4 | J11: =30*4+30*7+30*7+19.4 -> 559.4 | K11: =+H11-J11 -> 0
A12: 45896 | B12: 7217/7 | C12: {=VLOOKUP(B12,'PP BOTTOM SEAL'!C:N,{3,5,6,4,8},0)} -> نادر پلاسٹک سرگودھا | D12: 18X30 | E12: 5 | F12: PP | G12: 25 | H12: =SUMIFS('PP BOTTOM SEAL'!L:L,'PP BOTTOM SEAL'!C:C,'PP BOTTOM SEAL JOB CARD'!B12) -> 75 | J12: 25 | K12: =+H12-J12 -> 50
A13: 45897 | B13: 7202/1 | C13: {=VLOOKUP(B13,'PP BOTTOM SEAL'!C:N,{3,5,6,4,8},0)} -> ہیڈ افس سٹاک لاہور | D13: 06X08 | E13: 5 | F13: PP | G13: 125 | H13: =SUMIFS('PP BOTTOM SEAL'!L:L,'PP BOTTOM SEAL'!C:C,'PP BOTTOM SEAL JOB CARD'!B13) -> 125 | I13: 5 | J13: 125 | K13: =+H13-J13 -> 0
A14: 45897 | B14: 7205/3 | C14: {=VLOOKUP(B14,'PP BOTTOM SEAL'!C:N,{3,5,6,4,8},0)} -> محبوب مقبول گوجرانوالہ | D14: 06X08 | E14: 5 | F14: PP | G14: 125 | H14: =SUMIFS('PP BOTTOM SEAL'!L:L,'PP BOTTOM SEAL'!C:C,'PP BOTTOM SEAL JOB CARD'!B14) -> 125 | I14: 5 | J14: 125 | K14: =+H14-J14 -> 0
A15: 45897 | B15: 7205/4 | C15: {=VLOOKUP(B15,'PP BOTTOM SEAL'!C:N,{3,5,6,4,8},0)} -> محبوب مقبول گوجرانوالہ | D15: 12X14 | E15: 5 | F15: PP | G15: 125 | H15: =SUMIFS('PP BOTTOM SEAL'!L:L,'PP BOTTOM SEAL'!C:C,'PP BOTTOM SEAL JOB CARD'!B15) -> 175 | I15: 5 | J15: 125 | K15: =+H15-J15 -> 50
A16: 45897 | B16: 7203/6 | C16: {=VLOOKUP(B16,'PP BOTTOM SEAL'!C:N,{3,5,6,4,8},0)} -> فضل سعید صادق اباد | D16: 07X14 | E16: 5 | F16: PP | G16: 150 | H16: =SUMIFS('PP BOTTOM SEAL'!L:L,'PP BOTTOM SEAL'!C:C,'PP BOTTOM SEAL JOB CARD'!B16) -> 150 | I16: 6 | J16: =25*I16 -> 150 | K16: =+H16-J16 -> 0
A17: 45897 | B17: 7203/7 | C17: {=VLOOKUP(B17,'PP BOTTOM SEAL'!C:N,{3,5,6,4,8},0)} -> فضل سعید صادق اباد | D17: 08X12 | E17: 5 | F17: PP | G17: 300 | H17: =SUMIFS('PP BOTTOM SEAL'!L:L,'PP BOTTOM SEAL'!C:C,'PP BOTTOM SEAL JOB CARD'!B17) -> 350 | I17: 14 | J17: =25*I17 -> 350 | K17: =+H17-J17 -> 0
A18: 45897 | B18: 7203/13 | C18: {=VLOOKUP(B18,'PP BOTTOM SEAL'!C:N,{3,5,6,4,8},0)} -> فضل سعید صادق اباد | D18: 10X30 | E18: 5 | F18: PP | G18: 75 | H18: =SUMIFS('PP BOTTOM SEAL'!L:L,'PP BOTTOM SEAL'!C:C,'PP BOTTOM SEAL JOB CARD'!B18) -> 75 | I18: 3 | J18: =25*I18 -> 75 | K18: =+H18-J18 -> 0
A19: 45897 | B19: 7203/18 | C19: {=VLOOKUP(B19,'PP BOTTOM SEAL'!C:N,{3,5,6,4,8},0)} -> فضل سعید صادق اباد | D19: 12X24 | E19: 5 | F19: PP | G19: 50 | H19: =SUMIFS('PP BOTTOM SEAL'!L:L,'PP BOTTOM SEAL'!C:C,'PP BOTTOM SEAL JOB CARD'!B19) -> 50 | I19: 2 | J19: =25*I19 -> 50 | K19: =+H19-J19 -> 0
A20: 45898 | B20: 46P/1 | C20: {=VLOOKUP(B20,'PP BOTTOM SEAL'!C:N,{3,5,6,4,8},0)} -> - | D20: 0 | E20: 0 | F20: 0 | G20: 0 | H20: =SUMIFS('PP BOTTOM SEAL'!L:L,'PP BOTTOM SEAL'!C:C,'PP BOTTOM SEAL JOB CARD'!B20) -> 200 | I20: 8 | J20: =25*I20 -> 200 | K20: =+H20-J20 -> 0
A21: 45898 | B21: 7176/13 | C21: {=VLOOKUP(B21,'PP BOTTOM SEAL'!C:N,{3,5,6,4,8},0)} -> حاجی اسلماعیل وہاڑی | D21: 02.50X03.50 | E21: 5 | F21: PP | G21: 150 | H21: =SUMIFS('PP BOTTOM SEAL'!L:L,'PP BOTTOM SEAL'!C:C,'PP BOTTOM SEAL JOB CARD'!B21) -> 120 | I21: 6 | J21: =20*I21 -> 120 | K21: =+H21-J21 -> 0
A22: 45898 | B22: 30 P | C22: {=VLOOKUP(B22,'PP BOTTOM SEAL'!C:N,{3,5,6,4,8},0)} -> جیلانی پولی سٹاک | D22: 2.5X3.5 | E22: 5 | F22: PP | G22: - | H22: =SUMIFS('PP BOTTOM SEAL'!L:L,'PP BOTTOM SEAL'!C:C,'PP BOTTOM SEAL JOB CARD'!B22) -> 4310 | I22: =3+9+11+8 -> 31 | J22: =20*I22 -> 620 | K22: =+H22-J22 -> 3690
A23: 45898 | B23: 7197/7 | C23: {=VLOOKUP(B23,'PP BOTTOM SEAL'!C:N,{3,5,6,4,8},0)} -> نادر پلاسٹک سرگودھا | D23: 10X22 | E23: 5 | F23: PP | G23: 50 | H23: =SUMIFS('PP BOTTOM SEAL'!L:L,'PP BOTTOM SEAL'!C:C,'PP BOTTOM SEAL JOB CARD'!B23) -> 50 | I23: 2 | J23: =25*I23 -> 50 | K23: =+H23-J23 -> 0
A24: 45898 | B24: 7202/3 | C24: {=VLOOKUP(B24,'PP BOTTOM SEAL'!C:N,{3,5,6,4,8},0)} -> ہیڈ افس سٹاک لاہور | D24: 07X11 | E24: 5 | F24: PP | G24: 250 | H24: =SUMIFS('PP BOTTOM SEAL'!L:L,'PP BOTTOM SEAL'!C:C,'PP BOTTOM SEAL JOB CARD'!B24) -> 250 | I24: 10 | J24: =25*I24 -> 250 | K24: =+H24-J24 -> 0
A25: 45898 | B25: 7202/9 | C25: {=VLOOKUP(B25,'PP BOTTOM SEAL'!C:N,{3,5,6,4,8},0)} -> ہیڈ افس سٹاک لاہور | D25: 14X26 | E25: 5 | F25: PP | G25: 100 | H25: =SUMIFS('PP BOTTOM SEAL'!L:L,'PP BOTTOM SEAL'!C:C,'PP BOTTOM SEAL JOB CARD'!B25) -> 100 | I25: 4 | J25: =25*I25 -> 100 | K25: =+H25-J25 -> 0
A26: 45900 | B26: 512/2 | C26: {=VLOOKUP(B26,'PP BOTTOM SEAL'!C:N,{3,5,6,4,8},0)} -> سٹاک | D26: 5X12 | E26: 5 | F26: PP | G26: 250 | H26: =SUMIFS('PP BOTTOM SEAL'!L:L,'PP BOTTOM SEAL'!C:C,'PP BOTTOM SEAL JOB CARD'!B26) -> 300 | I26: 12 | J26: =25*I26 -> 300 | K26: =+H26-J26 -> 0
A27: 45900 | B27: 6861/3 | C27: {=VLOOKUP(B27,'PP BOTTOM SEAL'!C:N,{3,5,6,4,8},0)} -> عثمان امین لاہور | D27: 4X8 | E27: 5 | F27: PP | G27: 2000 | H27: =SUMIFS('PP BOTTOM SEAL'!L:L,'PP BOTTOM SEAL'!C:C,'PP BOTTOM SEAL JOB CARD'!B27) -> 1295 | I27: 10 | J27: =25*I27 -> 250 | K27: =+H27-J27 -> 1045
A28: 45900 | B28: 1418/1 | C28: {=VLOOKUP(B28,'PP BOTTOM SEAL'!C:N,{3,5,6,4,8},0)} -> سٹاک | D28: 14X18 | E28: 5 | F28: PP | G28: 500 | H28: =SUMIFS('PP BOTTOM SEAL'!L:L,'PP BOTTOM SEAL'!C:C,'PP BOTTOM SEAL JOB CARD'!B28) -> 350 | I28: 10 | J28: =25*I28 -> 250 | K28: =+H28-J28 -> 100
A29: 45900 | B29: 7191/5 | C29: {=VLOOKUP(B29,'PP BOTTOM SEAL'!C:N,{3,5,6,4,8},0)} -> العمر پلاسٹک گوجرانوالہ | D29: 22X22 | E29: 6 | F29: PP | G29: 250 | H29: =SUMIFS('PP BOTTOM SEAL'!L:L,'PP BOTTOM SEAL'!C:C,'PP BOTTOM SEAL JOB CARD'!B29) -> 251.3 | I29: 10 | J29: =25*9+26.3 -> 251.3 | K29: =+H29-J29 -> 0
A30: 45900 | B30: 7191/1 | C30: {=VLOOKUP(B30,'PP BOTTOM SEAL'!C:N,{3,5,6,4,8},0)} -> العمر پلاسٹک گوجرانوالہ | D30: 14X14 | E30: 10 | F30: PP | G30: 250 | H30: =SUMIFS('PP BOTTOM SEAL'!L:L,'PP BOTTOM SEAL'!C:C,'PP BOTTOM SEAL JOB CARD'!B30) -> 249 | I30: 10 | J30: =25*9+24 -> 249 | K30: =+H30-J30 -> 0
A31: 45900 | B31: 7191/3 | C31: {=VLOOKUP(B31,'PP BOTTOM SEAL'!C:N,{3,5,6,4,8},0)} -> العمر پلاسٹک گوجرانوالہ | D31: 18X18 | E31: 6 | F31: PP | G31: 250 | H31: =SUMIFS('PP BOTTOM SEAL'!L:L,'PP BOTTOM SEAL'!C:C,'PP BOTTOM SEAL JOB CARD'!B31) -> 250 | I31: 10 | J31: =25*I31 -> 250 | K31: =+H31-J31 -> 0
A32: 45900 | B32: 714/1 | C32: {=VLOOKUP(B32,'PP BOTTOM SEAL'!C:N,{3,5,6,4,8},0)} -> سٹاک | D32: 7X14 | E32: 5 | F32: PP | G32: 375 | H32: =SUMIFS('PP BOTTOM SEAL'!L:L,'PP BOTTOM SEAL'!C:C,'PP BOTTOM SEAL JOB CARD'!B32) -> 175 | I32: 4 | J32: =25*I32 -> 100 | K32: =+H32-J32 -> 75
A33: 45900 | B33: 711/1 | C33: {=VLOOKUP(B33,'PP BOTTOM SEAL'!C:N,{3,5,6,4,8},0)} -> سٹاک | D33: 7X11 | E33: 5 | F33: PP | G33: 250 | H33: =SUMIFS('PP BOTTOM SEAL'!L:L,'PP BOTTOM SEAL'!C:C,'PP BOTTOM SEAL JOB CARD'!B33) -> 250 | I33: 10 | J33: =25*I33 -> 250 | K33: =+H33-J33 -> 0
A34: 45900 | B34: 40P/1 | C34: {=VLOOKUP(B34,'PP BOTTOM SEAL'!C:N,{3,5,6,4,8},0)} -> - | D34: 0 | E34: 0 | F34: 0 | G34: 0 | H34: =SUMIFS('PP BOTTOM SEAL'!L:L,'PP BOTTOM SEAL'!C:C,'PP BOTTOM SEAL JOB CARD'!B34) -> 200 | I34: 10 | J34: =25*I34 -> 250 | K34: =+H34-J34 -> -50
A35: 45900 | B35: 7199/1 | C35: {=VLOOKUP(B35,'PP BOTTOM SEAL'!C:N,{3,5,6,4,8},0)} -> العمر پلاسٹک گوجرانوالہ | D35: 18X16 | E35: 6 | F35: PP | G35: 150 | H35: =SUMIFS('PP BOTTOM SEAL'!L:L,'PP BOTTOM SEAL'!C:C,'PP BOTTOM SEAL JOB CARD'!B35) -> 94.6 | I35: =2+1+1 -> 4 | J35: =75+19.6 -> 94.6 | K35: =+H35-J35 -> 0
A36: 45900 | B36: 23/1 | C36: {=VLOOKUP(B36,'PP BOTTOM SEAL'!C:N,{3,5,6,4,8},0)} -> سٹاک | D36: 2X3 | E36: 5.5-6 | F36: PP | G36: 375 | H36: =SUMIFS('PP BOTTOM SEAL'!L:L,'PP BOTTOM SEAL'!C:C,'PP BOTTOM SEAL JOB CARD'!B36) -> 320 | I36: =9+6 -> 15 | J36: =20*I36 -> 300 | K36: =+H36-J36 -> 20
A37: 45900 | B37: 3917 J | C37: {=VLOOKUP(B37,'PP BOTTOM SEAL'!C:N,{3,5,6,4,8},0)} -> Cakes and Bakes Lahore | D37: 16X22 | E37: 5.5-6 | F37: PP | G37: 250 | H37: =SUMIFS('PP BOTTOM SEAL'!L:L,'PP BOTTOM SEAL'!C:C,'PP BOTTOM SEAL JOB CARD'!B37) -> 225 | I37: 9 | J37: =25*I37 -> 225 | K37: =+H37-J37 -> 0
A38: 45904 | B38: 7228/1 | C38: {=VLOOKUP(B38,'PP BOTTOM SEAL'!C:N,{3,5,6,4,8},0)} -> بلال سویاں سرگودھا | D38: 04X18 | E38: 5 | F38: PP | G38: 300 | H38: =SUMIFS('PP BOTTOM SEAL'!L:L,'PP BOTTOM SEAL'!C:C,'PP BOTTOM SEAL JOB CARD'!B38) -> 320 | I38: =13+3 -> 16 | J38: =20*I38 -> 320 | K38: =+H38-J38 -> 0
A39: 45904 | B39: 7225/15 | C39: {=VLOOKUP(B39,'PP BOTTOM SEAL'!C:N,{3,5,6,4,8},0)} -> محبوب مقبول گوجرانوالہ | D39: 02X18 | E39: 5 | F39: PP | G39: 200 | H39: =SUMIFS('PP BOTTOM SEAL'!L:L,'PP BOTTOM SEAL'!C:C,'PP BOTTOM SEAL JOB CARD'!B39) -> 140 | I39: 7 | J39: =20*I39 -> 140 | K39: =+H39-J39 -> 0
A40: 45904 | B40: 7193/1 | C40: {=VLOOKUP(B40,'PP BOTTOM SEAL'!C:N,{3,5,6,4,8},0)} -> محبوب مقبول گوجرانوالہ | D40: 13X22 | E40: 5 | F40: PP | G40: 100 | H40: =SUMIFS('PP BOTTOM SEAL'!L:L,'PP BOTTOM SEAL'!C:C,'PP BOTTOM SEAL JOB CARD'!B40) -> 225 | I40: 9 | J40: =25*I40 -> 225 | K40: =+H40-J40 -> 0
...

Sheet LD DISPATCH
A1: SO | B1: DATE | C1: JOB NAME | D1: MTRL | E1: SIZE | F1: GUAGE | G1: QUALITY | H1: ORDER WEIGHT | I1: SECTION | J1: TRF # | K1: NO OF ROLLS | L1: G. WEIGHT | M1: CORE WEIGHT | N1: NET WEIGHT | O1: Column15
A2: LDM | B2: 45678 | C2: جیلانی پولی سٹاک | D2: LDM | E2: 5 | F2: 9 | G2: - | H2: - | I2: SALE | J2: 932 | K2: 8 | L2: 215 | M2: 5.6 | N2: 209.4
A3: LDN | B3: 45678 | C3: جیلانی پولی سٹاک | D3: LDN | E3: 7 | F3: 14 | G3: - | H3: - | I3: SALE | J3: 933 | K3: 14 | L3: 496.63 | M3: 11.2 | N3: 485.43
A4: LDN | B4: 45678 | C4: جیلانی پولی سٹاک | D4: LDN | E4: 20 | F4: 18 | G4: - | H4: - | I4: SALE | J4: 933 | K4: 3 | L4: 222.6 | M4: 8.7 | N4: 213.9
A5: 17725/1 | B5: 45695 | C5: جیلانی پولی سٹاک | D5: LDN | E5: 30 | F5: 9 | G5: - | H5: - | I5: SALE | J5: 1090 | K5: 20 | L5: 505.6 | M5: 32 | N5: 473.6
A6: LD | B6: 45695 | C6: جیلانی پولی سٹاک | D6: LD | E6: 8 | F6: 12 | I6: SALE | J6: 1092 | K6: 5 | L6: 134.6 | M6: 4.5 | N6: 130.1
A7: LD | B7: 45695 | C7: جیلانی پولی سٹاک | D7: LD | E7: 9 | F7: 12 | I7: SALE | J7: 1092 | K7: 3 | L7: 136.4 | M7: 3.3 | N7: 133.1
A8: LD | B8: 45695 | C8: جیلانی پولی سٹاک | D8: LD | E8: 8 | F8: 10 | I8: SALE | J8: 1092 | K8: 4 | L8: 106.5 | M8: 4 | N8: 102.5
A9: 5313/1 | B9: 45703 | C9: جیلانی پولی سٹاک | D9: LDN | E9: 36 | F9: 8 | G9: SUPER JILANI | I9: SALE | J9: 976 | K9: 8 | L9: 211.8 | M9: 17.6 | N9: 194.2
A10: LDN | B10: 45707 | C10: جیلانی پولی سٹاک | D10: LDN | E10: 9X13 | F10: 18 | I10: SALE | J10: 979 | K10: 14 | L10: 502.6 | N10: 502.6
A11: LDN | B11: 45707 | C11: جیلانی پولی سٹاک | D11: LDN | E11: 12X18 | F11: 14 | I11: SALE | J11: 979 | K11: 9 | L11: 428.21 | N11: 428.21
A12: LDN | B12: 45707 | C12: جیلانی پولی سٹاک | D12: LDN | E12: 39X62 | F12: 35-36 | I12: SALE | J12: 980 | K12: 3 | L12: 224.6 | N12: 224.6
A13: LDN | B13: 45707 | C13: جیلانی پولی سٹاک | D13: LDN | E13: 7X11 | I13: SALE | J13: 980 | K13: 3 | L13: 110.1 | N13: 110.1
A14: LD BLUE | B14: 45717 | C14: جیلانی پولی سٹاک | D14: LDN | E14: 40 | F14: 10 | I14: SALE | J14: 1144 | K14: 24 | L14: 573.46 | N14: 573.46
A15: LD | B15: 45717 | C15: جیلانی پولی سٹاک | D15: LDN | E15: 20 | F15: 18 | I15: SALE | J15: 1145 | K15: 1 | L15: 115.8 | N15: 115.8
A16: LD | B16: 45717 | C16: جیلانی پولی سٹاک | D16: LDN | E16: 7 | F16: 18 | I16: SALE | J16: 1145 | K16: 1 | L16: 20.5 | N16: 20.5
A17: LD | B17: 45717 | C17: جیلانی پولی سٹاک | D17: LDN | E17: 28 | F17: 4 | I17: SALE | J17: 1145 | K17: 8 | L17: 232.4 | N17: 232.4
A18: 1660/1 | B18: 45722 | C18: جیلانی پولی سٹاک | D18: LDN | E18: 24 | F18: 7.75-7.75 | I18: SALE | J18: 1024 | K18: 7 | L18: 390.6 | N18: 390.6
B19: 45758 | C19: جیلانی پولی سٹاک | D19: LDN | E19: 30 | F19: 10 | I19: SALE | J19: 1158 | K19: 7 | L19: 542.8 | N19: 542.8
B20: 45758 | C20: جیلانی پولی سٹاک | D20: LDN | E20: 9 | F20: 18 | I20: SALE | J20: 1160 | K20: 3 | L20: 130.4 | N20: 130.4
B21: 45758 | C21: جیلانی پولی سٹاک | D21: LDN | E21: 7 | F21: 18 | I21: SALE | J21: 1161 | K21: 11 | L21: 479.8 | N21: 479.8
B22: 45763 | C22: جیلانی پولی سٹاک | D22: LDN | E22: 5 | F22: 18 | I22: SALE | J22: 1174 | K22: 4 | L22: 127.2 | N22: 127.2
B23: 45763 | C23: جیلانی پولی سٹاک | D23: LDN | E23: 6 | F23: 18 | I23: SALE | J23: 1174 | K23: 2 | L23: 68.8 | N23: 68.8
B24: 45766 | C24: جیلانی پولی سٹاک | D24: LDN | I24: SALE | J24: 1214 | K24: 28 | L24: 1135 | N24: 1135
B25: 45768 | C25: جیلانی پولی سٹاک | D25: LDN | I25: SALE | J25: 1215 | K25: 28 | L25: 1135 | N25: 1135
B26: 45769 | C26: جیلانی پولی سٹاک | D26: LDM | E26: 18 | F26: 6 | I26: SALE | J26: 1226 | K26: 20 | L26: 347.79 | N26: 347.79
B27: 45769 | C27: جیلانی پولی سٹاک | D27: LDM | E27: 12 | F27: 5.6 | I27: SALE | J27: 1227 | K27: 7 | L27: 174.25 | N27: 174.25
B28: 45769 | C28: جیلانی پولی سٹاک | D28: LDM | E28: 18 | F28: 14 | I28: SALE | J28: 1228 | K28: 2 | L28: 154.8 | N28: 154.8
B29: 45769 | C29: جیلانی پولی سٹاک | D29: LDM | E29: 14 | F29: 12 | I29: SALE | J29: 1228 | K29: 2 | L29: 71.85 | N29: 71.85
B30: 45769 | C30: جیلانی پولی سٹاک | D30: LDM | E30: 19 | F30: 6.5 | I30: SALE | J30: 1228 | K30: 2 | L30: 66.5 | N30: 66.5
B31: 45769 | C31: جیلانی پولی سٹاک | D31: LDM | E31: 10 | F31: 6 | I31: SALE | J31: 1228 | K31: 1 | L31: 29.7 | N31: 29.7
B32: 45769 | C32: جیلانی پولی سٹاک | D32: LDM | E32: 36 | F32: 6 | I32: SALE | J32: 1228 | K32: 2 | L32: 41.06 | N32: 41.06
B33: 45769 | C33: جیلانی پولی سٹاک | D33: LDM | E33: 12 | F33: 6 | I33: SALE | J33: 1228 | K33: 1 | L33: 2.5 | N33: 2.5
B34: 45769 | C34: جیلانی پولی سٹاک | D34: LDM | E34: 5 | F34: 5.5-6 | I34: SALE | J34: 1229 | K34: 1 | L34: 36.3 | N34: 36.3
B35: 45769 | C35: جیلانی پولی سٹاک | D35: LDN | E35: 6 | I35: SALE | J35: 1238 | K35: 2 | L35: 38.68 | N35: 38.68
B36: 45769 | C36: جیلانی پولی سٹاک | D36: LDN | E36: 10 | I36: SALE | J36: 1238 | K36: 3 | L36: 106.8 | N36: 106.8
B37: 45769 | C37: جیلانی پولی سٹاک | D37: LDN | E37: 18 | I37: SALE | J37: 1238 | K37: 7 | L37: 319.21 | N37: 319.21
B38: 45769 | C38: جیلانی پولی سٹاک | D38: LDN | E38: 26 | I38: SALE | J38: 1238 | K38: 5 | L38: 173.17 | N38: 173.17
B39: 45769 | C39: جیلانی پولی سٹاک | D39: LDN | E39: 30 | I39: SALE | J39: 1238 | K39: 3 | L39: 216.23 | N39: 216.23
B40: 45769 | C40: جیلانی پولی سٹاک | D40: LDN | E40: 22 | I40: SALE | J40: 1238 | K40: 5 | L40: 124.14 | N40: 124.14
...

Sheet Sheet2
A1: DATE | B1: SO | C1: PARTY NAME | D1: SIZE | E1: GUAGE | F1: QUALITY | G1: ORDER WT | H1: PAPER PRO | I1: LD DISPATCH | J1: ROLL | K1: CARD PRO | L1: CORE WT | N1: DIFF
