Workbook
Name Slicer_WEEK_NO.: #N/A

Sheet PP
L1: DAILY OPERATION REVIEW FLEXO PRINTING
A2: DATE | B2: SHIFT | C2: MACHINES | D2: سائز تبدیل | E2: کوالٹی CHANGE | F2: ھیٹنگ | I2: TOTAL MIN | J2: P.S HOURS | K2: الیکٹریکل | L2: ڈایی صاف | M2: مکینیکل | N2: سائز کم | O2: سیمپل چیک | P2: مال میں مسئلہ | Q2: جالی تبدیل | R2: MC OFF | S2: TOTAL MIN | T2: U.P.S HOURS | U2: T.S HOURS | V2: RUNNING | W2: TOTAL HOURS | X2: WASTAGE/KGs | Y2: KWH/KG | Z2: TOTAL PRODUCTION | AA2: TARGET | AB2: RECIPE | AC2: WEEK NO. | AD2: REMARKS | AE2: ACTION | AF2: ACTION PLAN
A3: 45658 | B3: A | C3: 1 | I3: 0 | J3: 0 | S3: 0 | T3: 0 | U3: 0 | V3: 12 | W3: 12 | X3: 54.5 | Y3: 2020 | Z3: 128.83 | AA3: 146 | AB3: 398 | AC3: 1
A4: 45658 | B4: B | C4: 1 | I4: 0 | J4: 0 | S4: 0 | T4: 0 | U4: 0 | V4: 12 | W4: 12 | X4: 54.5 | Z4: 35.75 | AA4: 146 | AC4: 1
A5: 45658 | B5: A | C5: 2 | I5: 0 | J5: 0 | S5: 0 | T5: 0 | U5: 0 | V5: 12 | W5: 12 | X5: 0 | Z5: 63.01 | AA5: 58 | AC5: 1
A6: 45658 | B6: B | C6: 2 | I6: 0 | J6: 0 | S6: 0 | T6: 0 | U6: 0 | V6: 12 | W6: 12 | X6: 0 | Z6: 18.45 | AA6: 58 | AC6: 1
A7: 45658 | B7: A | C7: 3 | I7: 0 | J7: 0 | S7: 0 | T7: 0 | U7: 0 | V7: 12 | W7: 12 | X7: 0 | Z7: 305.65 | AA7: 239 | AC7: 1
A8: 45658 | B8: B | C8: 3 | D8: 25 | I8: 25 | J8: 0.41666667 | S8: 0 | T8: 0 | U8: 0.41666667 | V8: 11.583333 | W8: 12 | X8: 0 | Z8: 255.63 | AA8: 239 | AC8: 1
A9: 45658 | B9: A | C9: 4 | I9: 0 | J9: 0 | S9: 0 | T9: 0 | U9: 0 | V9: 12 | W9: 12 | X9: 0 | Z9: 802.27 | AA9: 797 | AC9: 1
A10: 45658 | B10: B | C10: 4 | I10: 0 | J10: 0 | S10: 0 | T10: 0 | U10: 0 | V10: 12 | W10: 12 | X10: 0 | Z10: 770.81 | AA10: 797 | AC10: 1
A11: 45658 | B11: A | C11: 5 | I11: 0 | J11: 0 | S11: 0 | T11: 0 | U11: 0 | V11: 12 | W11: 12 | X11: 0 | Z11: 617.66 | AA11: 379 | AC11: 1
A12: 45658 | B12: B | C12: 5 | D12: 30 | I12: 30 | J12: 0.5 | S12: 0 | T12: 0 | U12: 0.5 | V12: 11.5 | W12: 12 | X12: 0 | Z12: 567.66 | AA12: 379 | AC12: 1
A13: 45658 | B13: A | C13: 6 | I13: 0 | J13: 0 | S13: 0 | T13: 0 | U13: 0 | V13: 0 | X13: 0 | Z13: 0 | AC13: 1
A14: 45658 | B14: B | C14: 6 | I14: 0 | J14: 0 | S14: 0 | T14: 0 | U14: 0 | V14: 0 | X14: 0 | Z14: 0 | AC14: 1
A15: 45659 | B15: A | C15: 1 | I15: 0 | J15: 0 | K15: 120 | S15: 120 | T15: 2 | U15: 2 | V15: 10 | W15: 12 | X15: 22 | Y15: 2001 | Z15: 130.88 | AA15: 146 | AB15: 398 | AC15: 1
A16: 45659 | B16: B | C16: 1 | I16: 0 | J16: 0 | S16: 0 | T16: 0 | U16: 0 | V16: 12 | W16: 12 | X16: 30 | Z16: 118.84 | AA16: 146 | AC16: 1
A17: 45659 | B17: A | C17: 2 | I17: 0 | J17: 0 | P17: 60 | S17: 60 | T17: 1 | U17: 1 | V17: 11 | W17: 12 | X17: 0 | Z17: 86.37 | AA17: 58 | AC17: 1
A18: 45659 | B18: B | C18: 2 | I18: 0 | J18: 0 | S18: 0 | T18: 0 | U18: 0 | V18: 12 | W18: 12 | X18: 0 | Z18: 72.39 | AA18: 58 | AC18: 1
A19: 45659 | B19: A | C19: 3 | I19: 0 | J19: 0 | S19: 0 | T19: 0 | U19: 0 | V19: 12 | W19: 12 | X19: 0 | Z19: 297.87 | AA19: 239 | AC19: 1
A20: 45659 | B20: B | C20: 3 | I20: 0 | J20: 0 | S20: 0 | T20: 0 | U20: 0 | V20: 12 | W20: 12 | X20: 0 | Z20: 320.82 | AA20: 239 | AC20: 1
A21: 45659 | B21: A | C21: 4 | I21: 0 | J21: 0 | S21: 0 | T21: 0 | U21: 0 | V21: 12 | W21: 12 | X21: 0 | Z21: 875.88 | AA21: 797 | AC21: 1
A22: 45659 | B22: B | C22: 4 | I22: 0 | J22: 0 | S22: 0 | T22: 0 | U22: 0 | V22: 12 | W22: 12 | X22: 0 | Z22: 766.03 | AA22: 797 | AC22: 1
A23: 45659 | B23: A | C23: 5 | I23: 0 | J23: 0 | P23: 120 | S23: 120 | T23: 2 | U23: 2 | V23: 10 | W23: 12 | X23: 0 | Z23: 439.83 | AA23: 379 | AC23: 1
A24: 45659 | B24: B | C24: 5 | I24: 0 | J24: 0 | S24: 0 | T24: 0 | U24: 0 | V24: 12 | W24: 12 | X24: 0 | Z24: 538.48 | AA24: 379 | AC24: 1
A25: 45659 | B25: A | C25: 6 | I25: 0 | J25: 0 | S25: 0 | T25: 0 | U25: 0 | V25: 0 | X25: 0 | Z25: 0 | AC25: 1
A26: 45659 | B26: B | C26: 6 | I26: 0 | J26: 0 | S26: 0 | T26: 0 | U26: 0 | V26: 0 | X26: 0 | Z26: 0 | AC26: 1
A27: 45660 | B27: A | C27: 1 | I27: 0 | J27: 0 | L27: 60 | S27: 60 | T27: 1 | U27: 1 | V27: 11 | W27: 12 | X27: 40 | Y27: 2088 | Z27: 146.12 | AA27: 146 | AB27: 398 | AC27: 1
A28: 45660 | B28: B | C28: 1 | I28: 0 | J28: 0 | S28: 0 | T28: 0 | U28: 0 | V28: 12 | W28: 12 | X28: 30 | Z28: 128.62 | AA28: 146 | AC28: 1
A29: 45660 | B29: A | C29: 2 | I29: 0 | J29: 0 | S29: 0 | T29: 0 | U29: 0 | V29: 12 | W29: 12 | X29: 0 | Z29: 77.15 | AA29: 58 | AC29: 1
A30: 45660 | B30: B | C30: 2 | I30: 0 | J30: 0 | Q30: 45 | S30: 45 | T30: 0.75 | U30: 0.75 | V30: 11.25 | W30: 12 | X30: 0 | Z30: 91.46 | AA30: 58 | AC30: 1
A31: 45660 | B31: A | C31: 3 | I31: 0 | J31: 0 | S31: 0 | T31: 0 | U31: 0 | V31: 12 | W31: 12 | X31: 0 | Z31: 291.53 | AA31: 239 | AC31: 1
A32: 45660 | B32: B | C32: 3 | I32: 0 | J32: 0 | S32: 0 | T32: 0 | U32: 0 | V32: 12 | W32: 12 | X32: 0 | Z32: 289.84 | AA32: 239 | AC32: 1
A33: 45660 | B33: A | C33: 4 | I33: 0 | J33: 0 | S33: 0 | T33: 0 | U33: 0 | V33: 12 | W33: 12 | X33: 0 | Z33: 797.05 | AA33: 797 | AC33: 1
A34: 45660 | B34: B | C34: 4 | I34: 0 | J34: 0 | S34: 0 | T34: 0 | U34: 0 | V34: 12 | W34: 12 | X34: 0 | Z34: 826.54 | AA34: 797 | AC34: 1
A35: 45660 | B35: A | C35: 5 | I35: 0 | J35: 0 | S35: 0 | T35: 0 | U35: 0 | V35: 12 | W35: 12 | X35: 0 | Z35: 504.73 | AA35: 379 | AC35: 1
A36: 45660 | B36: B | C36: 5 | D36: 10 | I36: 10 | J36: 0.16666667 | S36: 0 | T36: 0 | U36: 0.16666667 | V36: 11.833333 | W36: 12 | X36: 0 | Z36: 557.98 | AA36: 379 | AC36: 1
A37: 45660 | B37: A | C37: 6 | I37: 0 | J37: 0 | S37: 0 | T37: 0 | U37: 0 | V37: 0 | X37: 0 | Z37: 0 | AC37: 1
A38: 45660 | B38: B | C38: 6 | I38: 0 | J38: 0 | S38: 0 | T38: 0 | U38: 0 | V38: 0 | X38: 0 | Z38: 0 | AC38: 1
A39: 45661 | B39: A | C39: 1 | D39: 10 | I39: 10 | J39: 0.16666667 | S39: 0 | T39: 0 | U39: 0.16666667 | V39: 11.833333 | W39: 12 | X39: 42 | Y39: 1778 | Z39: 152.52 | AA39: 146 | AB39: 398 | AC39: 1
A40: 45661 | B40: B | C40: 1 | I40: 0 | J40: 0 | S40: 0 | T40: 0 | U40: 0 | V40: 12 | W40: 12 | X40: 42 | Z40: 203.11 | AA40: 146 | AC40: 1
...

Sheet PP PRD
A1: SHIFT | B1: MCH# | C1: SO# | D1: DATE | E1: JOB NAME | F1: MATERIAL | G1: SIZE | H1: GUAGE | I1: QUALITY | J1: ORDER WEIGHT | K1: SECTION | L1: NO OF ROLLS | M1: G. WEIGHT | N1: CORE WEIGHT | O1: PRD WATSE | P1: SAMPLE WASTE | Q1: NET WEIGHT | R1: FOREMAN | S1: کوالٹی CHANGE | T1: ھیٹنگ | U1: MACHINE ON | V1: TOTAL MIN | W1: P.S HOURS | X1: الیکٹریکل | Y1: ڈایی صاف | Z1: مکینیکل | AA1: سائز کم | AB1: سیمپل چیک | AC1: OTHER | AD1: جالی تبدیل | AE1: TREET | AF1: TOTAL MIN_1 | AG1: U.P.S HOURS | AH1: T.S HOURS | AI1: RUNNING | AJ1: TOTAL HOURS | AK1: WASTAGE/KGs | AL1: KWH/KG | AM1: TOTAL PRODUCTION | AN1: TARGET | AO1: RECIPE | AP1: WEEK NO. | AQ1: REMARKS | AR1: ACTION | AS1: ACTION PLAN | AT1: REMARKS_2
A2: A | B2: 1 | C2: 4 P | D2: 45809 | E2: سادہ لفافہ | F2: PP | G2: 3 | H2: 5.5-6 | I2: 0 | J2: - | K2: PP | L2: 14 | M2: 157.7 | N2: 4.2 | O2: 21 | Q2: 153.5
A3: B | B3: 1 | C3: 4 P | D3: 45809 | E3: سادہ لفافہ | F3: PP | G3: 3 | H3: 5.5-6 | I3: 0 | J3: - | K3: PP | L3: 15 | M3: 164.97 | N3: 4.5 | O3: 21 | Q3: 160.47
A4: A | B4: 2 | C4: 8 P | D4: 45809 | E4: سادہ لفافہ | F4: PP | G4: 5 | H4: 5.5-6 | I4: 0 | J4: - | K4: PP | L4: 14 | M4: 176.7 | N4: 5.6 | Q4: 171.1
A5: B | B5: 2 | C5: 8 P | D5: 45809 | E5: سادہ لفافہ | F5: PP | G5: 5 | H5: 5.5-6 | I5: 0 | J5: - | K5: PP | L5: 15 | M5: 187.62 | N5: 6 | Q5: 181.62
A6: A | B6: 3 | C6: 10 P | D6: 45809 | E6: سادہ لفافہ | F6: PP | G6: 7 | H6: 5 | I6: 0 | J6: - | K6: PP | L6: 7 | M6: 255.13 | N6: 5.6 | Q6: 249.53
A7: B | B7: 3 | C7: 10 P | D7: 45809 | E7: سادہ لفافہ | F7: PP | G7: 7 | H7: 5 | I7: 0 | J7: - | K7: PP | L7: 7 | M7: 250.49 | N7: 6.3 | Q7: 244.19
A8: A | B8: 4 | C8: 6941/6 | D8: 45809 | E8: رول | F8: PP | G8: 17 | H8: 6.5 | I8: 0 | J8: 400 | K8: PP | L8: 6 | M8: 184.7 | N8: 12.6 | Q8: 172.1
A9: A | B9: 4 | C9: 6940/2 | D9: 45809 | E9: رول | F9: PP | G9: 15 | H9: 5 | I9: 0 | J9: 200 | K9: PP | L9: 7 | M9: 216.99 | N9: 11.9 | Q9: 205.09
A10: A | B10: 4 | C10: 6941/4 | D10: 45809 | E10: رول | F10: PP | G10: 15 | H10: 6.5 | I10: 0 | J10: 900 | K10: PP | L10: 8 | M10: 247.83 | N10: 14.4 | Q10: 233.43
A11: B | B11: 4 | C11: 6941/4 | D11: 45809 | E11: رول | F11: PP | G11: 15 | H11: 6.5 | I11: 0 | J11: 900 | K11: PP | L11: 15 | M11: 480.06 | N11: 25.5 | Q11: 454.56
A12: B | B12: 4 | C12: 2599 J | D12: 45809 | E12: سادہ لفافہ سپر یونیفارم | F12: PP | G12: 15 | H12: 8-8.5 | I12: .1:1 | J12: 50 | K12: PP | L12: 4 | M12: 156.94 | N12: 6 | Q12: 150.94
A13: A | B13: 5 | C13: 16 P | D13: 45809 | E13: سادہ لفافہ | F13: PP | G13: 13 | H13: 5 | I13: 0 | J13: - | K13: PP | L13: 16 | M13: 512.68 | N13: 25.6 | Q13: 487.08
A14: B | B14: 5 | C14: 16 P | D14: 45809 | E14: سادہ لفافہ | F14: PP | G14: 13 | H14: 5 | I14: 0 | J14: - | K14: PP | L14: 4 | M14: 124.17 | N14: 6.4 | Q14: 117.77
A15: B | B15: 5 | C15: 15 P | D15: 45809 | E15: سادہ لفافہ | F15: PP | G15: 12 | H15: 5 | I15: 0 | J15: - | K15: PP | L15: 12 | M15: 385.6 | N15: 18 | Q15: 367.6
A16: A | B16: 1 | C16: 4 P | D16: 45810 | E16: سادہ لفافہ | F16: PP | G16: 3 | H16: 5.5-6 | I16: 0 | J16: - | K16: PP | L16: 2 | M16: 35.98 | N16: 0.6 | O16: 30 | Q16: 35.38
A17: A | B17: 1 | C17: 2 P | D17: 45810 | E17: سادہ لفافہ | F17: PP | G17: 2 | H17: 5.5-6 | I17: 0 | J17: - | K17: PP | L17: 10 | M17: 94.25 | N17: 2 | Q17: 92.25
A18: B | B18: 1 | C18: 2 P | D18: 45810 | E18: سادہ لفافہ | F18: PP | G18: 2 | H18: 5.5-6 | I18: 0 | J18: - | K18: PP | L18: 12 | M18: 102.96 | N18: 2.4 | O18: 25 | Q18: 100.56
A19: A | B19: 2 | C19: 6 P | D19: 45810 | E19: سادہ لفافہ | F19: PP | G19: 4 | H19: 5.5-6 | I19: 0 | J19: - | K19: PP | L19: 10 | M19: 116.02 | N19: 4 | Q19: 112.02
A20: B | B20: 2 | C20: 6 P | D20: 45810 | E20: سادہ لفافہ | F20: PP | G20: 4 | H20: 5.5-6 | I20: 0 | J20: - | K20: PP | L20: 5 | M20: 66.74 | N20: 2 | Q20: 64.74
A21: A | B21: 3 | C21: 10 P | D21: 45810 | E21: سادہ لفافہ | F21: PP | G21: 7 | H21: 5 | I21: 0 | J21: - | K21: PP | L21: 2 | M21: 48.06 | N21: 1.4 | Q21: 46.66
A22: A | B22: 3 | C22: 6938/1 | D22: 45810 | E22: لفافہ | F22: PP | G22: 7 | H22: 15 | I22: 0 | J22: 250 | K22: PP | L22: 9 | M22: 257.82 | N22: 6.3 | Q22: 251.52
A23: B | B23: 3 | C23: 6938/1 | D23: 45810 | E23: لفافہ | F23: PP | G23: 7 | H23: 15 | I23: 0 | J23: 250 | K23: PP | L23: 10 | M23: 329.06 | N23: 7 | Q23: 322.06
A24: A | B24: 4 | C24: 6941/4 | D24: 45810 | E24: رول | F24: PP | G24: 15 | H24: 6.5 | I24: 0 | J24: 900 | K24: PP | L24: 8 | M24: 243.14 | N24: 14.4 | Q24: 228.74
A25: A | B25: 4 | C25: 6916/1 | D25: 45810 | E25: لفافہ | F25: PP | G25: 14 | H25: 5 | I25: 0 | J25: 150 | K25: PP | L25: 8 | M25: 321.89 | N25: 13.6 | Q25: 308.29
A26: A | B26: 4 | C26: 6941/3 | D26: 45810 | E26: رول | F26: PP | G26: 14 | H26: 6.5 | I26: 0 | J26: 300 | K26: PP | L26: 2 | M26: 60.19 | N26: 3.5 | Q26: 56.69
A27: B | B27: 4 | C27: 6941/3 | D27: 45810 | E27: رول | F27: PP | G27: 14 | H27: 6.5 | I27: 0 | J27: 300 | K27: PP | L27: 14 | M27: 549.6 | N27: 23.8 | Q27: 525.8
A28: A | B28: 5 | C28: 15 P | D28: 45810 | E28: سادہ لفافہ | F28: PP | G28: 12 | H28: 5 | I28: 0 | J28: - | K28: PP | L28: 10 | M28: 444.9 | N28: 14 | Q28: 430.9
A29: B | B29: 5 | C29: 15 P | D29: 45810 | E29: سادہ لفافہ | F29: PP | G29: 12 | H29: 5 | I29: 0 | J29: - | K29: PP | L29: 12 | M29: 519.41 | N29: 16.8 | Q29: 502.61
A30: A | B30: 1 | C30: 2 P | D30: 45811 | E30: سادہ لفافہ | F30: PP | G30: 2 | H30: 5.5-6 | I30: 0 | J30: - | K30: PP | L30: 10 | M30: 115 | N30: 2 | O30: 35 | Q30: 113
A31: B | B31: 1 | C31: 2 P | D31: 45811 | E31: سادہ لفافہ | F31: PP | G31: 2 | H31: 5.5-6 | I31: 0 | J31: - | K31: PP | L31: 10 | M31: 97.49 | N31: 2 | O31: 65 | Q31: 95.49
A32: A | B32: 2 | C32: 6 P | D32: 45811 | E32: سادہ لفافہ | F32: PP | G32: 4 | H32: 5.5-6 | I32: 0 | J32: - | K32: PP | L32: 9 | M32: 262.66 | N32: 3.6 | Q32: 259.06
A33: B | B33: 2 | C33: 6 P | D33: 45811 | E33: سادہ لفافہ | F33: PP | G33: 4 | H33: 5.5-6 | I33: 0 | J33: - | K33: PP | L33: 12 | M33: 171.27 | N33: 4.8 | Q33: 166.47
A34: A | B34: 3 | C34: 10 P | D34: 45811 | E34: سادہ لفافہ | F34: PP | G34: 7 | H34: 5 | I34: 0 | J34: - | K34: PP | L34: 8 | M34: 300.01 | N34: 5.6 | Q34: 294.41
A35: B | B35: 3 | C35: 10 P | D35: 45811 | E35: سادہ لفافہ | F35: PP | G35: 7 | H35: 5 | I35: 0 | J35: - | K35: PP | L35: 4 | M35: 270.88 | N35: 2.8 | Q35: 268.08
A36: A | B36: 4 | C36: 2625 J | D36: 45811 | E36: سادہ رول جیلانی پولی سٹاک | F36: PP | G36: 20 | H36: 5-5.5 | I36: .1:1 | J36: 1000 | K36: PP | L36: 13 | M36: 666.18 | N36: 32.5 | Q36: 633.68
A37: B | B37: 4 | C37: 2671 J | D37: 45811 | E37: (1X1)بندوخاں برگر بن | F37: PP | G37: 18" شیٹ | H37: 4-4.5/8-9 | I37: .1:1 | J37: 50 | K37: PP | L37: 15 | M37: 647.09 | N37: 27 | Q37: 620.09
A38: B | B38: 4 | C38: 2668 J | D38: 45811 | E38: بندوخاں پلین شیر مال | F38: PP | G38: 22" شیٹ | H38: 4-4.5/8-9 | I38: .1:1 | J38: 100 | K38: PP | L38: 1 | M38: 50.79 | N38: 2.2 | Q38: 48.59
A39: A | B39: 5 | C39: 15 P | D39: 45811 | E39: سادہ لفافہ | F39: PP | G39: 12 | H39: 5 | I39: 0 | J39: - | K39: PP | L39: 2 | M39: 106.38 | N39: 3 | Q39: 103.38
A40: A | B40: 5 | C40: 6916/4 | D40: 45811 | E40: لفافہ | F40: PP | G40: 9 | H40: 4.5 | I40: 0 | J40: 150 | K40: PP | L40: 6 | M40: 165.42 | N40: 7.2 | Q40: 158.22
...

Sheet PP PRO PIVOTE
A1: DATE | B1: Months | C1: MCH# | D1: SHIFT | E1: Min of TOTAL HOURS | F1: Count of REMARKS | G1: Count of REMARKS_2 | H1: Sum of سیمپل چیک | I1: Sum of TREET | J1: Count of KWH/KG | K1: Sum of NET WEIGHT | L1: Count of ACTION | M1: Count of ACTION PLAN | N1: Sum of کوالٹی CHANGE | O1: Sum of ھیٹنگ | P1: Sum of MACHINE ON | Q1: Sum of TOTAL MIN | R1: Sum of P.S HOURS | S1: Sum of الیکٹریکل | T1: Sum of ڈایی صاف | U1: Sum of مکینیکل | V1: Sum of سائز کم | W1: Sum of OTHER | X1: Sum of جالی تبدیل | Y1: Sum of TOTAL MIN_1 | Z1: Sum of U.P.S HOURS | AA1: Sum of T.S HOURS | AB1: Sum of RUNNING | AC1: Sum of WASTAGE/KGs | AD1: Sum of TOTAL PRODUCTION | AE1: Sum of TARGET | AF1: Sum of RECIPE | AG1: Min of WEEK NO.
A3: DATE | B3: Months | C3: MCH# | D3: SHIFT | E3: Min of TOTAL HOURS | F3: Count of REMARKS | G3: Count of REMARKS_2 | H3: Sum of سیمپل چیک | I3: Sum of TREET | J3: Count of KWH/KG | K3: Sum of NET WEIGHT | L3: Count of ACTION | M3: Count of ACTION PLAN | N3: Sum of کوالٹی CHANGE | O3: Sum of ھیٹنگ | P3: Sum of MACHINE ON | Q3: Sum of TOTAL MIN | R3: Sum of P.S HOURS | S3: Sum of الیکٹریکل | T3: Sum of ڈایی صاف | U3: Sum of مکینیکل | V3: Sum of سائز کم | W3: Sum of OTHER | X3: Sum of جالی تبدیل | Y3: Sum of TOTAL MIN_1 | Z3: Sum of U.P.S HOURS | AA3: Sum of T.S HOURS | AB3: Sum of RUNNING | AC3: Sum of WASTAGE/KGs | AD3: Sum of TOTAL PRODUCTION | AE3: Sum of TARGET | AF3: Sum of RECIPE | AG3: Min of WEEK NO.
A4: 01-Apr | B4: Apr | C4: 4 | D4: A | E4: 12 | K4: 463.98 | N4: 25 | O4: 180 | Q4: 205 | R4: 3.4166667 | X4: 30 | Y4: 30 | Z4: 0.5 | AA4: 3.9166667 | AB4: 44.083333 | AD4: 0 | AE4: 504.58 | AG4: 14
A5: 01-Apr | B5: Apr | C5: 4 | D5: B | E5: 12 | K5: 592.22 | N5: 25 | Q5: 25 | R5: 0.41666667 | Y5: 0 | Z5: 0 | AA5: 0.41666667 | AB5: 35.583333 | AD5: 0 | AE5: 644.62 | AG5: 14
A6: 01-Apr | B6: Apr | C6: 5 | D6: A | E6: 12 | K6: 404.01 | N6: 20 | O6: 180 | Q6: 200 | R6: 3.3333333 | Y6: 0 | Z6: 0 | AA6: 3.3333333 | AB6: 20.666667 | AD6: 0 | AE6: 424.61 | AG6: 14
A7: 01-Apr | B7: Apr | C7: 5 | D7: B | E7: 12 | K7: 618.32 | Q7: 0 | R7: 0 | Y7: 0 | Z7: 0 | AA7: 0 | AB7: 12 | AD7: 0 | AE7: 639.32 | AG7: 14
A8: 02-Apr | B8: Apr | C8: 1 | D8: B | E8: 12 | K8: 93.29 | O8: 180 | Q8: 180 | R8: 3 | Y8: 0 | Z8: 0 | AA8: 3 | AB8: 9 | AD8: 0 | AE8: 99.79 | AG8: 14
A9: 02-Apr | B9: Apr | C9: 2 | D9: B | E9: 12 | K9: 111.69 | O9: 150 | Q9: 150 | R9: 2.5 | Y9: 0 | Z9: 0 | AA9: 2.5 | AB9: 9.5 | AD9: 0 | AE9: 119.09 | AG9: 14
A10: 02-Apr | B10: Apr | C10: 4 | D10: A | E10: 12 | K10: 686.44 | Q10: 0 | R10: 0 | Y10: 0 | Z10: 0 | AA10: 0 | AB10: 36 | AD10: 0 | AE10: 723.94 | AG10: 14
A11: 02-Apr | B11: Apr | C11: 4 | D11: B | E11: 12 | K11: 678.41 | N11: 40 | Q11: 40 | R11: 0.66666667 | Y11: 0 | Z11: 0 | AA11: 0.66666667 | AB11: 47.333333 | AD11: 0 | AE11: 729.81 | AG11: 14
A12: 02-Apr | B12: Apr | C12: 5 | D12: A | E12: 12 | K12: 586.7 | Q12: 0 | R12: 0 | Y12: 0 | Z12: 0 | AA12: 0 | AB12: 12 | AD12: 0 | AE12: 605.7 | AG12: 14
A13: 02-Apr | B13: Apr | C13: 5 | D13: B | E13: 12 | K13: 402.08 | N13: 20 | Q13: 20 | R13: 0.33333333 | Y13: 0 | Z13: 0 | AA13: 0.33333333 | AB13: 23.666667 | AD13: 0 | AE13: 422.88 | AG13: 14
A14: 03-Apr | B14: Apr | C14: 1 | D14: A | E14: 12 | K14: 132.43 | Q14: 0 | R14: 0 | Y14: 0 | Z14: 0 | AA14: 0 | AB14: 12 | AD14: 0 | AE14: 139.53 | AG14: 14
A15: 03-Apr | B15: Apr | C15: 1 | D15: B | E15: 12 | K15: 130.26 | Q15: 0 | R15: 0 | Y15: 0 | Z15: 0 | AA15: 0 | AB15: 12 | AD15: 0 | AE15: 137.36 | AG15: 14
A16: 03-Apr | B16: Apr | C16: 2 | D16: A | E16: 12 | K16: 165.02 | Q16: 0 | R16: 0 | Y16: 0 | Z16: 0 | AA16: 0 | AB16: 12 | AD16: 0 | AE16: 173.62 | AG16: 14
A17: 03-Apr | B17: Apr | C17: 2 | D17: B | E17: 12 | K17: 169 | Q17: 0 | R17: 0 | Y17: 0 | Z17: 0 | AA17: 0 | AB17: 12 | AD17: 0 | AE17: 177.6 | AG17: 14
A18: 03-Apr | B18: Apr | C18: 4 | D18: A | E18: 12 | K18: 744.41 | Q18: 0 | R18: 0 | Y18: 0 | Z18: 0 | AA18: 0 | AB18: 12 | AD18: 0 | AE18: 785.41 | AG18: 14
A19: 03-Apr | B19: Apr | C19: 4 | D19: B | E19: 12 | K19: 713.56 | Q19: 0 | R19: 0 | Y19: 0 | Z19: 0 | AA19: 0 | AB19: 12 | AD19: 0 | AE19: 751.56 | AG19: 14
A20: 03-Apr | B20: Apr | C20: 5 | D20: A | E20: 12 | K20: 416.39 | Q20: 0 | R20: 0 | Y20: 0 | Z20: 0 | AA20: 0 | AB20: 12 | AD20: 0 | AE20: 429.49 | AG20: 14
A21: 03-Apr | B21: Apr | C21: 5 | D21: B | E21: 12 | K21: 416.34 | Q21: 0 | R21: 0 | Y21: 0 | Z21: 0 | AA21: 0 | AB21: 12 | AD21: 0 | AE21: 429.44 | AG21: 14
A22: 04-Apr | B22: Apr | C22: 1 | D22: A | E22: 12 | K22: 113.71 | Q22: 0 | R22: 0 | X22: 30 | Y22: 30 | Z22: 0.5 | AA22: 0.5 | AB22: 11.5 | AD22: 0 | AE22: 120.81 | AG22: 14
A23: 04-Apr | B23: Apr | C23: 1 | D23: B | E23: 12 | K23: 113.62 | Q23: 0 | R23: 0 | Y23: 0 | Z23: 0 | AA23: 0 | AB23: 12 | AD23: 0 | AE23: 120.42 | AG23: 14
A24: 04-Apr | B24: Apr | C24: 2 | D24: A | E24: 12 | K24: 161.92 | Q24: 0 | R24: 0 | Y24: 0 | Z24: 0 | AA24: 0 | AB24: 12 | AD24: 0 | AE24: 170.52 | AG24: 14
A25: 04-Apr | B25: Apr | C25: 2 | D25: B | E25: 12 | K25: 169.5 | Q25: 0 | R25: 0 | X25: 20 | Y25: 20 | Z25: 0.33333333 | AA25: 0.33333333 | AB25: 11.666667 | AD25: 0 | AE25: 177.7 | AG25: 14
A26: 04-Apr | B26: Apr | C26: 4 | D26: A | E26: 12 | K26: 668.07 | N26: 30 | Q26: 30 | R26: 0.5 | Y26: 0 | Z26: 0 | AA26: 0.5 | AB26: 35.5 | AD26: 0 | AE26: 706.17 | AG26: 14
A27: 04-Apr | B27: Apr | C27: 4 | D27: B | E27: 12 | K27: 723.44 | Q27: 0 | R27: 0 | Y27: 0 | Z27: 0 | AA27: 0 | AB27: 24 | AD27: 0 | AE27: 753.34 | AG27: 14
A28: 04-Apr | B28: Apr | C28: 5 | D28: A | E28: 12 | K28: 280.14 | Q28: 0 | R28: 0 | Y28: 0 | Z28: 0 | AA28: 0 | AB28: 12 | AD28: 0 | AE28: 290.54 | AG28: 14
A29: 04-Apr | B29: Apr | C29: 5 | D29: B | E29: 12 | K29: 327.04 | Q29: 0 | R29: 0 | U29: 180 | Y29: 180 | Z29: 3 | AA29: 3 | AB29: 9 | AD29: 0 | AE29: 339.74 | AG29: 14
A30: 05-Apr | B30: Apr | C30: 1 | D30: A | E30: 12 | K30: 129.42 | Q30: 0 | R30: 0 | Y30: 0 | Z30: 0 | AA30: 0 | AB30: 12 | AD30: 0 | AE30: 136.52 | AG30: 14
A31: 05-Apr | B31: Apr | C31: 1 | D31: B | E31: 12 | K31: 121.59 | Q31: 0 | R31: 0 | Y31: 0 | Z31: 0 | AA31: 0 | AB31: 12 | AD31: 0 | AE31: 128.69 | AG31: 14
A32: 05-Apr | B32: Apr | C32: 2 | D32: A | E32: 12 | K32: 178.03 | Q32: 0 | R32: 0 | Y32: 0 | Z32: 0 | AA32: 0 | AB32: 12 | AD32: 0 | AE32: 187.03 | AG32: 14
A33: 05-Apr | B33: Apr | C33: 2 | D33: B | E33: 12 | K33: 175.21 | Q33: 0 | R33: 0 | Y33: 0 | Z33: 0 | AA33: 0 | AB33: 12 | AD33: 0 | AE33: 184.21 | AG33: 14
A34: 05-Apr | B34: Apr | C34: 4 | D34: A | E34: 12 | K34: 429.36 | Q34: 0 | R34: 0 | Y34: 0 | Z34: 0 | AA34: 0 | AB34: 12 | AD34: 0 | AE34: 447.96 | AG34: 14
A35: 05-Apr | B35: Apr | C35: 4 | D35: B | E35: 12 | K35: 511.73 | Q35: 0 | R35: 0 | Y35: 0 | Z35: 0 | AA35: 0 | AB35: 12 | AD35: 0 | AE35: 533.73 | AG35: 14
A36: 05-Apr | B36: Apr | C36: 5 | D36: A | E36: 12 | K36: 387.16 | N36: 30 | Q36: 30 | R36: 0.5 | Y36: 0 | Z36: 0 | AA36: 0.5 | AB36: 23.5 | AD36: 0 | AE36: 406.86 | AG36: 14
A37: 05-Apr | B37: Apr | C37: 5 | D37: B | E37: 12 | K37: 609.93 | Q37: 0 | R37: 0 | Y37: 0 | Z37: 0 | AA37: 0 | AB37: 60 | AD37: 0 | AE37: 653.13 | AG37: 14
A38: 06-Apr | B38: Apr | C38: 1 | D38: A | E38: 12 | K38: 134.26 | Q38: 0 | R38: 0 | Y38: 0 | Z38: 0 | AA38: 0 | AB38: 12 | AD38: 0 | AE38: 141.36 | AG38: 15
A39: 06-Apr | B39: Apr | C39: 1 | D39: B | E39: 12 | K39: 128.42 | Q39: 0 | R39: 0 | Y39: 0 | Z39: 0 | AA39: 0 | AB39: 12 | AD39: 0 | AE39: 135.52 | AG39: 15
A40: 06-Apr | B40: Apr | C40: 2 | D40: A | E40: 12 | K40: 194.37 | Q40: 0 | R40: 0 | Y40: 0 | Z40: 0 | AA40: 0 | AB40: 12 | AD40: 0 | AE40: 203.37 | AG40: 15
A41: 06-Apr | B41: Apr | C41: 2 | D41: B | E41: 12 | K41: 178.6 | Q41: 0 | R41: 0 | Y41: 0 | Z41: 0 | AA41: 0 | AB41: 12 | AD41: 0 | AE41: 187.6 | AG41: 15
...

Sheet WOR
A1: WEEKLY OPERATION REVIEW PP DEPARTMENT | M1: 46139 | N1: 17
A2: KPI | C2: MACHINES | J2: WEEK NO 17 | K2: % | L2: WEEK NO 16
C3: 1 | D3: =+C3+1 -> 2 | E3: =+D3+1 -> 3 | F3: =+E3+1 -> 4 | G3: =+F3+1 -> 5 | H3: =+G3+1 -> 6 | M3: REMARKS
A4: PLANED STOPPAGE HOURS | C4: =SUMIFS('PP PRD'!$W:$W,'PP PRD'!$B:$B,C$3,'PP PRD'!$AP:$AP,WOR!$N$1) -> 0 | D4: =SUMIFS('PP PRD'!$W:$W,'PP PRD'!$B:$B,D$3,'PP PRD'!$AP:$AP,WOR!$N$1) -> 4.1666667 | E4: =SUMIFS('PP PRD'!$W:$W,'PP PRD'!$B:$B,E$3,'PP PRD'!$AP:$AP,WOR!$N$1) -> 0 | F4: =SUMIFS('PP PRD'!$W:$W,'PP PRD'!$B:$B,F$3,'PP PRD'!$AP:$AP,WOR!$N$1) -> 5.1666667 | G4: =SUMIFS('PP PRD'!$W:$W,'PP PRD'!$B:$B,G$3,'PP PRD'!$AP:$AP,WOR!$N$1) -> 1.5833333 | H4: =SUMIFS('PP PRD'!$W:$W,'PP PRD'!$B:$B,H$3,'PP PRD'!$AP:$AP,WOR!$N$1) -> 0 | J4: =SUM(C4:I4) -> 10.916667 | K4: =J4/SUMIFS('PP PRO PIVOTE'!E:E,'PP PRO PIVOTE'!AG:AG,WOR!N1) -> 0.022188347 | L4: 5.58 | M4: SIZE CHANGE (0.93%) HEATING (1.29%)
A5: PLANED STOPPAGE % (2 %) | C5: =IFERROR(+C4/SUMIFS('PP PRO PIVOTE'!$E:$E,'PP PRO PIVOTE'!$AG:$AG,WOR!$N$1,'PP PRO PIVOTE'!$C:$C,WOR!C3),"-") -> - | D5: =IFERROR(+D4/SUMIFS('PP PRO PIVOTE'!$E:$E,'PP PRO PIVOTE'!$AG:$AG,WOR!$N$1,'PP PRO PIVOTE'!$C:$C,WOR!D3),"-") -> 0.024801587 | E5: =IFERROR(+E4/SUMIFS('PP PRO PIVOTE'!$E:$E,'PP PRO PIVOTE'!$AG:$AG,WOR!$N$1,'PP PRO PIVOTE'!$C:$C,WOR!E3),"-") -> - | F5: =IFERROR(+F4/SUMIFS('PP PRO PIVOTE'!$E:$E,'PP PRO PIVOTE'!$AG:$AG,WOR!$N$1,'PP PRO PIVOTE'!$C:$C,WOR!F3),"-") -> 0.033119658 | G5: =IFERROR(+G4/SUMIFS('PP PRO PIVOTE'!$E:$E,'PP PRO PIVOTE'!$AG:$AG,WOR!$N$1,'PP PRO PIVOTE'!$C:$C,WOR!G3),"-") -> 0.0094246032 | H5: =IFERROR(+H4/SUMIFS('PP PRO PIVOTE'!$E:$E,'PP PRO PIVOTE'!$AG:$AG,WOR!$N$1,'PP PRO PIVOTE'!$C:$C,WOR!H3),"-") -> - | L5: 0.0111
A6: UNPLANED STOPPAGE HOURS | C6: =SUMIFS('PP PRD'!$AG:$AG,'PP PRD'!$B:$B,C3,'PP PRD'!$AP:$AP,WOR!$N$1) -> 0 | D6: =SUMIFS('PP PRD'!$AG:$AG,'PP PRD'!$B:$B,D3,'PP PRD'!$AP:$AP,WOR!$N$1) -> 1.6666667 | E6: =SUMIFS('PP PRD'!$AG:$AG,'PP PRD'!$B:$B,E3,'PP PRD'!$AP:$AP,WOR!$N$1) -> 0 | F6: =SUMIFS('PP PRD'!$AG:$AG,'PP PRD'!$B:$B,F3,'PP PRD'!$AP:$AP,WOR!$N$1) -> 9 | G6: =SUMIFS('PP PRD'!$AG:$AG,'PP PRD'!$B:$B,G3,'PP PRD'!$AP:$AP,WOR!$N$1) -> 0 | H6: =SUMIFS('PP PRD'!$AG:$AG,'PP PRD'!$B:$B,H3,'PP PRD'!$AP:$AP,WOR!$N$1) -> 0 | J6: =SUM(C6:I6) -> 10.666667 | K6: =J6/SUMIFS('PP PRO PIVOTE'!E:E,'PP PRO PIVOTE'!AG:AG,WOR!N1) -> 0.021680217 | L6: 16.58 | M6: MECHANICAL ISSUE (0.24%) JALI CHANGE (0.10%)OTHERS (1.83%) | O6: =+J8-L8 -> -1136.29
A7: UNPLANED STOPPAGE % (3%) | C7: =IFERROR(+C6/SUMIFS('PP PRO PIVOTE'!$E:$E,'PP PRO PIVOTE'!$AG:$AG,WOR!$N$1,'PP PRO PIVOTE'!$C:$C,WOR!C3),"-") -> - | D7: =IFERROR(+D6/SUMIFS('PP PRO PIVOTE'!$E:$E,'PP PRO PIVOTE'!$AG:$AG,WOR!$N$1,'PP PRO PIVOTE'!$C:$C,WOR!D3),"-") -> 0.0099206349 | E7: =IFERROR(+E6/SUMIFS('PP PRO PIVOTE'!$E:$E,'PP PRO PIVOTE'!$AG:$AG,WOR!$N$1,'PP PRO PIVOTE'!$C:$C,WOR!E3),"-") -> - | F7: =IFERROR(+F6/SUMIFS('PP PRO PIVOTE'!$E:$E,'PP PRO PIVOTE'!$AG:$AG,WOR!$N$1,'PP PRO PIVOTE'!$C:$C,WOR!F3),"-") -> 0.057692308 | G7: =IFERROR(+G6/SUMIFS('PP PRO PIVOTE'!$E:$E,'PP PRO PIVOTE'!$AG:$AG,WOR!$N$1,'PP PRO PIVOTE'!$C:$C,WOR!G3),"-") -> 0 | H7: =IFERROR(+H6/SUMIFS('PP PRO PIVOTE'!$E:$E,'PP PRO PIVOTE'!$AG:$AG,WOR!$N$1,'PP PRO PIVOTE'!$C:$C,WOR!H3),"-") -> - | L7: 0.0329 | S7: ROLL WASTE
A8: TOTAL PRODUCTION KGs | C8: =SUMIFS('PP PRD'!$Q:$Q,'PP PRD'!$B:$B,C3,'PP PRD'!$AP:$AP,WOR!$N$1) -> 0 | D8: =SUMIFS('PP PRD'!$Q:$Q,'PP PRD'!$B:$B,D3,'PP PRD'!$AP:$AP,WOR!$N$1) -> 2119.2 | E8: =SUMIFS('PP PRD'!$Q:$Q,'PP PRD'!$B:$B,E3,'PP PRD'!$AP:$AP,WOR!$N$1) -> 0 | F8: =SUMIFS('PP PRD'!$Q:$Q,'PP PRD'!$B:$B,F3,'PP PRD'!$AP:$AP,WOR!$N$1) -> 6170.69 | G8: =SUMIFS('PP PRD'!$Q:$Q,'PP PRD'!$B:$B,G3,'PP PRD'!$AP:$AP,WOR!$N$1) -> 5566.43 | H8: =SUMIFS('PP PRD'!$Q:$Q,'PP PRD'!$B:$B,H3,'PP PRD'!$AP:$AP,WOR!$N$1) -> 0 | J8: =SUM(C8:I8) -> 13856.32 | K8: =+$J$8/$J$9 -> 0.94796052 | L8: 14992.61 | O8: WASTE RATE | P8: 200 | S8: WASTE RATE | T8: 200
A9: TARGET PRODUCTION | C9: =SUMIFS('PP PRD'!$AN:$AN,'PP PRD'!$B:$B,C3,'PP PRD'!$AP:$AP,WOR!$N$1) -> 0 | D9: =SUMIFS('PP PRD'!$AN:$AN,'PP PRD'!$B:$B,D3,'PP PRD'!$AP:$AP,WOR!$N$1) -> 2261.8 | E9: =SUMIFS('PP PRD'!$AN:$AN,'PP PRD'!$B:$B,E3,'PP PRD'!$AP:$AP,WOR!$N$1) -> 0 | F9: =SUMIFS('PP PRD'!$AN:$AN,'PP PRD'!$B:$B,F3,'PP PRD'!$AP:$AP,WOR!$N$1) -> 6504.45 | G9: =SUMIFS('PP PRD'!$AN:$AN,'PP PRD'!$B:$B,G3,'PP PRD'!$AP:$AP,WOR!$N$1) -> 5850.73 | H9: =SUMIFS('PP PRD'!$AN:$AN,'PP PRD'!$B:$B,H3,'PP PRD'!$AP:$AP,WOR!$N$1) -> 0 | J9: =SUM(C9:I9) -> 14616.98 | L9: 15880 | P9: =+J11*P8 -> 80000 | T9: =+J14*T8 -> 0
A10: PRODUCTION ACHIVEMENT % (95 %) | C10: =IFERROR((C$8/C$9),"--") -> -- | D10: =IFERROR((D$8/D$9),"--") -> 0.93695287 | E10: =IFERROR((E$8/E$9),"--") -> -- | F10: =IFERROR((F$8/F$9),"--") -> 0.94868744 | G10: =IFERROR((G$8/G$9),"--") -> 0.95140777 | H10: =IFERROR((H$8/H$9),"--") -> -- | L10: 0.9441 | P10: =+J13-P9 -> 79200 | T10: =+T9-J14 -> 0
A11: WASTAGE/KGS | C11: =SUMIFS('PP PRD'!O:O,'PP PRD'!AP:AP,WOR!$N$1)+M26 -> 400 | J11: =SUM(C11:I11) -> 400 | K11: =+$J$11/$J$8 -> 0.028867694 | L11: 709 | O11: WASTE LOSS | P11: =+P10/J8 -> 5.7158033 | S11: WASTE LOSS | T11: =+T10/J8 -> 0
A12: WASTAGE/% (4%) | C12: =IFERROR((C$11/J$8),"--") -> 0.028867694 | L12: 0.0473
A13: WASTAGE/VALUE | C13: {=(SUMIFS(KWH!D:D,KWH!E:E,WOR!$N$1)/(COUNT(_xlfn._xlws.FILTER(_xlfn._xlws.FILTER(KWH!A:E,KWH!E:E=WOR!$N$1),{0,0,1,0,0})))*C11)} -> 159200 | J13: {=(SUMIFS(KWH!D:D,KWH!E:E,WOR!$N$1)/(COUNT(_xlfn._xlws.FILTER(_xlfn._xlws.FILTER(KWH!A:E,KWH!E:E=WOR!$N$1),{0,0,1,0,0}))))*J11} -> 159200 | K13: =+$P$11 -> 5.7158033 | L13: 9.36 | O13: 160394
A14: ROLL WASTAGE/KGS | C14: 0 | J14: =+C14 -> 0 | K14: =+$J$14/$J$8 -> 0
A15: WASTAGE/% (4%) | C15: =IFERROR((C$14/J$8),"--") -> 0
A16: WASTAGE/VALUE | C16: {=(SUMIFS(KWH!D:D,KWH!E:E,WOR!$N$1)/(COUNT(_xlfn._xlws.FILTER(_xlfn._xlws.FILTER(KWH!A:E,KWH!E:E=WOR!$N$1),{0,0,1,0,0})))*C14)} -> 0 | J16: {=(SUMIFS(KWH!D:D,KWH!E:E,WOR!$N$1)/(COUNT(_xlfn._xlws.FILTER(_xlfn._xlws.FILTER(KWH!A:E,KWH!E:E=WOR!$N$1),{0,0,1,0,0}))))*J14} -> 0 | K16: =+T11 -> 0
A17: TOTAL KWH (26/KG) | C17: =SUMIFS(KWH!B:B,KWH!E:E,WOR!$N$1) -> 8149.5
A18: KWH VALUE @ 44 | C18: =+C17*44 -> 358578 | K18: =+$C$18/$J$8 -> 25.8783 | L18: 28.49
A19: LABOR/KG | B19: VARIABLE | C19: =236000+28320 -> 264320 | E19: =(((C19/26)*7)/J8) -> 5.1357847 | F19: ADMIN | G19: =150000+18000 -> 168000 | H19: =(((G19/26)*7)/J8) -> 3.26427 | K19: =+E19+H20+H19 -> 14.107087 | L19: 13.04 | O19: =266000/2 -> 133000
B20: FIXED | C20: FOREMANS | E20: =((123200/26)*7)/$J$8 -> 2.393798 | G20: STAFF | H20: =(((170520/26)*7)/J8)+E20 -> 5.707032 | M20: =+L21+L19+L18+L13 -> 53.27
A21: STORE EXPENSE | C21: =+[1]WOR!$Q$18 -> 79090.13 | F21: REPAIR | J21: =+(C21+H21)/J8 -> 5.7078741 | L21: 2.38 | M21: =+J21+K19+K18+K13+K16 -> 51.409064
L24: tr# waste | M24: 400
M25: =+M24-J11 -> 0
L26: diff | M26: 225
M27: =+M24-M25 -> 400

Sheet MOR
A1: MONTHLY OPERATION REVIEW PP DEPARTMENT | Y1: 46113
A2: KPI | C2: MACHINES | H2: MONTH OF APR | I2: % | J2: MONTH OF MAR | K2: MONTH OF FEB | L2: MONTH OF JAN | M2: MONTH OF DEC | N2: MONTH OF NOV | O2: MONTH OF OCT | P2: MONTH OF SEP | Q2: MONTH OF AUG | R2: MONTH OF JUL | S2: MONTH OF JUN | T2: MONTH OF MAY | U2: MONTH OF APR | V2: MONTH OF MAR | W2: MONTH OF FEB | X2: MONTH OF JAN
C3: 14 | D3: =+C3+1 -> 15 | E3: =+D3+1 -> 16 | F3: =+E3+1 -> 17 | G3: =+F3+1 -> 18 | Y3: REMARKS
A4: PLANED STOPPAGE HOURS | C4: =SUMIFS(PP_PRD[P.S HOURS],PP_PRD[WEEK NO.],MOR!C3) -> 14.666667 | D4: =SUMIFS(PP_PRD[P.S HOURS],PP_PRD[WEEK NO.],MOR!D3) -> 7.5 | E4: =SUMIFS(PP_PRD[P.S HOURS],PP_PRD[WEEK NO.],MOR!E3) -> 5.5833333 | F4: =SUMIFS(PP_PRD[P.S HOURS],PP_PRD[WEEK NO.],MOR!F3) -> 10.916667 | G4: =SUMIFS(PP_PRD[P.S HOURS],PP_PRD[WEEK NO.],MOR!G3) -> 9.75 | H4: =SUM(C4:G4) -> 48.416667 | I4: =+H4/(SUMIFS('PP PRO PIVOTE'!E:E,'PP PRO PIVOTE'!AG:AG,MOR!C3)+SUMIFS('PP PRO PIVOTE'!E:E,'PP PRO PIVOTE'!AG:AG,D3)+SUMIFS('PP PRO PIVOTE'!E:E,'PP PRO PIVOTE'!AG:AG,E3)+SUMIFS('PP PRO PIVOTE'!E:E,'PP PRO PIVOTE'!AG:AG,F3)+SUMIFS('PP PRO PIVOTE'!E:E,'PP PRO PIVOTE'!AG:AG,G3)) -> 0.020797537 | J4: 24.83 | K4: 58.53 | L4: 123.33 | M4: 110.92 | N4: 134.67 | O4: 96.18 | P4: 78.48 | Q4: 51.57 | R4: 83.17 | S4: 72.33 | T4: 63.67 | U4: 37.08 | V4: 25.75 | W4: 21.58 | X4: 18.67 | Y4: Size Change 1.08% + MACHINE ON/OFF 1.00% TOTAL=2.08%
A5: PLANED STOPPAGE % TARGET (2 %) | C5: =IFERROR((C4/(SUMIFS('PP PRO PIVOTE'!$E:$E,'PP PRO PIVOTE'!$AG:$AG,MOR!C3))),"--") -> 0.035947712 | D5: =IFERROR((D4/(SUMIFS('PP PRO PIVOTE'!$E:$E,'PP PRO PIVOTE'!$AG:$AG,MOR!D3))),"--") -> 0.013888889 | E5: =IFERROR((E4/(SUMIFS('PP PRO PIVOTE'!$E:$E,'PP PRO PIVOTE'!$AG:$AG,MOR!E3))),"--") -> 0.011078042 | F5: =IFERROR((F4/(SUMIFS('PP PRO PIVOTE'!$E:$E,'PP PRO PIVOTE'!$AG:$AG,MOR!F3))),"--") -> 0.022188347 | G5: =IFERROR((G4/(SUMIFS('PP PRO PIVOTE'!$E:$E,'PP PRO PIVOTE'!$AG:$AG,MOR!G3))),"--") -> 0.025390625 | J5: 0.0171 | K5: 0.0255 | L5: 0.0478 | M5: 0.038 | N5: 0.0484 | O5: 0.0314 | P5: 0.0219 | Q5: 0.0117 | R5: 0.0275 | S5: 0.0301 | T5: 0.0211 | U5: 0.0187 | V5: 0.0074 | W5: 0.0073 | X5: 0.0056
A6: UNPLANED STOPPAGE HOURS | C6: =SUMIFS(PP_PRD[U.P.S HOURS],PP_PRD[WEEK NO.],MOR!C3) -> 4.3333333 | D6: =SUMIFS(PP_PRD[U.P.S HOURS],PP_PRD[WEEK NO.],MOR!D3) -> 5.4166667 | E6: =SUMIFS(PP_PRD[U.P.S HOURS],PP_PRD[WEEK NO.],MOR!E3) -> 16.583333 | F6: =SUMIFS(PP_PRD[U.P.S HOURS],PP_PRD[WEEK NO.],MOR!F3) -> 10.666667 | G6: =SUMIFS(PP_PRD[U.P.S HOURS],PP_PRD[WEEK NO.],MOR!G3) -> 4 | H6: =SUM(C6:G6) -> 41 | I6: =+H6/(SUMIFS('PP PRO PIVOTE'!E:E,'PP PRO PIVOTE'!AG:AG,MOR!C3)+SUMIFS('PP PRO PIVOTE'!E:E,'PP PRO PIVOTE'!AG:AG,D3)+SUMIFS('PP PRO PIVOTE'!E:E,'PP PRO PIVOTE'!AG:AG,E3)+SUMIFS('PP PRO PIVOTE'!E:E,'PP PRO PIVOTE'!AG:AG,F3)+SUMIFS('PP PRO PIVOTE'!E:E,'PP PRO PIVOTE'!AG:AG,G3)) -> 0.017611684 | J6: 23.83 | K6: 66.25 | L6: 59 | M6: 60.17 | N6: 76.83 | O6: 76.83 | P6: 108.58 | Q6: 80 | R6: 69.42 | S6: 88 | T6: 59.83 | U6: 18 | V6: 39.92 | W6: 14.67 | X6: 77.08 | Y6: ELECTRICAL ISSUE (0.17%) JALI CHANGE (0.43 %) MECHANICAL ISSUE(0.54%) TREET ISSUE (0.24%) OTHERS (0.39%) TOTAL=1.76%
A7: UNPLANED STOPPAGE TARGET (3 %) | C7: =IFERROR((C6/(SUMIFS('PP PRO PIVOTE'!$E:$E,'PP PRO PIVOTE'!$AG:$AG,MOR!C3))),"--") -> 0.010620915 | D7: =IFERROR((D6/(SUMIFS('PP PRO PIVOTE'!$E:$E,'PP PRO PIVOTE'!$AG:$AG,MOR!D3))),"--") -> 0.010030864 | E7: =IFERROR((E6/(SUMIFS('PP PRO PIVOTE'!$E:$E,'PP PRO PIVOTE'!$AG:$AG,MOR!E3))),"--") -> 0.032903439 | F7: =IFERROR((F6/(SUMIFS('PP PRO PIVOTE'!$E:$E,'PP PRO PIVOTE'!$AG:$AG,MOR!F3))),"--") -> 0.021680217 | G7: =IFERROR((G6/(SUMIFS('PP PRO PIVOTE'!$E:$E,'PP PRO PIVOTE'!$AG:$AG,MOR!G3))),"--") -> 0.010416667 | J7: 0.0164 | K7: 0.0289 | L7: 0.0229 | M7: 0.0206 | N7: 0.013 | O7: 0.0251 | P7: 0.0304 | Q7: 0.0181 | R7: 0.023 | S7: 0.0367 | T7: 0.0198 | U7: 0.0091 | V7: 0.0115 | W7: 0.0049 | X7: 0.0229
A8: TOTAL PRODUCTION KGs | C8: =SUMIFS(PP_PRD[NET WEIGHT],PP_PRD[WEEK NO.],MOR!C3) -> 12624.42 | D8: =SUMIFS(PP_PRD[NET WEIGHT],PP_PRD[WEEK NO.],MOR!D3) -> 18864.65 | E8: =SUMIFS(PP_PRD[NET WEIGHT],PP_PRD[WEEK NO.],MOR!E3) -> 14992.61 | F8: =SUMIFS(PP_PRD[NET WEIGHT],PP_PRD[WEEK NO.],MOR!F3) -> 13856.32 | G8: =SUMIFS(PP_PRD[NET WEIGHT],PP_PRD[WEEK NO.],MOR!G3) -> 8730.93 | H8: =SUM(C8:G8) -> 69068.93 | I8: =+$H$8/$H$9 -> 0.94805193 | J8: 40944 | K8: 67240.4 | L8: 81891 | M8: 85912 | N8: 78685 | O8: 83296.77 | P8: 101702 | Q8: 124628 | R8: 78393 | S8: 58995 | T8: 78391 | U8: 53727 | V8: 103091.48 | W8: 88615.86 | X8: 104314.84
A9: TARGET PRODUCTION TARGET | C9: =SUMIFS(PP_PRD[TARGET],PP_PRD[WEEK NO.],MOR!C3) -> 13295.72 | D9: =SUMIFS(PP_PRD[TARGET],PP_PRD[WEEK NO.],MOR!D3) -> 19834.09 | E9: =SUMIFS(PP_PRD[TARGET],PP_PRD[WEEK NO.],MOR!E3)+100 -> 15879.91 | F9: =SUMIFS(PP_PRD[TARGET],PP_PRD[WEEK NO.],MOR!F3) -> 14616.98 | G9: =SUMIFS(PP_PRD[TARGET],PP_PRD[WEEK NO.],MOR!G3) -> 9226.83 | H9: =SUM(C9:G9) -> 72853.53 | J9: 43274 | K9: 70965 | L9: 86398 | M9: 89984 | N9: 82656 | O9: 87222.1 | P9: 103702 | Q9: 125538 | R9: 81300 | S9: 61250 | T9: 81050 | U9: 55350 | V9: 104750 | W9: 90380 | X9: 105050
A10: PRODUCTION ACHIVEMENT (95 %) | C10: =IFERROR((C$8/C$9),"--") -> 0.94951007 | D10: =IFERROR((D$8/D$9),"--") -> 0.95112254 | E10: =IFERROR((E$8/E$9),"--") -> 0.94412437 | F10: =IFERROR((F$8/F$9),"--") -> 0.94796052 | G10: =IFERROR((G$8/G$9),"--") -> 0.94625456 | J10: 0.9461 | K10: 0.9475 | L10: 0.9478 | M10: 0.9547 | N10: 0.952 | O10: 0.955 | P10: 0.9807 | Q10: 0.9927 | R10: 0.9642 | S10: 0.9632 | T10: 0.9672 | U10: 0.9707 | V10: =+V8/V9 -> 0.98416687 | W10: =+W8/W9 -> 0.98048086 | X10: =+X8/X9 -> 0.99300181
A11: WASTAGE/KGS | C11: =SUMIFS(PP_PRD[PRD WATSE],PP_PRD[WEEK NO.],MOR!C3)+C26 -> 358.96134 | D11: =SUMIFS(PP_PRD[PRD WATSE],PP_PRD[WEEK NO.],MOR!D3)+D26 -> 628.80189 | E11: =SUMIFS(PP_PRD[PRD WATSE],PP_PRD[WEEK NO.],MOR!E3)+E26 -> 525.47169 | F11: =SUMIFS(PP_PRD[PRD WATSE],PP_PRD[WEEK NO.],MOR!F3)+F26 -> 394.47371 | G11: =SUMIFS(PP_PRD[PRD WATSE],PP_PRD[WEEK NO.],MOR!G3)+G26 -> 302.29138 | H11: =SUM(C11:G11) -> 2210 | I11: =+$H$11/$H$8 -> 0.031997021 | J11: 1868 | K11: 1884 | L11: 2760 | M11: 3091 | N11: 3425 | O11: 3760 | P11: 3347 | Q11: 3146 | R11: 2534 | S11: 2421 | T11: 3497 | U11: 1962 | V11: 2894.76 | W11: 2888 | X11: 2548
A12: WASTE TARGET (4 %) | C12: =IFERROR((C$11/C$8),"--") -> 0.028433887 | D12: =IFERROR((D$11/D$8),"--") -> 0.033332285 | E12: =IFERROR((E$11/E$8),"--") -> 0.035048713 | F12: =IFERROR((F$11/F$8),"--") -> 0.028468865 | G12: =IFERROR((G$11/G$8),"--") -> 0.034623044 | J12: 0.0456 | K12: 0.028 | L12: 0.0337 | M12: 0.036 | N12: 0.0435 | O12: 0.0451 | P12: 0.0329 | Q12: 0.0252 | R12: 0.0323 | S12: 0.041 | T12: 0.0446 | U12: 0.0365 | V12: 0.0281 | W12: 0.0326 | X12: 0.0244
A13: ROLL/BAGS WASTE | C13: 5039.95 | H13: =+R29 -> 14.448032 | I13: =+$C$13/$H$8 -> 0.072969858 | J13: - | K13: 0.0105 | L13: 0.0105 | M13: 0.0105 | N13: 0.0105
A14: ROLL/BAGS WASTAGE/VALUE | C14: {=IFERROR((((SUMIFS(KWH!$D:$D,KWH!$E:$E,MOR!F3)/(COUNT(_xlfn._xlws.FILTER(_xlfn._xlws.FILTER(KWH!$A:$F,KWH!$E:$E=F$3),{0,0,0,1,0,0})))))*C13),"0")} -> 2005900.1
A15: WASTAGE/VALUE | C15: {=IFERROR((((SUMIFS(KWH!$D:$D,KWH!$E:$E,MOR!C3)/(COUNT(_xlfn._xlws.FILTER(_xlfn._xlws.FILTER(KWH!$A:$F,KWH!$E:$E=C$3),{0,0,0,1,0,0})))))*C11),"0")} -> 142866.61 | D15: {=IFERROR((((SUMIFS(KWH!$D:$D,KWH!$E:$E,MOR!D3)/(COUNT(_xlfn._xlws.FILTER(_xlfn._xlws.FILTER(KWH!$A:$F,KWH!$E:$E=D$3),{0,0,0,1,0,0})))))*D11),"0")} -> 250263.15 | E15: {=IFERROR((((SUMIFS(KWH!$D:$D,KWH!$E:$E,MOR!E3)/(COUNT(_xlfn._xlws.FILTER(_xlfn._xlws.FILTER(KWH!$A:$F,KWH!$E:$E=E$3),{0,0,0,1,0,0})))))*E11),"0")} -> 209137.73 | F15: {=IFERROR((((SUMIFS(KWH!$D:$D,KWH!$E:$E,MOR!F3)/(COUNT(_xlfn._xlws.FILTER(_xlfn._xlws.FILTER(KWH!$A:$F,KWH!$E:$E=F$3),{0,0,0,1,0,0})))))*F11),"0")} -> 157000.54 | G15: {=IFERROR((((SUMIFS(KWH!$D:$D,KWH!$E:$E,MOR!G3)/(COUNT(_xlfn._xlws.FILTER(_xlfn._xlws.FILTER(KWH!$A:$F,KWH!$E:$E=G$3),{0,0,0,1,0,0})))))*G11),"0")} -> 120311.97 | H15: =SUM(C15:G15) -> 879580 | I15: =+P29 -> 6.3354101 | J15: 9.03 | K15: 5.7 | L15: 6.67 | M15: 7.12 | N15: 9.09 | O15: 9.74 | P15: 7.96 | Q15: 4.11 | R15: 5.27 | S15: 8.13 | T15: 8.83 | U15: 8.4 | V15: 5.56 | W15: 4.65 | X15: 5.62
A16: TOTAL KWH | C16: =SUMIFS(KWH!$B:$B,KWH!$E:$E,MOR!C3)-255.6 -> 7789 | D16: =SUMIFS(KWH!$B:$B,KWH!$E:$E,MOR!D3)-255.6 -> 9399.4 | E16: =SUMIFS(KWH!$B:$B,KWH!$E:$E,MOR!E3)-255.6 -> 9453.66 | F16: =SUMIFS(KWH!$B:$B,KWH!$E:$E,MOR!F3)-255.6 -> 7893.9 | G16: =SUMIFS(KWH!$B:$B,KWH!$E:$E,MOR!G3)-255.6 -> 5811.16 | H16: =SUM(C16:G16) -> 40347.12 | J16: 28174 | K16: 43331.51 | L16: 51278 | M16: 50078 | N16: 48350 | O16: 55045 | P16: 66102 | Q16: 77770 | R16: 50056 | S16: 38552 | T16: 45080 | U16: 28908 | V16: 53581 | W16: 47356 | X16: 57191
A17: KWH VALUE @ 44 | C17: =+C16*44 -> 342716 | D17: =+D16*44 -> 413573.6 | E17: =+E16*44 -> 415961.04 | F17: =+F16*44 -> 347331.6 | G17: =+G16*44 -> 255691.04 | H17: =SUM(C17:G17) -> 1775273.3 | J17: =+J16*44 -> 1239656 | K17: =+K16*44 -> 1906586.4 | L17: =+L16*44 -> 2256232 | M17: 2203418 | N17: 2127383 | O17: 2421965 | P17: 2904528 | Q17: 3421858 | R17: 2202464 | S17: 1696266 | T17: 1983520 | U17: 1271952 | V17: 2357564 | W17: =+W16*44 -> 2083664 | X17: 2516404
A18: KWH (TARGET 26/KG) | C18: =IFERROR((C17/C8),"0") -> 27.147069 | D18: =IFERROR((D17/D8),"0") -> 21.923206 | E18: =IFERROR((E17/E8),"0") -> 27.744405 | F18: =IFERROR((F17/F8),"0") -> 25.066656 | G18: =IFERROR((G17/G8),"0") -> 29.285659 | I18: =+H17/H8 -> 25.702921 | J18: 30.28 | K18: 28.36 | L18: =+L17/L8 -> 27.551648 | M18: 25.65 | N18: 27.04 | O18: 29.08 | P18: 28.56 | Q18: 27.46 | R18: 28.1 | S18: 28.75 | T18: 25.3 | U18: 23.67 | V18: 22.87 | W18: =+W17/W8 -> 23.513443 | X18: 24.12
A19: LABOR/KG | B19: VARIABLE | C19: 5.9167797 | D19: 5.6032272 | E19: 6.6596509 | F19: 9.611506 | G19: 11.11967 | H19: 7.17 | I19: =+D20+D21+F20+H19 -> 11.54 | J19: 16.24 | K19: 12.03 | L19: 8.86 | M19: 8.86 | N19: 9.23 | O19: 9.2 | P19: 10.33 | Q19: 9.0597551 | R19: 9.92 | S19: 10.78 | T19: 10.13 | U19: 8.6 | V19: 8.09 | W19: 7.03 | X19: 7.15
B20: FIXED | C20: STAFF+STORES | D20: 1.67 | E20: WELFARE | F20: 0.31
A21: OVERHEADS | C21: ADMIN | D21: 2.39 | E21: PACKING | F21: 0.76
C22: REPAIR | D22: 0.86 | E22: STORE & SPARES | F22: 1.17 | I22: =+D24+F21+D23+D22+F22+F23 -> 3.36 | J22: 6 | K22: 3.32 | L22: 4.08 | M22: 4.08 | N22: 2.05 | O22: 5.7 | P22: 6.97 | Q22: 4.84 | R22: 5.73 | S22: 7.14 | T22: 10.26 | U22: 4.86 | V22: 4.64 | W22: =0.01+0.11+0.01+0.59+0.05 -> 0.77 | X22: 1.11
C23: FREIGHT | E23: CORE | F23: 0.57
C24: RM GENERAL | E24: OTHERS
A25: CONVERSION COST | I25: =+I22+I19+I18+I15 -> 46.938332 | J25: 61.55 | K25: 49.25 | L25: =+L22+L19+L18+L15 -> 47.161648 | M25: =+M22+M19+M18+M15 -> 45.71 | N25: =+N22+N19+N18+N15 -> 47.41 | O25: 60.31 | P25: 51.22 | Q25: 45.47 | R25: 49.02 | S25: 54.8 | T25: 54.52 | U25: 45.53 | V25: =+V22+V19+V18+V15 -> 41.16 | W25: =+W22+W19+W18+W15 -> 35.963443 | X25: =+X22+X19+X18+X15 -> 38
C26: =$G$28/$H$8*C8 -> 199.96134 | D26: =$G$28/$H$8*D8 -> 298.80189 | E26: =$G$28/$H$8*E8 -> 237.47169 | F26: =$G$28/$H$8*F8 -> 219.47371 | G26: =$G$28/$H$8*G8 -> 138.29138 | I26: WASTE RATE | P26: 200 | Q26: WASTE RATE | R26: 200
E27: =2210-H11 -> 0 | F27: =3091/H8*C8 -> 564.97302 | G27: =+H11-2210 -> 0 | H27: 2210 | P27: =+H11*P26 -> 442000 | R27: =+C13*R26 -> 1007990
G28: 1094 | P28: =+H15-P27 -> 437580 | R28: =+C14-R27 -> 997910.1
I29: WASTE LOSS | P29: =+P28/H8 -> 6.3354101 | Q29: WASTE LOSS | R29: =+R28/$H$8 -> 14.448032
F32: 805 | G32: 1076.4
G33: 738.55
G34: 949.4
G35: 1035

Sheet KWH
A1: DATE | B1: PP | C1: LD | D1: RECIPE | E1: WEEK | F1: LD RECIPE
A2: 1-Oct-25 | B2: 1945 | C2: 2272 | D2: 398 | E2: 40 | F2: 372 | G2: 49
A3: 2-Oct-25 | B3: 2087 | C3: 2567 | D3: 398 | E3: 40 | F3: 372
A4: 3-Oct-25 | B4: 2040 | C4: 2864 | D4: 398 | E4: 40 | F4: 372
A5: 4-Oct-25 | B5: 2041 | C5: 2931 | D5: 398 | E5: 40 | F5: 372
A6: 5-Oct-25 | B6: 2044.5 | C6: 2856.5 | D6: 398 | E6: 40 | F6: 372
A7: 6-Oct-25 | B7: 2021.5 | C7: 2836.5 | D7: 398 | E7: 41 | F7: 372
A8: 7-Oct-25 | B8: 2048 | C8: 3082 | D8: 398 | E8: 41 | F8: 372
A9: 8-Oct-25 | B9: 1996.5 | C9: 2762.5 | D9: 398 | E9: 41 | F9: 372
A10: 9-Oct-25 | B10: 2129 | C10: 2361 | D10: 398 | E10: 41 | F10: 372
A11: 10-Oct-25 | B11: 2141.5 | C11: 2543.5 | D11: 398 | E11: 41 | F11: 372
A12: 11-Oct-25 | B12: 2009 | C12: 2336 | D12: 398 | E12: 41 | F12: 372
A13: 12-Oct-25 | B13: 1625 | C13: 2339 | D13: 398 | E13: 41 | F13: 372
A14: 13-Oct-25 | B14: 200.5 | C14: 2155.5 | D14: 398 | E14: 42 | F14: 372
... A20: 19-Oct-25 | B20: 1295.5 | C20: 1945.5 | D20: 398 | E20: 42 | F20: 372
A21: 45950 | B21: 268.74 | C21: 2841.74 | D21: 398 | E21: 43 | F21: 372
A22: 45951 | B22: 1401.58 | C22: 3008.58 | D22: 398 | E22: 43 | F22: 372
A23: 45952 | B23: 2077.08 | C23: 2827.08 | D23: 398 | E23: 43 | F23: 372
A24: 45953 | B24: 2136.28 | C24: 3083.28 | D24: 398 | E24: 43 | F24: 372
A25: 45954 | B25: 2195.44 | C25: 3140.44 | D25: 398 | E25: 43 | F25: 372
A26: 45955 | B26: 1812.82 | C26: 2870.82 | D26: 398 | E26: 43 | F26: 372
A27: 45956 | B27: 378.12 | C27: 3051.12 | D27: 398 | E27: 43 | F27: 372
A28: 45957 | B28: 1323.38 | C28: 3086.38 | D28: 398 | E28: 44 | F28: 372
A29: 45958 | B29: 1463.7 | C29: 2527.7 | D29: 398 | E29: 44 | F29: 372
A30: 45959 | B30: 1974.3 | C30: 2304.3 | D30: 398 | E30: 44 | F30: 372
A31: 45960 | B31: 2147.72 | C31: 2998.72 | D31: 398 | E31: 44 | F31: 372
A32: 45961 | B32: 1924.84 | C32: 3020.84 | D32: 398 | E32: 44 | F32: 372
... A93: 46022 | B93: 2267.82 | C93: 2234.82 | D93: 398 | E93: 53 | F93: 372
A94: 46023 | B94: 2239.92 | C94: 2232.92 | D94: 398 | E94: 54 | F94: 372 | G94: 53
A95: 46024 | B95: 2093.3 | C95: 2310.3 | D95: 398 | E95: 54 | F95: 372 | G95: 53
A96: 46025 | B96: 1923.86 | C96: 1799.86 | D96: 398 | E96: 54 | F96: 372 | G96: 53
A97: 46026 | B97: 1907.04 | C97: 162.04 | D97: 398 | E97: 54 | F97: 372 | G97: 53
A98: 46027 | B98: 1806.04 | C98: 1676.04 | D98: 398 | E98: 54 | F98: 372 | G98: 54
A99: 46028 | B99: 1905.56 | C99: 2311.56 | D99: 398 | E99: 54 | F99: 372 | G99: 54
A100: 46029 | B100: 1738.06 | C100: 2359.06 | D100: 398 | E100: 54 | F100: 372 | G100: 54
A101: 46030 | B101: 1793.72 | C101: 2433.72 | D101: 398 | E101: 54 | F101: 372 | G101: 54
A102: 46031 | B102: 1906.28 | C102: 2899.28 | D102: 398 | E102: 54 | F102: 372 | G102: 54
A103: 46032 | B103: 1535.72 | C103: 2712.72 | D103: 398 | E103: 54 | F103: 372 | G103: 54
A104: 46033 | B104: 1681.52 | C104: 2715.52 | D104: 398 | E104: 54 | F104: 372 | G104: 54
A105: 46034 | B105: 1906.4 | C105: 2725.4 | D105: 398 | E105: 55 | F105: 372 | G105: 55
...

Sheet TARGET
A1: PP | Q1: LD
B2: 1 | C2: 1 | D2: 2 | E2: 2 | F2: 3 | G2: 3 | H2: 4 | I2: 4 | J2: 5 | K2: 5 | L2: 6 | M2: 6 | Q2: 1 | R2: 1 | S2: 2 | T2: 2 | U2: 3 | V2: 3 | W2: 4 | X2: 4 | Y2: 5 | Z2: 5 | AA2: 6 | AB2: 6 | AC2: 7 | AD2: 7 | AE2: 8 | AF2: 8
A3: DATE | B3: A | C3: B | D3: A | E3: B | F3: A | G3: B | H3: A | I3: B | J3: A | K3: B | O3: WEEK | Q3: A | R3: B | S3: A | T3: B | U3: A | V3: B | W3: A | X3: B | Y3: A | Z3: B | AA3: A | AB3: B | AC3: A | AD3: B | AE3: A | AF3: B
A4: 46054 | N4: 0 | O4: 6 | Q4: 210 | R4: 220 | S4: 140 | T4: 170 | U4: 0 | V4: 0 | W4: 390 | X4: 390 | Y4: 0 | Z4: 0 | AA4: 0 | AB4: 0 | AC4: 500 | AD4: 800 | AE4: 500 | AF4: 500 | AG4: 3820
A5: 46055 | B5: 90 | C5: 125 | D5: 140 | E5: 180 | F5: 0 | G5: 0 | H5: 450 | I5: 800 | J5: 350 | K5: 500 | L5: 0 | M5: 0 | N5: 2635 | O5: 6 | Q5: 185 | R5: 185 | S5: 0 | T5: 0 | U5: 0 | V5: 0 | W5: 480 | X5: 480 | Y5: 0 | Z5: 0 | AA5: 0 | AB5: 0 | AC5: 850 | AD5: 700 | AE5: 400 | AF5: 400 | AG5: 3680
A6: 46056 | B6: 120 | C6: 120 | D6: 160 | E6: 160 | F6: 0 | G6: 0 | H6: 780 | I6: 750 | J6: 480 | K6: 500 | L6: 0 | M6: 0 | N6: 3070 | O6: 6 | Q6: 180 | R6: 180 | S6: 100 | T6: 0 | U6: 0 | V6: 0 | W6: 430 | X6: 430 | Y6: 0 | Z6: 0 | AA6: 0 | AB6: 0 | AC6: 720 | AD6: 720 | AE6: 410 | AF6: 340 | AG6: 3510
A7: 46057 | B7: 120 | C7: 120 | D7: 180 | E7: 180 | F7: 0 | G7: 0 | H7: 750 | I7: 750 | J7: 500 | K7: 500 | L7: 0 | M7: 0 | N7: 3100 | O7: 6 | Q7: 160 | R7: 160 | S7: 160 | T7: 180 | U7: 0 | V7: 0 | W7: 320 | X7: 400 | Y7: 0 | Z7: 0 | AA7: 0 | AB7: 0 | AC7: 700 | AD7: 700 | AE7: 300 | AF7: 330 | AG7: 3410
A8: 46058 | B8: 120 | C8: 120 | D8: 180 | E8: 180 | F8: 0 | G8: 0 | H8: 550 | I8: 500 | J8: 700 | K8: 620 | L8: 0 | M8: 0 | N8: 2970 | O8: 6 | Q8: 120 | R8: 150 | S8: 130 | T8: 130 | U8: 0 | V8: 0 | W8: 420 | X8: 400 | Y8: 0 | Z8: 0 | AA8: 0 | AB8: 0 | AC8: 530 | AD8: 460 | AE8: 500 | AF8: 430 | AG8: 3270
A9: 46062 | B9: 90 | C9: 150 | D9: 150 | E9: 210 | F9: 0 | G9: 0 | H9: 480 | I9: 700 | J9: 300 | K9: 600 | L9: 0 | M9: 0 | N9: 2680 | O9: 7 | Q9: 100 | R9: 140 | S9: 0 | T9: 0 | U9: 0 | V9: 0 | W9: 270 | X9: 420 | Y9: 0 | Z9: 450 | AA9: 0 | AB9: 0 | AC9: 0 | AD9: 450 | AE9: 360 | AF9: 550 | AG9: 2740
A10: 46063 | B10: 135 | C10: 135 | D10: 230 | E10: 230 | F10: 0 | G10: 0 | H10: 740 | I10: 740 | J10: 550 | K10: 500 | L10: 0 | M10: 0 | N10: 3260 | O10: 7 | Q10: 180 | R10: 180 | S10: 110 | T10: 145 | U10: 0 | V10: 0 | W10: 500 | X10: 400 | Y10: 400 | Z10: 380 | AA10: 0 | AB10: 0 | AC10: 800 | AD10: 900 | AE10: 500 | AF10: 450 | AG10: 4945
A11: 46064 | B11: 145 | C11: 145 | D11: 225 | E11: 225 | F11: 0 | G11: 0 | H11: 750 | I11: 70 | J11: 500 | K11: 420 | L11: 0 | M11: 0 | N11: 2480 | O11: 7 | Q11: 200 | R11: 230 | S11: 170 | T11: 100 | U11: 0 | V11: 0 | W11: 420 | X11: 390 | Y11: 340 | Z11: 300 | AA11: 410 | AB11: 650 | AC11: 600 | AD11: 800 | AE11: 400 | AF11: 340 | AG11: 5350
A12: 46065 | B12: 130 | C12: 130 | D12: 200 | E12: 200 | F12: 0 | G12: 0 | H12: 0 | I12: 450 | J12: 500 | K12: 500 | L12: 0 | M12: 0 | N12: 2110 | O12: 7 | Q12: 200 | R12: 200 | S12: 80 | T12: 80 | U12: 0 | V12: 0 | W12: 290 | X12: 350 | Y12: 490 | Z12: 450 | AA12: 600 | AB12: 600 | AC12: 800 | AD12: 800 | AE12: 500 | AF12: 500 | AG12: 5940
A13: 46066 | B13: 135 | C13: 135 | D13: 190 | E13: 190 | F13: 0 | G13: 0 | H13: 700 | I13: 1100 | J13: 500 | K13: 500 | L13: 0 | M13: 0 | N13: 3450 | O13: 7 | Q13: 200 | R13: 200 | S13: 100 | T13: 80 | U13: 0 | V13: 0 | W13: 500 | X13: 550 | Y13: 430 | Z13: 370 | AA13: 650 | AB13: 650 | AC13: 870 | AD13: 850 | AE13: 500 | AF13: 420 | AG13: 6370
A14: 46067 | B14: 140 | C14: 130 | D14: 180 | E14: 180 | F14: 0 | G14: 0 | H14: 780 | I14: 750 | J14: 200 | K14: 350 | L14: 0 | M14: 0 | N14: 2710 | O14: 7 | Q14: 200 | R14: 200 | S14: 100 | T14: 80 | U14: 0 | V14: 0 | W14: 500 | X14: 550 | Y14: 430 | Z14: 370 | AA14: 650 | AB14: 650 | AC14: 870 | AD14: 850 | AE14: 500 | AF14: 420 | AG14: 6370
A15: 46068 | B15: 140 | C15: 130 | D15: 180 | E15: 180 | F15: 0 | G15: 0 | H15: 780 | I15: 750 | J15: 200 | K15: 350 | L15: 0 | M15: 0 | N15: 2710 | O15: 7 | Q15: 160 | R15: 185 | S15: 160 | T15: 200 | U15: 0 | V15: 0 | W15: 400 | X15: 280 | Y15: 400 | Z15: 500 | AA15: 670 | AB15: 670 | AC15: 560 | AD15: 700 | AE15: 340 | AF15: 340 | AG15: 5565
