Workbook
Name Slicer_WEEK_NO.: #N/A

Sheet PT
L1: DAILY OPERATION REVIEW FLEXO PRINTING
A2: DATE | B2: SHIFT | C2: MACHINES | D2: سائز تبدیل | E2: کوالٹی CHANGE | F2: ھیٹنگ | I2: TOTAL MIN | J2: P.S HOURS | K2: الیکٹریکل | L2: ڈایی صاف | M2: مکینیکل | N2: سائز کم | O2: سیمپل چیک | P2: مال میں مسئلہ | Q2: جالی تبدیل | S2: TOTAL MIN | T2: U.P.S HOURS | U2: T.S HOURS | V2: RUNNING | W2: TOTAL HOURS | X2: WASTAGE/KGs | Y2: KWH/KG | Z2: TOTAL PRODUCTION | AA2: TARGET | AB2: RECIPE | AC2: WEEK NO. | AD2: REMARKS | AE2: ACTION | AF2: ACTION PLAN
A3: 45658 | B3: A | C3: 1 | I3: 0 | J3: 0 | Q3: 65 | S3: 65 | T3: 1.0833333 | U3: 1.0833333 | V3: 10.916667 | W3: 12 | X3: 0 | Z3: 130.1 | AA3: 150 | AC3: 1
A4: 45658 | B4: B | C4: 1 | I4: 0 | J4: 0 | S4: 0 | T4: 0 | U4: 0 | V4: 12 | W4: 12 | X4: 4 | Z4: 148.3 | AA4: 150 | AC4: 1
A5: 45658 | B5: A | C5: 3 | D5: 7 | I5: 7 | J5: 0.11666667 | S5: 0 | T5: 0 | U5: 0.11666667 | V5: 11.883333 | W5: 12 | X5: 44 | Z5: 474.4 | AA5: 450 | AC5: 1
A6: 45658 | B6: B | C6: 3 | I6: 0 | J6: 0 | S6: 0 | T6: 0 | U6: 0 | V6: 12 | W6: 12 | X6: 9 | Z6: 327.7 | AA6: 350 | AB6: 372 | AC6: 1
A7: 45658 | B7: A | C7: 5 | D7: 10 | I7: 10 | J7: 0.16666667 | N7: 10 | S7: 10 | T7: 0.16666667 | U7: 0.33333333 | V7: 11.666667 | W7: 12 | X7: 0 | Y7: 1832 | Z7: 471.4 | AA7: 450 | AC7: 1
A8: 45658 | B8: B | C8: 5 | D8: 10 | I8: 10 | J8: 0.16666667 | S8: 0 | T8: 0 | U8: 0.16666667 | V8: 11.833333 | W8: 12 | X8: 15.6 | Z8: 480.4 | AA8: 450 | AC8: 1
A9: 45658 | B9: A | C9: 7 | I9: 0 | J9: 0 | N9: 20 | S9: 20 | T9: 0.33333333 | U9: 0.33333333 | V9: 11.666667 | W9: 12 | X9: 0 | Z9: 587.2 | AA9: 600 | AC9: 1
A10: 45658 | B10: B | C10: 7 | D10: 2 | I10: 2 | J10: 0.033333333 | S10: 0 | T10: 0 | U10: 0.033333333 | V10: 11.966667 | W10: 12 | X10: 7.2 | Z10: 407.54 | AA10: 400 | AC10: 1
A11: 45659 | B11: A | C11: 1 | D11: 5 | I11: 5 | J11: 0.083333333 | S11: 0 | T11: 0 | U11: 0.083333333 | V11: 11.916667 | W11: 12 | X11: 20 | Z11: 186.56 | AA11: 200 | AC11: 1
A12: 45659 | B12: B | C12: 1 | I12: 0 | J12: 0 | S12: 0 | T12: 0 | U12: 0 | V12: 12 | W12: 12 | X12: 2 | Z12: 162 | AA12: 150 | AC12: 1
A13: 45659 | B13: A | C13: 3 | I13: 0 | J13: 0 | S13: 0 | T13: 0 | U13: 0 | V13: 12 | W13: 12 | X13: 0 | Z13: 360.2 | AA13: 350 | AB13: 372 | AC13: 1
A14: 45659 | B14: B | C14: 3 | I14: 0 | J14: 0 | S14: 0 | T14: 0 | U14: 0 | V14: 12 | W14: 12 | X14: 0 | Z14: 383 | AA14: 400 | AC14: 1
A15: 45659 | B15: A | C15: 5 | I15: 0 | J15: 0 | S15: 0 | T15: 0 | U15: 0 | V15: 12 | W15: 12 | X15: 0 | Z15: 495.6 | AA15: 500 | AC15: 1
A16: 45659 | B16: B | C16: 5 | I16: 0 | J16: 0 | S16: 0 | T16: 0 | U16: 0 | V16: 12 | W16: 12 | X16: 0 | Y16: 1886 | Z16: 84.8 | AA16: 100 | AC16: 1
A17: 45659 | B17: B | C17: 6 | F17: 180 | I17: 180 | J17: 3 | S17: 0 | T17: 0 | U17: 3 | V17: 9 | W17: 12 | X17: 36.2 | Z17: 451.26 | AA17: 450 | AC17: 1
A18: 45659 | B18: A | C18: 7 | I18: 0 | J18: 0 | S18: 0 | T18: 0 | U18: 0 | V18: 12 | W18: 12 | X18: 0 | Z18: 401.38 | AA18: 400 | AC18: 1
A19: 45659 | B19: B | C19: 7 | I19: 0 | J19: 0 | S19: 0 | T19: 0 | U19: 0 | V19: 12 | W19: 12 | X19: 13.9 | Z19: 412.58 | AA19: 400 | AC19: 1
A20: 45660 | B20: A | C20: 1 | I20: 0 | J20: 0 | S20: 0 | T20: 0 | U20: 0 | V20: 12 | W20: 12 | X20: 0 | Z20: 157.8 | AA20: 150 | AC20: 1
A21: 45660 | B21: B | C21: 1 | I21: 0 | J21: 0 | S21: 0 | T21: 0 | U21: 0 | V21: 12 | W21: 12 | X21: 0 | Z21: 200.4 | AA21: 200 | AC21: 1
A22: 45660 | B22: A | C22: 3 | I22: 0 | J22: 0 | S22: 0 | T22: 0 | U22: 0 | V22: 12 | W22: 12 | X22: 0 | Z22: 263.4 | AA22: 250 | AB22: 372 | AC22: 1
A23: 45660 | B23: B | C23: 3 | I23: 0 | J23: 0 | S23: 0 | T23: 0 | U23: 0 | V23: 12 | W23: 12 | X23: 0 | Y23: 1949 | Z23: 253.2 | AA23: 250 | AC23: 1
A24: 45660 | B24: A | C24: 6 | D24: 15 | I24: 15 | J24: 0.25 | N24: 5 | S24: 5 | T24: 0.083333333 | U24: 0.33333333 | V24: 11.666667 | W24: 12 | X24: 0 | Z24: 607 | AA24: 600 | AC24: 1
A25: 45660 | B25: B | C25: 6 | I25: 0 | J25: 0 | K25: 45 | S25: 45 | T25: 0.75 | U25: 0.75 | V25: 11.25 | W25: 12 | X25: 35 | Z25: 572 | AA25: 550 | AC25: 1
A26: 45660 | B26: A | C26: 7 | I26: 0 | J26: 0 | S26: 0 | T26: 0 | U26: 0 | V26: 12 | W26: 12 | X26: 0 | Z26: 522.16 | AA26: 500 | AC26: 1
A27: 45660 | B27: B | C27: 7 | I27: 0 | J27: 0 | S27: 0 | T27: 0 | U27: 0 | V27: 12 | W27: 12 | X27: 6.5 | Z27: 433.06 | AA27: 450 | AC27: 1
A28: 45661 | B28: A | C28: 1 | I28: 0 | J28: 0 | S28: 0 | T28: 0 | U28: 0 | V28: 12 | W28: 12 | X28: 0 | Z28: 175 | AA28: 200 | AC28: 1
A29: 45661 | B29: B | C29: 1 | I29: 0 | J29: 0 | S29: 0 | T29: 0 | U29: 0 | V29: 12 | W29: 12 | X29: 0 | Z29: 196.7 | AA29: 200 | AB29: 372 | AC29: 1
A30: 45661 | B30: A | C30: 3 | I30: 0 | J30: 0 | S30: 0 | T30: 0 | U30: 0 | V30: 12 | W30: 12 | X30: 38.2 | Z30: 428 | AA30: 400 | AC30: 1
A31: 45661 | B31: B | C31: 3 | E31: 25 | I31: 25 | J31: 0.41666667 | S31: 0 | T31: 0 | U31: 0.41666667 | V31: 11.583333 | W31: 12 | X31: 0 | Y31: 2149 | Z31: 644.4 | AA31: 650 | AC31: 1
A32: 45661 | B32: A | C32: 6 | I32: 0 | J32: 0 | S32: 0 | T32: 0 | U32: 0 | V32: 12 | W32: 12 | X32: 0 | Z32: 808.2 | AA32: 800 | AC32: 1
A33: 45661 | B33: B | C33: 6 | D33: 2 | I33: 2 | J33: 0.033333333 | N33: 10 | S33: 10 | T33: 0.16666667 | U33: 0.2 | V33: 11.8 | W33: 12 | X33: 0 | Z33: 944.4 | AA33: 950 | AC33: 1
A34: 45661 | B34: A | C34: 7 | I34: 0 | J34: 0 | S34: 0 | T34: 0 | U34: 0 | V34: 12 | W34: 12 | X34: 0 | Z34: 419.74 | AA34: 400 | AC34: 1
A35: 45661 | B35: B | C35: 7 | I35: 0 | J35: 0 | S35: 0 | T35: 0 | U35: 0 | V35: 12 | W35: 12 | X35: 35.2 | Z35: 490.27 | AA35: 500 | AC35: 1
A36: 45662 | B36: A | C36: 1 | I36: 0 | J36: 0 | S36: 0 | T36: 0 | U36: 0 | V36: 12 | W36: 12 | X36: 10 | Z36: 135.6 | AA36: 100 | AC36: 1
A37: 45662 | B37: B | C37: 1 | I37: 0 | J37: 0 | S37: 0 | T37: 0 | U37: 0 | V37: 12 | W37: 12 | X37: 0 | Z37: 564.3 | AA37: 550 | AC37: 1
A38: 45662 | B38: A | C38: 3 | I38: 0 | J38: 0 | S38: 0 | T38: 0 | U38: 0 | V38: 12 | W38: 12 | X38: 0 | Z38: 429.1 | AA38: 400 | AB38: 372 | AC38: 1
A39: 45662 | B39: B | C39: 3 | D39: 10 | I39: 10 | J39: 0.16666667 | S39: 0 | T39: 0 | U39: 0.16666667 | V39: 11.833333 | W39: 12 | X39: 0 | Z39: 557.4 | AA39: 550 | AC39: 1
A40: 45662 | B40: A | C40: 6 | D40: 5 | I40: 5 | J40: 0.083333333 | S40: 0 | T40: 0 | U40: 0.083333333 | V40: 11.916667 | W40: 12 | X40: 0 | Y40: 2297 | Z40: 810 | AA40: 800 | AC40: 1
...

Sheet LD PRO
A1: DATE | B1: SHIFT | C1: MCH# | D1: NET WEIGHT | E1: PRD WATSE | F1: کوالٹی CHANGE | G1: ھیٹنگ | H1: MACHINE ON | I1: TOTAL | J1: ACTION PLAN | K1: P.S HOURS | L1: الیکٹریکل | M1: ACTION | N1: REMARKS | O1: KWH/KG | P1: ڈایی صاف | Q1: مکینیکل | R1: سائز کم | S1: سیمپل چیک | T1: OTHER | U1: جالی تبدیل | V1: TREET | W1: TOTAL 2 | X1: U.P.S HOURS | Y1: T.S HOURS | Z1: RUNNING | AA1: TOTAL HOURS | AB1: WASTAGE/KGs | AC1: TARGET | AD1: RECIPE | AE1: TOTAL PRO | AF1: WEEK NO.
D3: Values
A4: DATE | B4: SHIFT | C4: MCH# | D4: Sum of NET WEIGHT | E4: Sum of PRD WATSE | F4: Sum of کوالٹی CHANGE | G4: Sum of ھیٹنگ | H4: Sum of MACHINE ON | I4: Sum of TOTAL MIN | J4: Count of ACTION PLAN | K4: Sum of P.S HOURS | L4: Sum of الیکٹریکل | M4: Count of ACTION | N4: Count of REMARKS | O4: Sum of KWH/KG | P4: Sum of ڈایی صاف | Q4: Sum of مکینیکل | R4: Sum of سائز کم | S4: Sum of سیمپل چیک | T4: Sum of OTHER | U4: Sum of جالی تبدیل | V4: Sum of TREET | W4: Sum of TOTAL MIN2 | X4: Sum of U.P.S HOURS | Y4: Sum of T.S HOURS | Z4: Sum of RUNNING | AA4: Min of TOTAL HOURS | AB4: Sum of WASTAGE/KGs | AC4: Sum of TARGET | AD4: Min of RECIPE | AE4: Sum of TOTAL PRODUCTION | AF4: Min of WEEK NO.
A5: 46113 | B5: A | C5: 1 | D5: 161.2 | E5: 4 | I5: 0 | K5: 0 | N5: 1 | W5: 0 | X5: 0 | Y5: 0 | Z5: 12 | AA5: 12 | AC5: 169.5 | AF5: 14
A6: 46113 | B6: A | C6: 4 | D6: 434 | E6: 100 | F6: 10 | I6: 10 | K6: 0.16666667 | N6: 2 | W6: 0 | X6: 0 | Y6: 0.16666667 | Z6: 23.833333 | AA6: 12 | AC6: 450 | AF6: 14
A7: 46113 | B7: A | C7: 5 | D7: 278.5 | E7: 3 | I7: 0 | K7: 0 | N7: 1 | W7: 0 | X7: 0 | Y7: 0 | Z7: 12 | AA7: 12 | AC7: 294 | AF7: 14
A8: 46113 | B8: A | C8: 6 | D8: 572.7 | E8: 4 | I8: 0 | K8: 0 | N8: 2 | W8: 0 | X8: 0 | Y8: 0 | Z8: 24 | AA8: 12 | AC8: 599.5 | AF8: 14
A9: 46113 | B9: A | C9: 7 | D9: 336.3 | E9: 6 | I9: 0 | K9: 0 | N9: 2 | Q9: 300 | R9: 20 | W9: 320 | X9: 5.3333333 | Y9: 5.3333333 | Z9: 18.666667 | AA9: 12 | AC9: 358.5 | AF9: 14
A10: 46113 | B10: A | C10: 8 | D10: 388.5 | E10: 13 | I10: 0 | K10: 0 | N10: 3 | W10: 0 | X10: 0 | Y10: 0 | Z10: 36 | AA10: 12 | AC10: 427.5 | AF10: 14
A11: 46113 | B11: B | C11: 1 | D11: 151.7 | E11: 2 | I11: 0 | K11: 0 | N11: 1 | W11: 0 | X11: 0 | Y11: 0 | Z11: 12 | AA11: 12 | AC11: 160 | AF11: 14
A12: 46113 | B12: B | C12: 2 | D12: 193.4 | G12: 120 | I12: 120 | K12: 2 | N12: 1 | W12: 0 | X12: 0 | Y12: 2 | Z12: 10 | AA12: 12 | AC12: 202.5 | AF12: 14
A13: 46113 | B13: B | C13: 4 | D13: 436 | I13: 0 | K13: 0 | N13: 1 | W13: 0 | X13: 0 | Y13: 0 | Z13: 12 | AA13: 12 | AC13: 448.5 | AF13: 14
A14: 46113 | B14: B | C14: 5 | D14: 297.4 | E14: 2 | I14: 0 | K14: 0 | N14: 1 | W14: 0 | X14: 0 | Y14: 0 | Z14: 12 | AA14: 12 | AC14: 309.4 | AF14: 14
A15: 46113 | B15: B | C15: 6 | D15: 545.3 | E15: 2 | I15: 0 | K15: 0 | N15: 1 | W15: 0 | X15: 0 | Y15: 0 | Z15: 12 | AA15: 12 | AC15: 562 | AF15: 14
A16: 46113 | B16: B | C16: 7 | D16: 281.3 | E16: 28 | G16: 240 | I16: 240 | K16: 4 | N16: 2 | W16: 0 | X16: 0 | Y16: 4 | Z16: 20 | AA16: 12 | AC16: 304.5 | AF16: 14
A17: 46113 | B17: B | C17: 8 | D17: 507 | E17: 25 | I17: 0 | K17: 0 | N17: 2 | W17: 0 | X17: 0 | Y17: 0 | Z17: 24 | AA17: 12 | AC17: 556 | AF17: 14
A18: 46114 | B18: A | C18: 1 | D18: 167.7 | E18: 2 | I18: 0 | K18: 0 | N18: 1 | W18: 0 | X18: 0 | Y18: 0 | Z18: 12 | AA18: 12 | AC18: 177.5 | AF18: 14
A19: 46114 | B19: A | C19: 2 | D19: 154.4 | E19: 2 | I19: 0 | K19: 0 | N19: 1 | W19: 0 | X19: 0 | Y19: 0 | Z19: 12 | AA19: 12 | AC19: 163 | AF19: 14
A20: 46114 | B20: A | C20: 4 | D20: 264.9 | E20: 25 | I20: 0 | K20: 0 | N20: 1 | T20: 240 | W20: 240 | X20: 4 | Y20: 4 | Z20: 8 | AA20: 12 | AC20: 275 | AF20: 14
A21: 46114 | B21: A | C21: 5 | D21: 272.7 | E21: 5 | I21: 0 | K21: 0 | N21: 1 | W21: 0 | X21: 0 | Y21: 0 | Z21: 12 | AA21: 12 | AC21: 285.5 | AF21: 14
A22: 46114 | B22: A | C22: 6 | D22: 608.6 | E22: 11 | I22: 0 | K22: 0 | N22: 1 | W22: 0 | X22: 0 | Y22: 0 | Z22: 12 | AA22: 12 | AC22: 631 | AF22: 14
A23: 46114 | B23: A | C23: 7 | D23: 338.4 | E23: 31 | I23: 0 | K23: 0 | N23: 2 | T23: 240 | W23: 240 | X23: 4 | Y23: 4 | Z23: 20 | AA23: 12 | AC23: 362 | AF23: 14
A24: 46114 | B24: A | C24: 8 | D24: 467.3 | E24: 9 | I24: 0 | K24: 0 | N24: 3 | W24: 0 | X24: 0 | Y24: 0 | Z24: 36 | AA24: 12 | AC24: 511 | AF24: 14
A25: 46114 | B25: B | C25: 1 | D25: 170.3 | E25: 2 | I25: 0 | K25: 0 | N25: 2 | W25: 0 | X25: 0 | Y25: 0 | Z25: 24 | AA25: 12 | AC25: 185 | AF25: 14
A26: 46114 | B26: B | C26: 2 | D26: 147.7 | E26: 2 | I26: 0 | K26: 0 | N26: 1 | W26: 0 | X26: 0 | Y26: 0 | Z26: 12 | AA26: 12 | AC26: 155.5 | AF26: 14
A27: 46114 | B27: B | C27: 4 | D27: 429.32 | E27: 9 | I27: 0 | K27: 0 | N27: 3 | W27: 0 | X27: 0 | Y27: 0 | Z27: 36 | AA27: 12 | AC27: 454 | AF27: 14
A28: 46114 | B28: B | C28: 5 | D28: 272.71 | E28: 5 | I28: 0 | K28: 0 | N28: 1 | W28: 0 | X28: 0 | Y28: 0 | Z28: 12 | AA28: 12 | AC28: 284.9 | AF28: 14
A29: 46114 | B29: B | C29: 6 | D29: 591.9 | E29: 9 | I29: 0 | K29: 0 | N29: 1 | W29: 0 | X29: 0 | Y29: 0 | Z29: 12 | AA29: 12 | AC29: 608.5 | AF29: 14
A30: 46114 | B30: B | C30: 7 | D30: 326.9 | E30: 68 | I30: 0 | K30: 0 | N30: 4 | W30: 0 | X30: 0 | Y30: 0 | Z30: 48 | AA30: 12 | AC30: 355.6 | AF30: 14
A31: 46114 | B31: B | C31: 8 | D31: 385.1 | E31: 7 | I31: 0 | K31: 0 | N31: 2 | W31: 0 | X31: 0 | Y31: 0 | Z31: 24 | AA31: 12 | AC31: 408.5 | AF31: 14
A32: 46115 | B32: A | C32: 1 | D32: 141.8 | E32: 1 | I32: 0 | K32: 0 | N32: 1 | W32: 0 | X32: 0 | Y32: 0 | Z32: 12 | AA32: 12 | AC32: 149.5 | AF32: 14
A33: 46115 | B33: A | C33: 2 | D33: 193.3 | E33: 3 | I33: 0 | K33: 0 | N33: 1 | W33: 0 | X33: 0 | Y33: 0 | Z33: 12 | AA33: 12 | AC33: 201.9 | AF33: 14
A34: 46115 | B34: A | C34: 4 | D34: 305 | E34: 56 | F34: 10 | I34: 10 | K34: 0.16666667 | N34: 3 | R34: 10 | W34: 10 | X34: 0.16666667 | Y34: 0.33333333 | Z34: 35.666667 | AA34: 12 | AC34: 329.5 | AF34: 14
A35: 46115 | B35: A | C35: 5 | D35: 292.8 | I35: 0 | K35: 0 | N35: 1 | W35: 0 | X35: 0 | Y35: 0 | Z35: 12 | AA35: 12 | AC35: 305 | AF35: 14
A36: 46115 | B36: A | C36: 6 | D36: 549.5 | E36: 11 | I36: 0 | K36: 0 | N36: 2 | W36: 0 | X36: 0 | Y36: 0 | Z36: 24 | AA36: 12 | AC36: 573 | AF36: 14
A37: 46115 | B37: A | C37: 7 | D37: 512.6 | E37: 35 | F37: 10 | I37: 10 | K37: 0.16666667 | N37: 3 | U37: 90 | W37: 90 | X37: 1.5 | Y37: 1.6666667 | Z37: 34.333333 | AA37: 12 | AC37: 543 | AF37: 14
A38: 46115 | B38: A | C38: 8 | D38: 533.2 | E38: 9 | I38: 0 | K38: 0 | N38: 5 | W38: 0 | X38: 0 | Y38: 0 | Z38: 60 | AA38: 12 | AC38: 580.5 | AF38: 14
A39: 46115 | B39: B | C39: 1 | D39: 140.5 | E39: 2 | I39: 0 | K39: 0 | N39: 1 | W39: 0 | X39: 0 | Y39: 0 | Z39: 12 | AA39: 12 | AC39: 148.5 | AF39: 14
A40: 46115 | B40: B | C40: 2 | D40: 198 | E40: 3 | I40: 0 | K40: 0 | N40: 1 | W40: 0 | X40: 0 | Y40: 0 | Z40: 12 | AA40: 12 | AC40: 206.6 | AF40: 14
A41: 46115 | B41: B | C41: 4 | D41: 288.1 | E41: 28 | F41: 5 | I41: 5 | K41: 0.083333333 | N41: 3 | W41: 0 | X41: 0 | Y41: 0.083333333 | Z41: 35.916667 | AA41: 12 | AC41: 311.5 | AF41: 14
...

Sheet WOR
A1: WEEKLY OPERATION REVIEW LD DEPARTMENT | N1: 46139 | O1: 17
A2: KPI | C2: MACHINES | K2: WEEK NO 17 | L2: % | M2: WEEK NO 16
C3: 1 | D3: =+C3+1 -> 2 | E3: =+D3+1 -> 3 | F3: =+E3+1 -> 4 | G3: =+F3+1 -> 5 | H3: =+G3+1 -> 6 | I3: =+H3+1 -> 7 | J3: =+I3+1 -> 8 | N3: REMARKS
A4: PLANED STOPPAGE HOURS | C4: =SUMIFS('LD PRO'!$K:$K,'LD PRO'!$C:$C,C$3,'LD PRO'!$AF:$AF,WOR!$O$1) -> 0.18333333 | D4: =SUMIFS('LD PRO'!$K:$K,'LD PRO'!$C:$C,D$3,'LD PRO'!$AF:$AF,WOR!$O$1) -> 0.18333333 | E4: =SUMIFS('LD PRO'!$K:$K,'LD PRO'!$C:$C,E$3,'LD PRO'!$AF:$AF,WOR!$O$1) -> 0 | F4: =SUMIFS('LD PRO'!$K:$K,'LD PRO'!$C:$C,F$3,'LD PRO'!$AF:$AF,WOR!$O$1) -> 7.2 | G4: =SUMIFS('LD PRO'!$K:$K,'LD PRO'!$C:$C,G$3,'LD PRO'!$AF:$AF,WOR!$O$1) -> 4.0833333 | H4: =SUMIFS('LD PRO'!$K:$K,'LD PRO'!$C:$C,H$3,'LD PRO'!$AF:$AF,WOR!$O$1) -> 0.6 | I4: =SUMIFS('LD PRO'!$K:$K,'LD PRO'!$C:$C,I$3,'LD PRO'!$AF:$AF,WOR!$O$1) -> 0 | J4: =SUMIFS('LD PRO'!$K:$K,'LD PRO'!$C:$C,J$3,'LD PRO'!$AF:$AF,WOR!$O$1) -> 0.15 | K4: =SUM(C4:J4) -> 12.4 | L4: =+K4/SUMIFS('LD PRO'!AA:AA,'LD PRO'!AF:AF,WOR!O1) -> 0.017514124 | M4: 10.17 | N4: SIZE CHANGE (0.62%) MACHINE ON/OFF (1.13%)
A5: PLANED STOPPAGE % (2 %) | C5: =IFERROR(+C4/SUMIFS('LD PRO'!$AA:$AA,'LD PRO'!$AF:$AF,WOR!$O$1,'LD PRO'!$C:$C,WOR!C3),"-") -> 0.0021825397 | D5: =IFERROR(+D4/SUMIFS('LD PRO'!$AA:$AA,'LD PRO'!$AF:$AF,WOR!$O$1,'LD PRO'!$C:$C,WOR!D3),"-") -> 0.0012731481 | E5: =IFERROR(+E4/SUMIFS('LD PRO'!$AA:$AA,'LD PRO'!$AF:$AF,WOR!$O$1,'LD PRO'!$C:$C,WOR!E3),"-") -> - | F5: =IFERROR(+F4/SUMIFS('LD PRO'!$AA:$AA,'LD PRO'!$AF:$AF,WOR!$O$1,'LD PRO'!$C:$C,WOR!F3),"-") -> 0.054545455 | G5: =IFERROR(+G4/SUMIFS('LD PRO'!$AA:$AA,'LD PRO'!$AF:$AF,WOR!$O$1,'LD PRO'!$C:$C,WOR!G3),"-") -> 0.068055556 | H5: =IFERROR(+H4/SUMIFS('LD PRO'!$AA:$AA,'LD PRO'!$AF:$AF,WOR!$O$1,'LD PRO'!$C:$C,WOR!H3),"-") -> 0.0035714286 | I5: =IFERROR(+I4/SUMIFS('LD PRO'!$AA:$AA,'LD PRO'!$AF:$AF,WOR!$O$1,'LD PRO'!$C:$C,WOR!I3),"-") -> - | J5: =IFERROR(+J4/SUMIFS('LD PRO'!$AA:$AA,'LD PRO'!$AF:$AF,WOR!$O$1,'LD PRO'!$C:$C,WOR!J3),"-") -> 0.00125 | M5: 0.0099
A6: UNPLANED STOPPAGE HOURS | C6: =SUMIFS('LD PRO'!$X:$X,'LD PRO'!$C:$C,C$3,'LD PRO'!$AF:$AF,WOR!$O$1) -> 0 | D6: =SUMIFS('LD PRO'!$X:$X,'LD PRO'!$C:$C,D$3,'LD PRO'!$AF:$AF,WOR!$O$1) -> 0 | E6: =SUMIFS('LD PRO'!$X:$X,'LD PRO'!$C:$C,E$3,'LD PRO'!$AF:$AF,WOR!$O$1) -> 0 | F6: =SUMIFS('LD PRO'!$X:$X,'LD PRO'!$C:$C,F$3,'LD PRO'!$AF:$AF,WOR!$O$1) -> 1.1666667 | G6: =SUMIFS('LD PRO'!$X:$X,'LD PRO'!$C:$C,G$3,'LD PRO'!$AF:$AF,WOR!$O$1) -> 0 | H6: =SUMIFS('LD PRO'!$X:$X,'LD PRO'!$C:$C,H$3,'LD PRO'!$AF:$AF,WOR!$O$1) -> 2.9166667 | I6: =SUMIFS('LD PRO'!$X:$X,'LD PRO'!$C:$C,I$3,'LD PRO'!$AF:$AF,WOR!$O$1) -> 0 | J6: =SUMIFS('LD PRO'!$X:$X,'LD PRO'!$C:$C,J$3,'LD PRO'!$AF:$AF,WOR!$O$1) -> 9 | K6: =SUM(C6:J6) -> 13.083333 | L6: =+K6/SUMIFS('LD PRO'!AA:AA,'LD PRO'!AF:AF,WOR!O1) -> 0.018479284 | M6: 5.67 | N6: MEHCANICAL ISSUE (1.41%) SIZE ISSUE (0.04%) JALI CHANGE (0.16%) TREET ISSUE (0.07%) SAPMLE (0.16%)
A7: UNPLANED STOPPAGE % (1.5%) | C7: =IFERROR(+C6/SUMIFS('LD PRO'!$AA:$AA,'LD PRO'!$AF:$AF,WOR!$O$1,'LD PRO'!$C:$C,WOR!C3),"-") -> 0 | D7: =IFERROR(+D6/SUMIFS('LD PRO'!$AA:$AA,'LD PRO'!$AF:$AF,WOR!$O$1,'LD PRO'!$C:$C,WOR!D3),"-") -> 0 | E7: =IFERROR(+E6/SUMIFS('LD PRO'!$AA:$AA,'LD PRO'!$AF:$AF,WOR!$O$1,'LD PRO'!$C:$C,WOR!E3),"-") -> - | F7: =IFERROR(+F6/SUMIFS('LD PRO'!$AA:$AA,'LD PRO'!$AF:$AF,WOR!$O$1,'LD PRO'!$C:$C,WOR!F3),"-") -> 0.0088383838 | G7: =IFERROR(+G6/SUMIFS('LD PRO'!$AA:$AA,'LD PRO'!$AF:$AF,WOR!$O$1,'LD PRO'!$C:$C,WOR!G3),"-") -> 0 | H7: =IFERROR(+H6/SUMIFS('LD PRO'!$AA:$AA,'LD PRO'!$AF:$AF,WOR!$O$1,'LD PRO'!$C:$C,WOR!H3),"-") -> 0.017361111 | I7: =IFERROR(+I6/SUMIFS('LD PRO'!$AA:$AA,'LD PRO'!$AF:$AF,WOR!$O$1,'LD PRO'!$C:$C,WOR!I3),"-") -> - | J7: =IFERROR(+J6/SUMIFS('LD PRO'!$AA:$AA,'LD PRO'!$AF:$AF,WOR!$O$1,'LD PRO'!$C:$C,WOR!J3),"-") -> 0.075 | M7: 0.0055
A8: TOTAL PRODUCTION KGs | C8: =SUMIFS('LD PRO'!$D:$D,'LD PRO'!$C:$C,C3,'LD PRO'!$AF:$AF,WOR!$O$1) -> 1021.1 | D8: =SUMIFS('LD PRO'!$D:$D,'LD PRO'!$C:$C,D3,'LD PRO'!$AF:$AF,WOR!$O$1) -> 1578.3 | E8: =SUMIFS('LD PRO'!$D:$D,'LD PRO'!$C:$C,E3,'LD PRO'!$AF:$AF,WOR!$O$1) -> 0 | F8: =SUMIFS('LD PRO'!$D:$D,'LD PRO'!$C:$C,F3,'LD PRO'!$AF:$AF,WOR!$O$1) -> 3468.65 | G8: =SUMIFS('LD PRO'!$D:$D,'LD PRO'!$C:$C,G3,'LD PRO'!$AF:$AF,WOR!$O$1) -> 985.2 | H8: =SUMIFS('LD PRO'!$D:$D,'LD PRO'!$C:$C,H3,'LD PRO'!$AF:$AF,WOR!$O$1) -> 7298.6 | I8: =SUMIFS('LD PRO'!$D:$D,'LD PRO'!$C:$C,I3,'LD PRO'!$AF:$AF,WOR!$O$1) -> 0 | J8: =SUMIFS('LD PRO'!$D:$D,'LD PRO'!$C:$C,J3,'LD PRO'!$AF:$AF,WOR!$O$1) -> 3409.6 | K8: =SUM(C8:J8) -> 17761.45 | L8: =+$K$8/$K$9 -> 0.94974414 | M8: 30639.57 | O8: =+K8-M8 -> -12878.12 | P8: WASTE RATE | Q8: 220
A9: TARGET PRODUCTION (95 %) | C9: =SUMIFS('[1]LD PRD'!$AN:$AN,'[1]LD PRD'!$AP:$AP,$O$1,'[1]LD PRD'!$B:$B,C3)-40 -> 1056 | D9: =SUMIFS('[1]LD PRD'!$AN:$AN,'[1]LD PRD'!$AP:$AP,$O$1,'[1]LD PRD'!$B:$B,D3)-40 -> 1648.9 | E9: =SUMIFS('[1]LD PRD'!$AN:$AN,'[1]LD PRD'!$AP:$AP,$O$1,'[1]LD PRD'!$B:$B,E3) -> 0 | F9: =SUMIFS('[1]LD PRD'!$AN:$AN,'[1]LD PRD'!$AP:$AP,$O$1,'[1]LD PRD'!$B:$B,F3) -> 3694.4 | G9: =SUMIFS('[1]LD PRD'!$AN:$AN,'[1]LD PRD'!$AP:$AP,$O$1,'[1]LD PRD'!$B:$B,G3) -> 1072 | H9: =SUMIFS('[1]LD PRD'!$AN:$AN,'[1]LD PRD'!$AP:$AP,$O$1,'[1]LD PRD'!$B:$B,H3) -> 7612.7 | I9: =SUMIFS('[1]LD PRD'!$AN:$AN,'[1]LD PRD'!$AP:$AP,$O$1,'[1]LD PRD'!$B:$B,I3) -> 0 | J9: =SUMIFS('[1]LD PRD'!$AN:$AN,'[1]LD PRD'!$AP:$AP,$O$1,'[1]LD PRD'!$B:$B,J3) -> 3617.3 | K9: =SUM(C9:J9) -> 18701.3 | M9: 32141 | Q9: =+K11*Q8 -> 204600
A10: PRODUCTION ACHIVEMENT % | C10: =IFERROR((C$8/C$9),"--") -> 0.96695076 | D10: =IFERROR((D$8/D$9),"--") -> 0.95718358 | E10: =IFERROR((E$8/E$9),"--") -> -- | F10: =IFERROR((F$8/F$9),"--") -> 0.938894 | G10: =IFERROR((G$8/G$9),"--") -> 0.91902985 | H10: =IFERROR((H$8/H$9),"--") -> 0.95874 | I10: =IFERROR((I$8/I$9),"--") -> -- | J10: =IFERROR((J$8/J$9),"--") -> 0.94258148 | M10: 0.9533 | Q10: =+K13-Q9 -> 141360
A11: WASTAGE/KGS | C11: =SUMIFS('LD PRO'!$E:$E,'LD PRO'!$C:$C,C3,'LD PRO'!$AF:$AF,WOR!$O$1)+C19 -> 33.818133 | D11: =SUMIFS('LD PRO'!$E:$E,'LD PRO'!$C:$C,D3,'LD PRO'!$AF:$AF,WOR!$O$1)+D19 -> 62.588198 | E11: =SUMIFS('LD PRO'!$E:$E,'LD PRO'!$C:$C,E3,'LD PRO'!$AF:$AF,WOR!$O$1)+E19 -> 0 | F11: =SUMIFS('LD PRO'!$E:$E,'LD PRO'!$C:$C,F3,'LD PRO'!$AF:$AF,WOR!$O$1)+F19 -> 236.60806 | G11: =SUMIFS('LD PRO'!$E:$E,'LD PRO'!$C:$C,G3,'LD PRO'!$AF:$AF,WOR!$O$1)+G19 -> 56.463152 | H11: =SUMIFS('LD PRO'!$E:$E,'LD PRO'!$C:$C,H3,'LD PRO'!$AF:$AF,WOR!$O$1)+H19 -> 371.82071 | I11: =SUMIFS('LD PRO'!$E:$E,'LD PRO'!$C:$C,I3,'LD PRO'!$AF:$AF,WOR!$O$1)+I19 -> 0 | J11: =SUMIFS('LD PRO'!$E:$E,'LD PRO'!$C:$C,J3,'LD PRO'!$AF:$AF,WOR!$O$1)+J19 -> 168.70175 | K11: =SUM(C11:J11) -> 930 | L11: =+$K$11/$K$8 -> 0.05236059 | M11: 2743.8 | P11: WASTE LOSS | Q11: =+Q10/K8 -> 7.9588097
A12: WASTAGE/% (4.5 %) | C12: =IFERROR((C$11/C$8),"--") -> 0.033119315 | D12: =IFERROR((D$11/D$8),"--") -> 0.039655451 | E12: =IFERROR((E$11/E$8),"--") -> -- | F12: =IFERROR((F$11/F$8),"--") -> 0.068213299 | G12: =IFERROR((G$11/G$8),"--") -> 0.05731136 | H12: =IFERROR((H$11/H$8),"--") -> 0.050944114 | I12: =IFERROR((I$11/I$8),"--") -> -- | J12: =IFERROR((J$11/J$8),"--") -> 0.049478458 | M12: 0.0896 | O12: PP+LD PRO
A13: WASTAGE/VALUE | C13: {=((SUMIFS([2]KWH!$F:$F,[2]KWH!$E:$E,WOR!$O$1)/(COUNT(_xlfn._xlws.FILTER(_xlfn._xlws.FILTER([2]KWH!$A:$F,[2]KWH!$E:$E=WOR!$O$1),{0,0,0,1,0,0}))))*C11)} -> 12580.345 | D13: {=((SUMIFS([2]KWH!$F:$F,[2]KWH!$E:$E,WOR!$O$1)/(COUNT(_xlfn._xlws.FILTER(_xlfn._xlws.FILTER([2]KWH!$A:$F,[2]KWH!$E:$E=WOR!$O$1),{0,0,0,1,0,0}))))*D11)} -> 23282.81 | E13: {=((SUMIFS([2]KWH!$F:$F,[2]KWH!$E:$E,WOR!$O$1)/(COUNT(_xlfn._xlws.FILTER(_xlfn._xlws.FILTER([2]KWH!$A:$F,[2]KWH!$E:$E=WOR!$O$1),{0,0,0,1,0,0}))))*E11)} -> 0 | F13: {=((SUMIFS([2]KWH!$F:$F,[2]KWH!$E:$E,WOR!$O$1)/(COUNT(_xlfn._xlws.FILTER(_xlfn._xlws.FILTER([2]KWH!$A:$F,[2]KWH!$E:$E=WOR!$O$1),{0,0,0,1,0,0}))))*F11)} -> 88018.199 | G13: {=((SUMIFS([2]KWH!$F:$F,[2]KWH!$E:$E,WOR!$O$1)/(COUNT(_xlfn._xlws.FILTER(_xlfn._xlws.FILTER([2]KWH!$A:$F,[2]KWH!$E:$E=WOR!$O$1),{0,0,0,1,0,0}))))*G11)} -> 21004.293 | H13: {=((SUMIFS([2]KWH!$F:$F,[2]KWH!$E:$E,WOR!$O$1)/(COUNT(_xlfn._xlws.FILTER(_xlfn._xlws.FILTER([2]KWH!$A:$F,[2]KWH!$E:$E=WOR!$O$1),{0,0,0,1,0,0}))))*H11)} -> 138317.3 | I13: {=((SUMIFS([2]KWH!$F:$F,[2]KWH!$E:$E,WOR!$O$1)/(COUNT(_xlfn._xlws.FILTER(_xlfn._xlws.FILTER([2]KWH!$A:$F,[2]KWH!$E:$E=WOR!$O$1),{0,0,0,1,0,0}))))*I11)} -> 0 | J13: {=((SUMIFS([2]KWH!$F:$F,[2]KWH!$E:$E,WOR!$O$1)/(COUNT(_xlfn._xlws.FILTER(_xlfn._xlws.FILTER([2]KWH!$A:$F,[2]KWH!$E:$E=WOR!$O$1),{0,0,0,1,0,0}))))*J11)} -> 62757.051 | K13: {=((SUMIFS([2]KWH!$F:$F,[2]KWH!$E:$E,WOR!$O$1)/(COUNT(_xlfn._xlws.FILTER(_xlfn._xlws.FILTER([2]KWH!$A:$F,[2]KWH!$E:$E=WOR!$O$1),{0,0,0,1,0,0}))))*K11)} -> 345960 | L13: =+$Q$11 -> 7.9588097 | M13: 13.61
A14: TOTAL KWH @ 44 | C14: =SUMIFS([2]KWH!$C:$C,[2]KWH!$E:$E,WOR!$O$1) -> 11343.5 | O14: =+K8+[2]WOR!$J$8 -> 31617.77
A15: KWH VALUE (26/KG) | C15: =+C14*44 -> 499114 | L15: =+$C$15/$K$8 -> 28.100971 | M15: 25.27 | O15: TOTAL EX | P15: LD PRO | Q15: LD STORE EX
A16: LABOR/KG | B16: VARIABLE | C16: =((236000)/26)*7 -> 63538.462 | F16: =C16/$K$8 -> 3.577324 | G16: ADMIN | H16: 150000 | J16: =((H16/26)*7)/K8 -> 2.2737229 | K16: =+F16+J17+J16 -> 9.5458466 | M16: 5.53 | O16: 180470.25 | P16: =+K8 -> 17761.45 | Q16: =+P16*O18 -> 101380.12
B17: FIXED | C17: FOREMANS | E17: =((115500/26)*7)/$K$8 -> 1.7507666 | I17: STAFF | J17: =(((128250/26)*7)/K8)+E17 -> 3.6947997 | N17: =+M18+M16+M15+M13 -> 46.85 | P17: PP PRO | Q17: PP STORE EX
A18: STORE EXPENSE | C18: =+Q16 -> 101380.12 | F18: REPAIR | K18: =+(C18+H18)/K8 -> 5.7078741 | M18: 2.44 | N18: =+K18+K16+L15+L13 -> 51.313502 | O18: =+O16/O14 -> 5.7078741 | P18: =+[2]WOR!$J$8 -> 13856.32 | Q18: =+P18*O18 -> 79090.13
C19: =($N$22/$K$8)*C8 -> 24.318133 | D19: =($N$22/$K$8)*D8 -> 37.588198 | E19: =($N$22/$K$8)*E8 -> 0 | F19: =($N$22/$K$8)*F8 -> 82.608061 | G19: =($N$22/$K$8)*G8 -> 23.463152 | H19: =($N$22/$K$8)*H8 -> 173.82071 | I19: =($N$22/$K$8)*I8 -> 0 | J19: =($N$22/$K$8)*J8 -> 81.201749
K20: 1626
G21: 82795 | M21: tr# | N21: 930 | O21: =+N21-K11 -> 0
G22: =+G21/2 -> 41397.5 | I22: =429960/2 -> 214980 | M22: diff | N22: 423
K24: store | L24: 97295
K25: repair | L25: 5074
D39: =35000*20% -> 7000
D40: =+D39+35000 -> 42000

Sheet MOR
A1: MONTHLY OPERATION REVIEW LD DEPARTMENT | X1: 46113
A2: KPI | C2: MACHINES | H2: MONTH OF APR | I2: % | J2: MONTH OF MAR | K2: MONTH OF FEB | L2: MONTH OF JAN | M2: MONTH OF DEC | N2: MONTH OF NOV | O2: MONTH OF OCT | P2: MONTH OF SEP | Q2: MONTH OF AUG | R2: MONTH OF JUL | S2: MONTH OF JUN | T2: MONTH OF MAY | U2: MONTH OF APR | V2: MONTH OF MAR | W2: MONTH OF FEB
C3: 14 | D3: =+C3+1 -> 15 | E3: =+D3+1 -> 16 | F3: =+E3+1 -> 17 | G3: =+F3+1 -> 18 | X3: REMARKS
A4: PLANED STOPPAGE HOURS | C4: =SUMIFS('LD PRO'!$K:$K,'LD PRO'!$AF:$AF,MOR!C3) -> 6.6666667 | D4: =SUMIFS('LD PRO'!$K:$K,'LD PRO'!$AF:$AF,MOR!D3) -> 2.9166667 | E4: =SUMIFS('LD PRO'!$K:$K,'LD PRO'!$AF:$AF,MOR!E3) -> 10.166667 | F4: =SUMIFS('LD PRO'!$K:$K,'LD PRO'!$AF:$AF,MOR!F3) -> 12.4 | G4: =SUMIFS('LD PRO'!$K:$K,'LD PRO'!$AF:$AF,MOR!G3) -> 8.9166667 | H4: =SUM(C4:G4) -> 41.066667 | I4: =SUM('LD PRO'!K:K)/SUM('LD PRO'!AA:AA) -> 0.0099194847 | J4: 57.7 | K4: 64.8 | L4: 56.38 | M4: 79.48 | N4: 132.15 | O4: 93.58 | P4: 71.1 | Q4: 34.233333 | R4: 68.59 | S4: 30.13 | T4: 28.3 | U4: 27.73 | V4: 30.85 | W4: 16.03 | X4: Size Change 0.32% + MACHINE ON/OFF 0.67%
A5: PLANED STOPPAGE TARGET(2%) | C5: =IFERROR((C4/(SUMIFS('LD PRO'!$AA:$AA,'LD PRO'!$AF:$AF,MOR!C3))),"--") -> 0.0080515298 | D5: =IFERROR((D4/(SUMIFS('LD PRO'!$AA:$AA,'LD PRO'!$AF:$AF,MOR!D3))),"--") -> 0.0027006173 | E5: =IFERROR((E4/(SUMIFS('LD PRO'!$AA:$AA,'LD PRO'!$AF:$AF,MOR!E3))),"--") -> 0.0098514212 | F5: =IFERROR((F4/(SUMIFS('LD PRO'!$AA:$AA,'LD PRO'!$AF:$AF,MOR!F3))),"--") -> 0.017514124 | G5: =IFERROR((G4/(SUMIFS('LD PRO'!$AA:$AA,'LD PRO'!$AF:$AF,MOR!G3))),"--") -> 0.018123306 | J5: 0.0194 | K5: 0.0181 | L5: 0.0155 | M5: 0.0208 | N5: 0.0347 | O5: 0.0205 | P5: 0.0211 | Q5: 0.0099 | R5: 0.0217 | S5: 0.0123 | T5: 0.0084 | U5: 0.0115 | V5: 0.0117 | W5: 0.0059
A6: UNPLANED STOPPAGE HOURS | C6: =SUMIFS('LD PRO'!$X:$X,'LD PRO'!$AF:$AF,MOR!C3) -> 19 | D6: =SUMIFS('LD PRO'!$X:$X,'LD PRO'!$AF:$AF,MOR!D3) -> 2.8333333 | E6: =SUMIFS('LD PRO'!$X:$X,'LD PRO'!$AF:$AF,MOR!E3) -> 5.6666667 | F6: =SUMIFS('LD PRO'!$X:$X,'LD PRO'!$AF:$AF,MOR!F3) -> 13.083333 | G6: =SUMIFS('LD PRO'!$X:$X,'LD PRO'!$AF:$AF,MOR!G3) -> 1.3833333 | H6: =SUM(C6:G6) -> 41.966667 | I6: =SUM('LD PRO'!X:X)/SUM('LD PRO'!AA:AA) -> 0.010136876 | J6: 20 | K6: 37.63 | L6: 8.47 | M6: 28.3 | N6: 33.27 | O6: 70.53 | P6: 73.42 | Q6: 70.85 | R6: 75.9 | S6: 36.97 | T6: 73 | U6: 33.05 | V6: 40.3 | W6: 24.75 | X6: DAI CLEAN (0.01%) SIZE ISSUE(0.04%) JALI CHANGE (0.11 %),MECHANICAL ISSUE (0.50%) SAMPLE (0.14%) OTHERS (0.19%) TREET ISSUE(0.01%)
A7: UNPLANED STOPPAGE TARGET(1.5%) | C7: =IFERROR((C6/(SUMIFS('LD PRO'!$AA:$AA,'LD PRO'!$AF:$AF,MOR!C3))),"--") -> 0.02294686 | D7: =IFERROR((D6/(SUMIFS('LD PRO'!$AA:$AA,'LD PRO'!$AF:$AF,MOR!D3))),"--") -> 0.0026234568 | E7: =IFERROR((E6/(SUMIFS('LD PRO'!$AA:$AA,'LD PRO'!$AF:$AF,MOR!E3))),"--") -> 0.0054909561 | F7: =IFERROR((F6/(SUMIFS('LD PRO'!$AA:$AA,'LD PRO'!$AF:$AF,MOR!F3))),"--") -> 0.018479284 | G7: =IFERROR((G6/(SUMIFS('LD PRO'!$AA:$AA,'LD PRO'!$AF:$AF,MOR!G3))),"--") -> 0.0028116531 | J7: 0.0067 | K7: 0.0105 | L7: 0.0023 | M7: 0.0074 | N7: 0.0087 | O7: 0.0154 | P7: 0.0218 | Q7: 0.0206 | R7: 0.024 | S7: 0.0151 | T7: 0.0217 | U7: 0.0137 | V7: 0.0153 | W7: 0.0091
A8: TOTAL PRODUCTION KGs | C8: =SUMIFS('LD PRO'!$D:$D,'LD PRO'!$AF:$AF,MOR!C3) -> 24062.33 | D8: =SUMIFS('LD PRO'!$D:$D,'LD PRO'!$AF:$AF,MOR!D3) -> 35370.95 | E8: =SUMIFS('LD PRO'!$D:$D,'LD PRO'!$AF:$AF,MOR!E3) -> 30639.57 | F8: =SUMIFS('LD PRO'!$D:$D,'LD PRO'!$AF:$AF,MOR!F3) -> 17761.45 | G8: =SUMIFS('LD PRO'!$D:$D,'LD PRO'!$AF:$AF,MOR!G3) -> 10790.1 | H8: =SUM(C8:G8) -> 118624.4 | I8: =+$H$8/$H$9 -> 0.95022388 | J8: 87392 | K8: 108010 | L8: 108283 | M8: 140403 | N8: 136620 | O8: 130657 | P8: 96689 | Q8: 97861.76 | R8: 92549 | S8: 71426 | T8: 99398 | U8: 79599 | V8: 90537.99 | W8: 92723.29
A9: TARGET PRODUCTION | C9: =SUMIFS('LD PRO'!$AC:$AC,'LD PRO'!$AF:$AF,MOR!C3) -> 25361.4 | D9: =SUMIFS('LD PRO'!$AC:$AC,'LD PRO'!$AF:$AF,MOR!D3)-200 -> 36881.15 | E9: =SUMIFS('LD PRO'!$AC:$AC,'LD PRO'!$AF:$AF,MOR!E3) -> 32241.15 | F9: =SUMIFS('LD PRO'!$AC:$AC,'LD PRO'!$AF:$AF,MOR!F3) -> 18781.3 | G9: =SUMIFS('LD PRO'!$AC:$AC,'LD PRO'!$AF:$AF,MOR!G3) -> 11573.37 | H9: =SUM(C9:G9) -> 124838.37 | J9: 92327 | K9: 113970 | L9: 114237 | M9: 147058 | N9: 142377 | O9: 136825 | P9: 97853 | Q9: 99884 | R9: 95400 | S9: 74050 | T9: 101750 | U9: 81950 | V9: 91750 | W9: 94000
A10: PRODUCTION ACHIVEMENT TARGET(95%) | C10: =IFERROR((C$8/C$9),"--") -> 0.94877767 | D10: =IFERROR((D$8/D$9),"--") -> 0.95905225 | E10: =IFERROR((E$8/E$9),"--") -> 0.95032497 | F10: =IFERROR((F$8/F$9),"--") -> 0.94569865 | G10: =IFERROR((G$8/G$9),"--") -> 0.93232135 | J10: 0.9466 | K10: 0.9477 | L10: 0.9479 | M10: 0.9547 | N10: 0.9596 | O10: 0.9549 | P10: 0.9881 | Q10: 0.9798 | R10: 0.9701 | S10: 0.9646 | T10: 0.9769 | U10: 0.9713 | V10: =+V8/V9 -> 0.98679008 | W10: =+W8/W9 -> 0.98641798
A11: WASTAGE/KGS | C11: =SUMIFS('LD PRO'!$E:$E,'LD PRO'!$AF:$AF,MOR!C3)+C26 -> 1383.3728 | D11: =SUMIFS('LD PRO'!$E:$E,'LD PRO'!$AF:$AF,MOR!D3)+D26 -> 1705.2759 | E11: =SUMIFS('LD PRO'!$E:$E,'LD PRO'!$AF:$AF,MOR!E3)+E26 -> 1580.9727 | F11: =SUMIFS('LD PRO'!$E:$E,'LD PRO'!$AF:$AF,MOR!F3)+F26 -> 894.79674 | G11: =SUMIFS('LD PRO'!$E:$E,'LD PRO'!$AF:$AF,MOR!G3) -> 553.5 | H11: =SUM(C11:G11) -> 6117.9181 | I11: =+$H$11/$H$8 -> 0.051573859 | J11: 4874 | K11: 5556 | L11: 5536 | M11: 6802 | N11: 8710 | O11: 13444 | P11: 5918 | Q11: 6141.22 | R11: 4664 | S11: 4041 | T11: 4483 | U11: 3186 | V11: 6660.2 | W11: 3510.9
A12: WASTE TARGET(4.5 % ) | C12: =IFERROR((C$11/C$8),"--") -> 0.057491222 | D12: =IFERROR((D$11/D$8),"--") -> 0.048211198 | E12: =IFERROR((E$11/E$8),"--") -> 0.05159905 | F12: =IFERROR((F$11/F$8),"--") -> 0.050378586 | G12: =IFERROR((G$11/G$8),"--") -> 0.051297022 | J12: 0.0558 | K12: 0.0514 | L12: 0.0511 | M12: 0.0484 | N12: 0.0638 | O12: 0.1029 | P12: 0.0612 | Q12: 0.0628 | R12: 0.0504 | S12: 0.0566 | T12: 0.0451 | U12: 0.04 | V12: 0.0736 | W12: 0.0379
A13: WASTAGE/VALUE | C13: {=IFERROR(((SUMIFS(KWH!$F:$F,KWH!$E:$E,C3)/(COUNT(_xlfn._xlws.FILTER(_xlfn._xlws.FILTER(KWH!$A:$F,KWH!$E:$E=C3),{0,0,0,0,0,1}))))*C11),"0")} -> 514614.66 | D13: {=IFERROR(((SUMIFS(KWH!$F:$F,KWH!$E:$E,D3)/(COUNT(_xlfn._xlws.FILTER(_xlfn._xlws.FILTER(KWH!$A:$F,KWH!$E:$E=D3),{0,0,0,0,0,1}))))*D11),"0")} -> 634362.62 | E13: {=IFERROR(((SUMIFS(KWH!$F:$F,KWH!$E:$E,E3)/(COUNT(_xlfn._xlws.FILTER(_xlfn._xlws.FILTER(KWH!$A:$F,KWH!$E:$E=E3),{0,0,0,0,0,1}))))*E11),"0")} -> 588121.85 | F13: {=IFERROR(((SUMIFS(KWH!$F:$F,KWH!$E:$E,F3)/(COUNT(_xlfn._xlws.FILTER(_xlfn._xlws.FILTER(KWH!$A:$F,KWH!$E:$E=F3),{0,0,0,0,0,1}))))*F11),"-")} -> 332864.39 | G13: {=IFERROR(((SUMIFS(KWH!$F:$F,KWH!$E:$E,G3)/(COUNT(_xlfn._xlws.FILTER(_xlfn._xlws.FILTER(KWH!$A:$F,KWH!$E:$E=G3),{0,0,0,0,0,1}))))*G11),"0")} -> 205902 | H13: =SUM(C13:G13) -> 2275865.5 | I13: =+H29 -> 7.8392265 | J13: 8.48 | K13: 7.81 | L13: 7.77 | M13: 7.36 | N13: 9.69 | O13: 15.66 | P13: 8.63 | Q13: 8.28 | R13: 6.65 | S13: 8.2 | T13: 5.95 | U13: 6.43 | V13: 10.37 | W13: 5.34
A14: ROLL WASTE | C14: 1035 | I14: =+$C$14/$H$8 -> 0.0087250178 | J14: 0.072 | K14: 0.014 | L14: 0.014 | M14: 0.014 | N14: 0.014 | O14: 3.45
A15: WASTAGE/VALUE | C15: {=IFERROR(((SUMIFS([2]KWH!$F:$F,[2]KWH!$E:$E,C3)/(COUNT(_xlfn._xlws.FILTER(_xlfn._xlws.FILTER([2]KWH!$A:$F,[2]KWH!$E:$E=C3),{0,0,0,0,0,1}))))*C14),"0")} -> 385020 | H15: =+P29 -> 1.3262027
A16: TOTAL KWH | C16: =SUMIFS(KWH!$C:$C,KWH!$E:$E,MOR!C3)-1055.6 -> 17074.76 | D16: =SUMIFS(KWH!$C:$C,KWH!$E:$E,MOR!D3)-1055.6 -> 17382.4 | E16: =SUMIFS(KWH!$C:$C,KWH!$E:$E,MOR!E3)-1055.6 -> 16544.66 | F16: =SUMIFS(KWH!$C:$C,KWH!$E:$E,MOR!F3)-1055.6 -> 10287.9 | G16: =SUMIFS(KWH!$C:$C,KWH!$E:$E,MOR!G3)-1055.6 -> 6072.16 | H16: =SUM(C16:G16) -> 67361.88 | J16: 52514 | K16: 64987.7 | L16: 65452 | M16: 72866 | N16: 72055 | O16: 75416 | P16: 58943 | Q16: 59604 | R16: 54386 | S16: 43049 | T16: 61584 | U16: 46211 | V16: 51018 | W16: 53168
A17: KWH VALUE @ 44 | C17: =+C16*44 -> 751289.44 | D17: =+D16*44 -> 764825.6 | E17: =+E16*44 -> 727965.04 | F17: =+F16*44 -> 452667.6 | G17: =+G16*44 -> 267175.04 | H17: =+H16*44 -> 2963922.7 | J17: =+J16*44 -> 2310616 | K17: =+K16*44 -> 2859458.8 | L17: =+L16*44 -> 2879888 | M17: =+M16*44 -> 3206104 | N17: =+N16*44 -> 3170420 | O17: =+O16*44 -> 3318304 | P17: =+P16*44 -> 2593492 | Q17: 2622576 | R17: 2392962 | S17: 1894134 | T17: 2709696 | U17: 2033284 | V17: 2244792 | W17: =+W16*44 -> 2339392
A18: KWH VALUE TARGET(26/KG) | C18: =IFERROR((C17/C8),"-") -> 31.222639 | D18: =IFERROR((D17/D8),"-") -> 21.622987 | E18: =IFERROR((E17/E8),"-") -> 23.758984 | F18: =IFERROR((F17/F8),"-") -> 25.48596 | G18: =IFERROR((G17/G8),"-") -> 24.761127 | I18: =+H17/H8 -> 24.985776 | J18: 26.44 | K18: 26.47 | L18: 26.6 | M18: 22.83 | N18: 23.21 | O18: 25.4 | P18: 26.82 | Q18: =+Q17/Q8 -> 26.798782 | R18: 25.86 | S18: 26.52 | T18: 27.26 | U18: 25.54 | V18: 24.79 | W18: =+W17/W8 -> 25.229821
A19: LABOR/KG | B19: VARIABLE | C19: 5.9167797 | D19: 5.6032272 | E19: 6.6596509 | F19: 9.611506 | G19: 11.11967 | H19: 7.17 | I19: =+D20+D21+F20+H19 -> 11.54 | J19: 16.24 | K19: 12.03 | L19: 8.86 | M19: 8.86 | N19: 9.23 | O19: 9.2 | P19: 10.33 | Q19: 10.31 | R19: 9.89 | S19: 10.78 | T19: 10.13 | U19: 8.6 | V19: 8.26 | W19: 7.03
B20: FIXED | C20: STAFF+STORES | D20: 1.67 | E20: WELFARE | F20: 0.31
A21: OVERHEADS | C21: ADMIN | D21: 2.39 | E21: PACKING | F21: 0.76
C22: REPAIR | D22: 0.86 | E22: STORE & SPARES | F22: 1.17 | I22: =+D24+F21+D23+D22+F22+F23+F24 -> 3.36 | J22: 6 | K22: 3.32 | L22: 4.08 | M22: 4.08 | N22: 2.05 | O22: 5.7 | P22: 6.97 | Q22: 4.84 | R22: 5.73 | S22: 7.14 | T22: 10.26 | U22: 4.86 | V22: 4.64 | W22: =0.01+0.11+0.01+0.59+0.05 -> 0.77
C23: FREIGHT | E23: CORE | F23: 0.57
C24: RM GENERAL | E24: OTHERS
A25: CONVERSION COST | I25: =+I22+I19+I18+I13 -> 47.725003 | J25: =+J22+J19+J18+J13 -> 57.16 | K25: =+K22+K19+K18+K13 -> 49.63 | L25: =+L22+L19+L18+L13 -> 47.31 | M25: =+M22+M19+M18+M13 -> 43.13 | N25: =+N22+N19+N18+N13 -> 44.18 | O25: =+O22+O19+O18+O13 -> 55.96 | P25: =+P22+P19+P18+P13 -> 52.75 | Q25: 50.24 | R25: 48.13 | S25: 52.64 | T25: 53.6 | U25: 45.44 | V25: =+V22+V19+V18+V13 -> 48.06 | W25: =+W22+W19+W18+W13 -> 38.369821
B26: =+$D$29/$H$8*C8 -> 525.36775 | C26: =+$D$29/$H$8*C8 -> 525.36775 | D26: =+$D$29/$H$8*D8 -> 772.27586 | E26: =+$D$29/$H$8*E8 -> 668.97271 | F26: =+$D$29/$H$8*F8 -> 387.79674 | G26: WASTE RATE | H26: 220 | I26: WASTE RATE | P26: 220
H27: =+H11*H26 -> 1345942 | P27: =+C14*P26 -> 227700
E28: 6354 | H28: =+H13-H27 -> 929923.55 | P28: =+C15-P27 -> 157320
D29: 2590 | E29: =+E28-H11 -> 236.08194 | G29: WASTE LOSS | H29: =+H28/H8 -> 7.8392265 | I29: WASTE LOSS | P29: =+P28/$H$8 -> 1.3262027

Sheet KWH
A1: DATE | B1: PP | C1: LD | D1: RECIPE | E1: WEEK | F1: LD RECIPE
A2: 1-Oct-25 | B2: 1945 | C2: 2272 | D2: 398 | E2: 40 | F2: 372 | G2: 49
A3: 2-Oct-25 | B3: 2087 | C3: 2567 | D3: 398 | E3: 40 | F3: 372
A4: 3-Oct-25 | B4: 2040 | C4: 2864 | D4: 398 | E4: 40 | F4: 372
A5: 4-Oct-25 | B5: 2041 | C5: 2931 | D5: 398 | E5: 40 | F5: 372
A6: 5-Oct-25 | B6: 2044.5 | C6: 2856.5 | D6: 398 | E6: 40 | F6: 372
A7: 6-Oct-25 | B7: 2021.5 | C7: 2836.5 | D7: 398 | E7: 41 | F7: 372
A8: 7-Oct-25 | B8: 2048 | C8: 3082 | D8: 398 | E8: 41 | F8: 372
A9: 8-Oct-25 | B9: 1996.5 | C9: 2762.5 | D9: 398 | E9: 41 | F9: 372
A10: 9-Oct-25 | B10: 2129 | C10: 2361 | D10: 398 | E10: 41 | F10: 372
A11: 10-Oct-25 | B11: 2141.5 | C11: 2543.5 | D11: 398 | E11: 41 | F11: 372
A12: 11-Oct-25 | B12: 2009 | C12: 2336 | D12: 398 | E12: 41 | F12: 372
A13: 12-Oct-25 | B13: 1625 | C13: 2339 | D13: 398 | E13: 41 | F13: 372
A14: 13-Oct-25 | B14: 200.5 | C14: 2155.5 | D14: 398 | E14: 42 | F14: 372
... A20: 19-Oct-25 | B20: 1295.5 | C20: 1945.5 | D20: 398 | E20: 42 | F20: 372
A21: 45950 | B21: 268.74 | C21: 2841.74 | D21: 398 | E21: 43 | F21: 372
A22: 45951 | B22: 1401.58 | C22: 3008.58 | D22: 398 | E22: 43 | F22: 372
A23: 45952 | B23: 2077.08 | C23: 2827.08 | D23: 398 | E23: 43 | F23: 372
A24: 45953 | B24: 2136.28 | C24: 3083.28 | D24: 398 | E24: 43 | F24: 372
A25: 45954 | B25: 2195.44 | C25: 3140.44 | D25: 398 | E25: 43 | F25: 372
A26: 45955 | B26: 1812.82 | C26: 2870.82 | D26: 398 | E26: 43 | F26: 372
A27: 45956 | B27: 378.12 | C27: 3051.12 | D27: 398 | E27: 43 | F27: 372
A28: 45957 | B28: 1323.38 | C28: 3086.38 | D28: 398 | E28: 44 | F28: 372
A29: 45958 | B29: 1463.7 | C29: 2527.7 | D29: 398 | E29: 44 | F29: 372
A30: 45959 | B30: 1974.3 | C30: 2304.3 | D30: 398 | E30: 44 | F30: 372
A31: 45960 | B31: 2147.72 | C31: 2998.72 | D31: 398 | E31: 44 | F31: 372
A32: 45961 | B32: 1924.84 | C32: 3020.84 | D32: 398 | E32: 44 | F32: 372
... A93: 46022 | B93: 2267.82 | C93: 2234.82 | D93: 398 | E93: 53 | F93: 372
A94: 46023 | B94: 2239.92 | C94: 2232.92 | D94: 398 | E94: 54 | F94: 372 | G94: 53
A95: 46024 | B95: 2093.3 | C95: 2310.3 | D95: 398 | E95: 54 | F95: 372 | G95: 53
A96: 46025 | B96: 1923.86 | C96: 1799.86 | D96: 398 | E96: 54 | F96: 372 | G96: 53
A97: 46026 | B97: 1907.04 | C97: 162.04 | D97: 398 | E97: 54 | F97: 372 | G97: 53
A98: 46027 | B98: 1806.04 | C98: 1676.04 | D98: 398 | E98: 54 | F98: 372 | G98: 54
A99: 46028 | B99: 1905.56 | C99: 2311.56 | D99: 398 | E99: 54 | F99: 372 | G99: 54
A100: 46029 | B100: 1738.06 | C100: 2359.06 | D100: 398 | E100: 54 | F100: 372 | G100: 54
A101: 46030 | B101: 1793.72 | C101: 2433.72 | D101: 398 | E101: 54 | F101: 372 | G101: 54
A102: 46031 | B102: 1906.28 | C102: 2899.28 | D102: 398 | E102: 54 | F102: 372 | G102: 54
A103: 46032 | B103: 1535.72 | C103: 2712.72 | D103: 398 | E103: 54 | F103: 372 | G103: 54
A104: 46033 | B104: 1681.52 | C104: 2715.52 | D104: 398 | E104: 54 | F104: 372 | G104: 54
A105: 46034 | B105: 1906.4 | C105: 2725.4 | D105: 398 | E105: 55 | F105: 372 | G105: 55
...
